script=/cube/neurocube/local/serenceslab/maggie/biasCNN/code/shell_scripts/TrainImageNetRots/train_net_cluster.sh
which_model=vgg_16
params=params1
rot=22
from_scratch=0
saving to /cube/neurocube/local/serenceslab/maggie/biasCNN/logs/vgg16/ImageNet/scratch_imagenet_rot_22/test
1000000
python train_image_classifier_biasCNN.py --train_dir=/cube/neurocube/local/serenceslab/maggie/biasCNN/logs/vgg16/ImageNet/scratch_imagenet_rot_22/test --dataset_name=imagenet --dataset_split_name=train --dataset_dir=/cube/neurocube/local/serenceslab/maggie/biasCNN/datasets/ImageNet/ILSVRC2012//tfrecord_rot_22/ --model_name=vgg_16 --max_number_of_steps=1000000 --flipLR=False --random_scale=False --is_windowed=True --weight_decay=0.00005 --rmsprop_decay=0.90 --rmsprop_momentum=0.80 --learning_rate=0.005 --learning_rate_decay_factor=0.94 --max_checkpoints_to_keep=5 --keep_checkpoint_every_n_hours=0.5 --batch_size=32
/home/AD/mmhender/anaconda3/lib/python3.7/site-packages/tensorflow/python/framework/dtypes.py:516: FutureWarning: Passing (type, 1) or '1type' as a synonym of type is deprecated; in a future version of numpy, it will be understood as (type, (1,)) / '(1,)type'.
  _np_qint8 = np.dtype([("qint8", np.int8, 1)])
/home/AD/mmhender/anaconda3/lib/python3.7/site-packages/tensorflow/python/framework/dtypes.py:517: FutureWarning: Passing (type, 1) or '1type' as a synonym of type is deprecated; in a future version of numpy, it will be understood as (type, (1,)) / '(1,)type'.
  _np_quint8 = np.dtype([("quint8", np.uint8, 1)])
/home/AD/mmhender/anaconda3/lib/python3.7/site-packages/tensorflow/python/framework/dtypes.py:518: FutureWarning: Passing (type, 1) or '1type' as a synonym of type is deprecated; in a future version of numpy, it will be understood as (type, (1,)) / '(1,)type'.
  _np_qint16 = np.dtype([("qint16", np.int16, 1)])
/home/AD/mmhender/anaconda3/lib/python3.7/site-packages/tensorflow/python/framework/dtypes.py:519: FutureWarning: Passing (type, 1) or '1type' as a synonym of type is deprecated; in a future version of numpy, it will be understood as (type, (1,)) / '(1,)type'.
  _np_quint16 = np.dtype([("quint16", np.uint16, 1)])
/home/AD/mmhender/anaconda3/lib/python3.7/site-packages/tensorflow/python/framework/dtypes.py:520: FutureWarning: Passing (type, 1) or '1type' as a synonym of type is deprecated; in a future version of numpy, it will be understood as (type, (1,)) / '(1,)type'.
  _np_qint32 = np.dtype([("qint32", np.int32, 1)])
/home/AD/mmhender/anaconda3/lib/python3.7/site-packages/tensorflow/python/framework/dtypes.py:525: FutureWarning: Passing (type, 1) or '1type' as a synonym of type is deprecated; in a future version of numpy, it will be understood as (type, (1,)) / '(1,)type'.
  np_resource = np.dtype([("resource", np.ubyte, 1)])
/home/AD/mmhender/anaconda3/lib/python3.7/site-packages/tensorboard/compat/tensorflow_stub/dtypes.py:541: FutureWarning: Passing (type, 1) or '1type' as a synonym of type is deprecated; in a future version of numpy, it will be understood as (type, (1,)) / '(1,)type'.
  _np_qint8 = np.dtype([("qint8", np.int8, 1)])
/home/AD/mmhender/anaconda3/lib/python3.7/site-packages/tensorboard/compat/tensorflow_stub/dtypes.py:542: FutureWarning: Passing (type, 1) or '1type' as a synonym of type is deprecated; in a future version of numpy, it will be understood as (type, (1,)) / '(1,)type'.
  _np_quint8 = np.dtype([("quint8", np.uint8, 1)])
/home/AD/mmhender/anaconda3/lib/python3.7/site-packages/tensorboard/compat/tensorflow_stub/dtypes.py:543: FutureWarning: Passing (type, 1) or '1type' as a synonym of type is deprecated; in a future version of numpy, it will be understood as (type, (1,)) / '(1,)type'.
  _np_qint16 = np.dtype([("qint16", np.int16, 1)])
/home/AD/mmhender/anaconda3/lib/python3.7/site-packages/tensorboard/compat/tensorflow_stub/dtypes.py:544: FutureWarning: Passing (type, 1) or '1type' as a synonym of type is deprecated; in a future version of numpy, it will be understood as (type, (1,)) / '(1,)type'.
  _np_quint16 = np.dtype([("quint16", np.uint16, 1)])
/home/AD/mmhender/anaconda3/lib/python3.7/site-packages/tensorboard/compat/tensorflow_stub/dtypes.py:545: FutureWarning: Passing (type, 1) or '1type' as a synonym of type is deprecated; in a future version of numpy, it will be understood as (type, (1,)) / '(1,)type'.
  _np_qint32 = np.dtype([("qint32", np.int32, 1)])
/home/AD/mmhender/anaconda3/lib/python3.7/site-packages/tensorboard/compat/tensorflow_stub/dtypes.py:550: FutureWarning: Passing (type, 1) or '1type' as a synonym of type is deprecated; in a future version of numpy, it will be understood as (type, (1,)) / '(1,)type'.
  np_resource = np.dtype([("resource", np.ubyte, 1)])
WARNING:tensorflow:
The TensorFlow contrib module will not be included in TensorFlow 2.0.
For more information, please see:
  * https://github.com/tensorflow/community/blob/master/rfcs/20180907-contrib-sunset.md
  * https://github.com/tensorflow/addons
  * https://github.com/tensorflow/io (for I/O related ops)
If you depend on functionality not listed there, please file an issue.

WARNING:tensorflow:From /cube/neurocube/local/serenceslab/maggie/tensorflow/models/research/slim/nets/inception_resnet_v2.py:373: The name tf.GraphKeys is deprecated. Please use tf.compat.v1.GraphKeys instead.

WARNING:tensorflow:From /cube/neurocube/local/serenceslab/maggie/tensorflow/models/research/slim/nets/mobilenet/mobilenet.py:389: The name tf.nn.avg_pool is deprecated. Please use tf.nn.avg_pool2d instead.

WARNING:tensorflow:From train_image_classifier_biasCNN.py:762: The name tf.app.run is deprecated. Please use tf.compat.v1.app.run instead.

WARNING:tensorflow:From train_image_classifier_biasCNN.py:445: The name tf.logging.set_verbosity is deprecated. Please use tf.compat.v1.logging.set_verbosity instead.

W0114 15:35:15.024977 140105975121728 deprecation_wrapper.py:119] From train_image_classifier_biasCNN.py:445: The name tf.logging.set_verbosity is deprecated. Please use tf.compat.v1.logging.set_verbosity instead.

WARNING:tensorflow:From train_image_classifier_biasCNN.py:445: The name tf.logging.INFO is deprecated. Please use tf.compat.v1.logging.INFO instead.

W0114 15:35:15.025253 140105975121728 deprecation_wrapper.py:119] From train_image_classifier_biasCNN.py:445: The name tf.logging.INFO is deprecated. Please use tf.compat.v1.logging.INFO instead.

WARNING:tensorflow:From train_image_classifier_biasCNN.py:459: create_global_step (from tensorflow.contrib.framework.python.ops.variables) is deprecated and will be removed in a future version.
Instructions for updating:
Please switch to tf.train.create_global_step
W0114 15:35:15.026300 140105975121728 deprecation.py:323] From train_image_classifier_biasCNN.py:459: create_global_step (from tensorflow.contrib.framework.python.ops.variables) is deprecated and will be removed in a future version.
Instructions for updating:
Please switch to tf.train.create_global_step
WARNING:tensorflow:From /cube/neurocube/local/serenceslab/maggie/tensorflow/models/research/slim/datasets/imagenet.py:151: The name tf.FixedLenFeature is deprecated. Please use tf.io.FixedLenFeature instead.

W0114 15:35:15.034111 140105975121728 deprecation_wrapper.py:119] From /cube/neurocube/local/serenceslab/maggie/tensorflow/models/research/slim/datasets/imagenet.py:151: The name tf.FixedLenFeature is deprecated. Please use tf.io.FixedLenFeature instead.

WARNING:tensorflow:From /cube/neurocube/local/serenceslab/maggie/tensorflow/models/research/slim/datasets/imagenet.py:159: The name tf.VarLenFeature is deprecated. Please use tf.io.VarLenFeature instead.

W0114 15:35:15.034286 140105975121728 deprecation_wrapper.py:119] From /cube/neurocube/local/serenceslab/maggie/tensorflow/models/research/slim/datasets/imagenet.py:159: The name tf.VarLenFeature is deprecated. Please use tf.io.VarLenFeature instead.

WARNING:tensorflow:From /cube/neurocube/local/serenceslab/maggie/tensorflow/models/research/slim/datasets/dataset_utils.py:127: The name tf.gfile.Exists is deprecated. Please use tf.io.gfile.exists instead.

W0114 15:35:15.034480 140105975121728 deprecation_wrapper.py:119] From /cube/neurocube/local/serenceslab/maggie/tensorflow/models/research/slim/datasets/dataset_utils.py:127: The name tf.gfile.Exists is deprecated. Please use tf.io.gfile.exists instead.

WARNING:tensorflow:From /cube/neurocube/local/serenceslab/maggie/tensorflow/models/research/slim/datasets/dataset_utils.py:141: The name tf.gfile.Open is deprecated. Please use tf.io.gfile.GFile instead.

W0114 15:35:15.034671 140105975121728 deprecation_wrapper.py:119] From /cube/neurocube/local/serenceslab/maggie/tensorflow/models/research/slim/datasets/dataset_utils.py:141: The name tf.gfile.Open is deprecated. Please use tf.io.gfile.GFile instead.

WARNING:tensorflow:From /home/AD/mmhender/anaconda3/lib/python3.7/site-packages/tensorflow/contrib/slim/python/slim/data/parallel_reader.py:246: string_input_producer (from tensorflow.python.training.input) is deprecated and will be removed in a future version.
Instructions for updating:
Queue-based input pipelines have been replaced by `tf.data`. Use `tf.data.Dataset.from_tensor_slices(string_tensor).shuffle(tf.shape(input_tensor, out_type=tf.int64)[0]).repeat(num_epochs)`. If `shuffle=False`, omit the `.shuffle(...)`.
W0114 15:35:15.108771 140105975121728 deprecation.py:323] From /home/AD/mmhender/anaconda3/lib/python3.7/site-packages/tensorflow/contrib/slim/python/slim/data/parallel_reader.py:246: string_input_producer (from tensorflow.python.training.input) is deprecated and will be removed in a future version.
Instructions for updating:
Queue-based input pipelines have been replaced by `tf.data`. Use `tf.data.Dataset.from_tensor_slices(string_tensor).shuffle(tf.shape(input_tensor, out_type=tf.int64)[0]).repeat(num_epochs)`. If `shuffle=False`, omit the `.shuffle(...)`.
WARNING:tensorflow:From /home/AD/mmhender/anaconda3/lib/python3.7/site-packages/tensorflow/python/training/input.py:278: input_producer (from tensorflow.python.training.input) is deprecated and will be removed in a future version.
Instructions for updating:
Queue-based input pipelines have been replaced by `tf.data`. Use `tf.data.Dataset.from_tensor_slices(input_tensor).shuffle(tf.shape(input_tensor, out_type=tf.int64)[0]).repeat(num_epochs)`. If `shuffle=False`, omit the `.shuffle(...)`.
W0114 15:35:15.122103 140105975121728 deprecation.py:323] From /home/AD/mmhender/anaconda3/lib/python3.7/site-packages/tensorflow/python/training/input.py:278: input_producer (from tensorflow.python.training.input) is deprecated and will be removed in a future version.
Instructions for updating:
Queue-based input pipelines have been replaced by `tf.data`. Use `tf.data.Dataset.from_tensor_slices(input_tensor).shuffle(tf.shape(input_tensor, out_type=tf.int64)[0]).repeat(num_epochs)`. If `shuffle=False`, omit the `.shuffle(...)`.
WARNING:tensorflow:From /home/AD/mmhender/anaconda3/lib/python3.7/site-packages/tensorflow/python/training/input.py:190: limit_epochs (from tensorflow.python.training.input) is deprecated and will be removed in a future version.
Instructions for updating:
Queue-based input pipelines have been replaced by `tf.data`. Use `tf.data.Dataset.from_tensors(tensor).repeat(num_epochs)`.
W0114 15:35:15.122993 140105975121728 deprecation.py:323] From /home/AD/mmhender/anaconda3/lib/python3.7/site-packages/tensorflow/python/training/input.py:190: limit_epochs (from tensorflow.python.training.input) is deprecated and will be removed in a future version.
Instructions for updating:
Queue-based input pipelines have been replaced by `tf.data`. Use `tf.data.Dataset.from_tensors(tensor).repeat(num_epochs)`.
WARNING:tensorflow:From /home/AD/mmhender/anaconda3/lib/python3.7/site-packages/tensorflow/python/training/input.py:199: QueueRunner.__init__ (from tensorflow.python.training.queue_runner_impl) is deprecated and will be removed in a future version.
Instructions for updating:
To construct input pipelines, use the `tf.data` module.
W0114 15:35:15.124782 140105975121728 deprecation.py:323] From /home/AD/mmhender/anaconda3/lib/python3.7/site-packages/tensorflow/python/training/input.py:199: QueueRunner.__init__ (from tensorflow.python.training.queue_runner_impl) is deprecated and will be removed in a future version.
Instructions for updating:
To construct input pipelines, use the `tf.data` module.
WARNING:tensorflow:From /home/AD/mmhender/anaconda3/lib/python3.7/site-packages/tensorflow/python/training/input.py:199: add_queue_runner (from tensorflow.python.training.queue_runner_impl) is deprecated and will be removed in a future version.
Instructions for updating:
To construct input pipelines, use the `tf.data` module.
W0114 15:35:15.125876 140105975121728 deprecation.py:323] From /home/AD/mmhender/anaconda3/lib/python3.7/site-packages/tensorflow/python/training/input.py:199: add_queue_runner (from tensorflow.python.training.queue_runner_impl) is deprecated and will be removed in a future version.
Instructions for updating:
To construct input pipelines, use the `tf.data` module.
WARNING:tensorflow:From /home/AD/mmhender/anaconda3/lib/python3.7/site-packages/tensorflow/contrib/slim/python/slim/data/parallel_reader.py:95: TFRecordReader.__init__ (from tensorflow.python.ops.io_ops) is deprecated and will be removed in a future version.
Instructions for updating:
Queue-based input pipelines have been replaced by `tf.data`. Use `tf.data.TFRecordDataset`.
W0114 15:35:15.133996 140105975121728 deprecation.py:323] From /home/AD/mmhender/anaconda3/lib/python3.7/site-packages/tensorflow/contrib/slim/python/slim/data/parallel_reader.py:95: TFRecordReader.__init__ (from tensorflow.python.ops.io_ops) is deprecated and will be removed in a future version.
Instructions for updating:
Queue-based input pipelines have been replaced by `tf.data`. Use `tf.data.TFRecordDataset`.
WARNING:tensorflow:From /cube/neurocube/local/serenceslab/maggie/tensorflow/models/research/slim/preprocessing/vgg_preprocessing_biasCNN.py:327: The name tf.assert_equal is deprecated. Please use tf.compat.v1.assert_equal instead.

W0114 15:35:15.384641 140105975121728 deprecation_wrapper.py:119] From /cube/neurocube/local/serenceslab/maggie/tensorflow/models/research/slim/preprocessing/vgg_preprocessing_biasCNN.py:327: The name tf.assert_equal is deprecated. Please use tf.compat.v1.assert_equal instead.

ERROR:tensorflow:==================================
Object was never used (type <class 'tensorflow.python.framework.ops.Operation'>):
<tf.Operation 'assert_equal/Assert/Assert' type=Assert>
If you want to mark it as used call its "mark_used()" method.
It was originally created here:
  File "train_image_classifier_biasCNN.py", line 762, in <module>
    tf.app.run()  File "/home/AD/mmhender/anaconda3/lib/python3.7/site-packages/tensorflow/python/platform/app.py", line 40, in run
    _run(main=main, argv=argv, flags_parser=_parse_flags_tolerate_undef)  File "/home/AD/mmhender/anaconda3/lib/python3.7/site-packages/absl/app.py", line 299, in run
    _run_main(main, args)  File "/home/AD/mmhender/anaconda3/lib/python3.7/site-packages/absl/app.py", line 250, in _run_main
    sys.exit(main(argv))  File "train_image_classifier_biasCNN.py", line 512, in main
    image = image_preprocessing_fn(image, train_image_size, train_image_size)  File "/cube/neurocube/local/serenceslab/maggie/tensorflow/models/research/slim/preprocessing/preprocessing_biasCNN.py", line 54, in preprocessing_fn
    image, output_height, output_width, is_training=is_training, flipLR=flipLR, random_scale=random_scale, is_windowed=is_windowed, **kwargs)  File "/cube/neurocube/local/serenceslab/maggie/tensorflow/models/research/slim/preprocessing/vgg_preprocessing_biasCNN.py", line 408, in preprocess_image
    resize_side_min, resize_side_max, flipLR, random_scale, is_windowed)  File "/cube/neurocube/local/serenceslab/maggie/tensorflow/models/research/slim/preprocessing/vgg_preprocessing_biasCNN.py", line 327, in preprocess_for_train
    tf.assert_equal(shape[0],shape[1])  File "/home/AD/mmhender/anaconda3/lib/python3.7/site-packages/tensorflow/python/ops/check_ops.py", line 557, in assert_equal
    return control_flow_ops.Assert(condition, data, summarize=summarize)  File "/home/AD/mmhender/anaconda3/lib/python3.7/site-packages/tensorflow/python/util/tf_should_use.py", line 193, in wrapped
    return _add_should_use_warning(fn(*args, **kwargs))
==================================
E0114 15:35:15.421786 140105975121728 tf_should_use.py:71] ==================================
Object was never used (type <class 'tensorflow.python.framework.ops.Operation'>):
<tf.Operation 'assert_equal/Assert/Assert' type=Assert>
If you want to mark it as used call its "mark_used()" method.
It was originally created here:
  File "train_image_classifier_biasCNN.py", line 762, in <module>
    tf.app.run()  File "/home/AD/mmhender/anaconda3/lib/python3.7/site-packages/tensorflow/python/platform/app.py", line 40, in run
    _run(main=main, argv=argv, flags_parser=_parse_flags_tolerate_undef)  File "/home/AD/mmhender/anaconda3/lib/python3.7/site-packages/absl/app.py", line 299, in run
    _run_main(main, args)  File "/home/AD/mmhender/anaconda3/lib/python3.7/site-packages/absl/app.py", line 250, in _run_main
    sys.exit(main(argv))  File "train_image_classifier_biasCNN.py", line 512, in main
    image = image_preprocessing_fn(image, train_image_size, train_image_size)  File "/cube/neurocube/local/serenceslab/maggie/tensorflow/models/research/slim/preprocessing/preprocessing_biasCNN.py", line 54, in preprocessing_fn
    image, output_height, output_width, is_training=is_training, flipLR=flipLR, random_scale=random_scale, is_windowed=is_windowed, **kwargs)  File "/cube/neurocube/local/serenceslab/maggie/tensorflow/models/research/slim/preprocessing/vgg_preprocessing_biasCNN.py", line 408, in preprocess_image
    resize_side_min, resize_side_max, flipLR, random_scale, is_windowed)  File "/cube/neurocube/local/serenceslab/maggie/tensorflow/models/research/slim/preprocessing/vgg_preprocessing_biasCNN.py", line 327, in preprocess_for_train
    tf.assert_equal(shape[0],shape[1])  File "/home/AD/mmhender/anaconda3/lib/python3.7/site-packages/tensorflow/python/ops/check_ops.py", line 557, in assert_equal
    return control_flow_ops.Assert(condition, data, summarize=summarize)  File "/home/AD/mmhender/anaconda3/lib/python3.7/site-packages/tensorflow/python/util/tf_should_use.py", line 193, in wrapped
    return _add_should_use_warning(fn(*args, **kwargs))
==================================
ERROR:tensorflow:==================================
Object was never used (type <class 'tensorflow.python.framework.ops.Operation'>):
<tf.Operation 'assert_equal_1/Assert/Assert' type=Assert>
If you want to mark it as used call its "mark_used()" method.
It was originally created here:
  File "train_image_classifier_biasCNN.py", line 762, in <module>
    tf.app.run()  File "/home/AD/mmhender/anaconda3/lib/python3.7/site-packages/tensorflow/python/platform/app.py", line 40, in run
    _run(main=main, argv=argv, flags_parser=_parse_flags_tolerate_undef)  File "/home/AD/mmhender/anaconda3/lib/python3.7/site-packages/absl/app.py", line 299, in run
    _run_main(main, args)  File "/home/AD/mmhender/anaconda3/lib/python3.7/site-packages/absl/app.py", line 250, in _run_main
    sys.exit(main(argv))  File "train_image_classifier_biasCNN.py", line 512, in main
    image = image_preprocessing_fn(image, train_image_size, train_image_size)  File "/cube/neurocube/local/serenceslab/maggie/tensorflow/models/research/slim/preprocessing/preprocessing_biasCNN.py", line 54, in preprocessing_fn
    image, output_height, output_width, is_training=is_training, flipLR=flipLR, random_scale=random_scale, is_windowed=is_windowed, **kwargs)  File "/cube/neurocube/local/serenceslab/maggie/tensorflow/models/research/slim/preprocessing/vgg_preprocessing_biasCNN.py", line 408, in preprocess_image
    resize_side_min, resize_side_max, flipLR, random_scale, is_windowed)  File "/cube/neurocube/local/serenceslab/maggie/tensorflow/models/research/slim/preprocessing/vgg_preprocessing_biasCNN.py", line 328, in preprocess_for_train
    tf.assert_equal(shape[0],output_height)  File "/home/AD/mmhender/anaconda3/lib/python3.7/site-packages/tensorflow/python/ops/check_ops.py", line 557, in assert_equal
    return control_flow_ops.Assert(condition, data, summarize=summarize)  File "/home/AD/mmhender/anaconda3/lib/python3.7/site-packages/tensorflow/python/util/tf_should_use.py", line 193, in wrapped
    return _add_should_use_warning(fn(*args, **kwargs))
==================================
E0114 15:35:15.438376 140105975121728 tf_should_use.py:71] ==================================
Object was never used (type <class 'tensorflow.python.framework.ops.Operation'>):
<tf.Operation 'assert_equal_1/Assert/Assert' type=Assert>
If you want to mark it as used call its "mark_used()" method.
It was originally created here:
  File "train_image_classifier_biasCNN.py", line 762, in <module>
    tf.app.run()  File "/home/AD/mmhender/anaconda3/lib/python3.7/site-packages/tensorflow/python/platform/app.py", line 40, in run
    _run(main=main, argv=argv, flags_parser=_parse_flags_tolerate_undef)  File "/home/AD/mmhender/anaconda3/lib/python3.7/site-packages/absl/app.py", line 299, in run
    _run_main(main, args)  File "/home/AD/mmhender/anaconda3/lib/python3.7/site-packages/absl/app.py", line 250, in _run_main
    sys.exit(main(argv))  File "train_image_classifier_biasCNN.py", line 512, in main
    image = image_preprocessing_fn(image, train_image_size, train_image_size)  File "/cube/neurocube/local/serenceslab/maggie/tensorflow/models/research/slim/preprocessing/preprocessing_biasCNN.py", line 54, in preprocessing_fn
    image, output_height, output_width, is_training=is_training, flipLR=flipLR, random_scale=random_scale, is_windowed=is_windowed, **kwargs)  File "/cube/neurocube/local/serenceslab/maggie/tensorflow/models/research/slim/preprocessing/vgg_preprocessing_biasCNN.py", line 408, in preprocess_image
    resize_side_min, resize_side_max, flipLR, random_scale, is_windowed)  File "/cube/neurocube/local/serenceslab/maggie/tensorflow/models/research/slim/preprocessing/vgg_preprocessing_biasCNN.py", line 328, in preprocess_for_train
    tf.assert_equal(shape[0],output_height)  File "/home/AD/mmhender/anaconda3/lib/python3.7/site-packages/tensorflow/python/ops/check_ops.py", line 557, in assert_equal
    return control_flow_ops.Assert(condition, data, summarize=summarize)  File "/home/AD/mmhender/anaconda3/lib/python3.7/site-packages/tensorflow/python/util/tf_should_use.py", line 193, in wrapped
    return _add_should_use_warning(fn(*args, **kwargs))
==================================
WARNING:tensorflow:From /cube/neurocube/local/serenceslab/maggie/tensorflow/models/research/slim/preprocessing/vgg_preprocessing_biasCNN.py:335: to_float (from tensorflow.python.ops.math_ops) is deprecated and will be removed in a future version.
Instructions for updating:
Use `tf.cast` instead.
W0114 15:35:15.438559 140105975121728 deprecation.py:323] From /cube/neurocube/local/serenceslab/maggie/tensorflow/models/research/slim/preprocessing/vgg_preprocessing_biasCNN.py:335: to_float (from tensorflow.python.ops.math_ops) is deprecated and will be removed in a future version.
Instructions for updating:
Use `tf.cast` instead.
WARNING:tensorflow:From train_image_classifier_biasCNN.py:518: batch (from tensorflow.python.training.input) is deprecated and will be removed in a future version.
Instructions for updating:
Queue-based input pipelines have been replaced by `tf.data`. Use `tf.data.Dataset.batch(batch_size)` (or `padded_batch(...)` if `dynamic_pad=True`).
W0114 15:35:15.445871 140105975121728 deprecation.py:323] From train_image_classifier_biasCNN.py:518: batch (from tensorflow.python.training.input) is deprecated and will be removed in a future version.
Instructions for updating:
Queue-based input pipelines have been replaced by `tf.data`. Use `tf.data.Dataset.batch(batch_size)` (or `padded_batch(...)` if `dynamic_pad=True`).
ERROR:tensorflow:==================================
Object was never used (type <class 'tensorflow.python.framework.ops.Operation'>):
<tf.Operation 'assert_equal_2/Assert/Assert' type=Assert>
If you want to mark it as used call its "mark_used()" method.
It was originally created here:
  File "train_image_classifier_biasCNN.py", line 762, in <module>
    tf.app.run()  File "/home/AD/mmhender/anaconda3/lib/python3.7/site-packages/tensorflow/python/platform/app.py", line 40, in run
    _run(main=main, argv=argv, flags_parser=_parse_flags_tolerate_undef)  File "/home/AD/mmhender/anaconda3/lib/python3.7/site-packages/absl/app.py", line 299, in run
    _run_main(main, args)  File "/home/AD/mmhender/anaconda3/lib/python3.7/site-packages/absl/app.py", line 250, in _run_main
    sys.exit(main(argv))  File "train_image_classifier_biasCNN.py", line 537, in main
    image_val = image_preprocessing_fn_val(image_val, eval_image_size, eval_image_size)  File "/cube/neurocube/local/serenceslab/maggie/tensorflow/models/research/slim/preprocessing/preprocessing_biasCNN.py", line 54, in preprocessing_fn
    image, output_height, output_width, is_training=is_training, flipLR=flipLR, random_scale=random_scale, is_windowed=is_windowed, **kwargs)  File "/cube/neurocube/local/serenceslab/maggie/tensorflow/models/research/slim/preprocessing/vgg_preprocessing_biasCNN.py", line 411, in preprocess_image
    resize_side_min, is_windowed)  File "/cube/neurocube/local/serenceslab/maggie/tensorflow/models/research/slim/preprocessing/vgg_preprocessing_biasCNN.py", line 363, in preprocess_for_eval
    tf.assert_equal(shape[0],shape[1])  File "/home/AD/mmhender/anaconda3/lib/python3.7/site-packages/tensorflow/python/ops/check_ops.py", line 557, in assert_equal
    return control_flow_ops.Assert(condition, data, summarize=summarize)  File "/home/AD/mmhender/anaconda3/lib/python3.7/site-packages/tensorflow/python/util/tf_should_use.py", line 193, in wrapped
    return _add_should_use_warning(fn(*args, **kwargs))
==================================
E0114 15:35:15.618678 140105975121728 tf_should_use.py:71] ==================================
Object was never used (type <class 'tensorflow.python.framework.ops.Operation'>):
<tf.Operation 'assert_equal_2/Assert/Assert' type=Assert>
If you want to mark it as used call its "mark_used()" method.
It was originally created here:
  File "train_image_classifier_biasCNN.py", line 762, in <module>
    tf.app.run()  File "/home/AD/mmhender/anaconda3/lib/python3.7/site-packages/tensorflow/python/platform/app.py", line 40, in run
    _run(main=main, argv=argv, flags_parser=_parse_flags_tolerate_undef)  File "/home/AD/mmhender/anaconda3/lib/python3.7/site-packages/absl/app.py", line 299, in run
    _run_main(main, args)  File "/home/AD/mmhender/anaconda3/lib/python3.7/site-packages/absl/app.py", line 250, in _run_main
    sys.exit(main(argv))  File "train_image_classifier_biasCNN.py", line 537, in main
    image_val = image_preprocessing_fn_val(image_val, eval_image_size, eval_image_size)  File "/cube/neurocube/local/serenceslab/maggie/tensorflow/models/research/slim/preprocessing/preprocessing_biasCNN.py", line 54, in preprocessing_fn
    image, output_height, output_width, is_training=is_training, flipLR=flipLR, random_scale=random_scale, is_windowed=is_windowed, **kwargs)  File "/cube/neurocube/local/serenceslab/maggie/tensorflow/models/research/slim/preprocessing/vgg_preprocessing_biasCNN.py", line 411, in preprocess_image
    resize_side_min, is_windowed)  File "/cube/neurocube/local/serenceslab/maggie/tensorflow/models/research/slim/preprocessing/vgg_preprocessing_biasCNN.py", line 363, in preprocess_for_eval
    tf.assert_equal(shape[0],shape[1])  File "/home/AD/mmhender/anaconda3/lib/python3.7/site-packages/tensorflow/python/ops/check_ops.py", line 557, in assert_equal
    return control_flow_ops.Assert(condition, data, summarize=summarize)  File "/home/AD/mmhender/anaconda3/lib/python3.7/site-packages/tensorflow/python/util/tf_should_use.py", line 193, in wrapped
    return _add_should_use_warning(fn(*args, **kwargs))
==================================
ERROR:tensorflow:==================================
Object was never used (type <class 'tensorflow.python.framework.ops.Operation'>):
<tf.Operation 'assert_equal_3/Assert/Assert' type=Assert>
If you want to mark it as used call its "mark_used()" method.
It was originally created here:
  File "train_image_classifier_biasCNN.py", line 762, in <module>
    tf.app.run()  File "/home/AD/mmhender/anaconda3/lib/python3.7/site-packages/tensorflow/python/platform/app.py", line 40, in run
    _run(main=main, argv=argv, flags_parser=_parse_flags_tolerate_undef)  File "/home/AD/mmhender/anaconda3/lib/python3.7/site-packages/absl/app.py", line 299, in run
    _run_main(main, args)  File "/home/AD/mmhender/anaconda3/lib/python3.7/site-packages/absl/app.py", line 250, in _run_main
    sys.exit(main(argv))  File "train_image_classifier_biasCNN.py", line 537, in main
    image_val = image_preprocessing_fn_val(image_val, eval_image_size, eval_image_size)  File "/cube/neurocube/local/serenceslab/maggie/tensorflow/models/research/slim/preprocessing/preprocessing_biasCNN.py", line 54, in preprocessing_fn
    image, output_height, output_width, is_training=is_training, flipLR=flipLR, random_scale=random_scale, is_windowed=is_windowed, **kwargs)  File "/cube/neurocube/local/serenceslab/maggie/tensorflow/models/research/slim/preprocessing/vgg_preprocessing_biasCNN.py", line 411, in preprocess_image
    resize_side_min, is_windowed)  File "/cube/neurocube/local/serenceslab/maggie/tensorflow/models/research/slim/preprocessing/vgg_preprocessing_biasCNN.py", line 364, in preprocess_for_eval
    tf.assert_equal(shape[0],output_height)  File "/home/AD/mmhender/anaconda3/lib/python3.7/site-packages/tensorflow/python/ops/check_ops.py", line 557, in assert_equal
    return control_flow_ops.Assert(condition, data, summarize=summarize)  File "/home/AD/mmhender/anaconda3/lib/python3.7/site-packages/tensorflow/python/util/tf_should_use.py", line 193, in wrapped
    return _add_should_use_warning(fn(*args, **kwargs))
==================================
E0114 15:35:15.628777 140105975121728 tf_should_use.py:71] ==================================
Object was never used (type <class 'tensorflow.python.framework.ops.Operation'>):
<tf.Operation 'assert_equal_3/Assert/Assert' type=Assert>
If you want to mark it as used call its "mark_used()" method.
It was originally created here:
  File "train_image_classifier_biasCNN.py", line 762, in <module>
    tf.app.run()  File "/home/AD/mmhender/anaconda3/lib/python3.7/site-packages/tensorflow/python/platform/app.py", line 40, in run
    _run(main=main, argv=argv, flags_parser=_parse_flags_tolerate_undef)  File "/home/AD/mmhender/anaconda3/lib/python3.7/site-packages/absl/app.py", line 299, in run
    _run_main(main, args)  File "/home/AD/mmhender/anaconda3/lib/python3.7/site-packages/absl/app.py", line 250, in _run_main
    sys.exit(main(argv))  File "train_image_classifier_biasCNN.py", line 537, in main
    image_val = image_preprocessing_fn_val(image_val, eval_image_size, eval_image_size)  File "/cube/neurocube/local/serenceslab/maggie/tensorflow/models/research/slim/preprocessing/preprocessing_biasCNN.py", line 54, in preprocessing_fn
    image, output_height, output_width, is_training=is_training, flipLR=flipLR, random_scale=random_scale, is_windowed=is_windowed, **kwargs)  File "/cube/neurocube/local/serenceslab/maggie/tensorflow/models/research/slim/preprocessing/vgg_preprocessing_biasCNN.py", line 411, in preprocess_image
    resize_side_min, is_windowed)  File "/cube/neurocube/local/serenceslab/maggie/tensorflow/models/research/slim/preprocessing/vgg_preprocessing_biasCNN.py", line 364, in preprocess_for_eval
    tf.assert_equal(shape[0],output_height)  File "/home/AD/mmhender/anaconda3/lib/python3.7/site-packages/tensorflow/python/ops/check_ops.py", line 557, in assert_equal
    return control_flow_ops.Assert(condition, data, summarize=summarize)  File "/home/AD/mmhender/anaconda3/lib/python3.7/site-packages/tensorflow/python/util/tf_should_use.py", line 193, in wrapped
    return _add_should_use_warning(fn(*args, **kwargs))
==================================
WARNING:tensorflow:From train_image_classifier_biasCNN.py:572: The name tf.get_collection is deprecated. Please use tf.compat.v1.get_collection instead.

W0114 15:35:15.647504 140105975121728 deprecation_wrapper.py:119] From train_image_classifier_biasCNN.py:572: The name tf.get_collection is deprecated. Please use tf.compat.v1.get_collection instead.

WARNING:tensorflow:Entity <bound method Conv.call of <tensorflow.python.layers.convolutional.Conv2D object at 0x7f6c9054ebd0>> could not be transformed and will be executed as-is. Please report this to the AutgoGraph team. When filing the bug, set the verbosity to 10 (on Linux, `export AUTOGRAPH_VERBOSITY=10`) and attach the full output. Cause: converting <bound method Conv.call of <tensorflow.python.layers.convolutional.Conv2D object at 0x7f6c9054ebd0>>: AssertionError: Bad argument number for Name: 3, expecting 4
W0114 15:35:16.042526 140105975121728 ag_logging.py:145] Entity <bound method Conv.call of <tensorflow.python.layers.convolutional.Conv2D object at 0x7f6c9054ebd0>> could not be transformed and will be executed as-is. Please report this to the AutgoGraph team. When filing the bug, set the verbosity to 10 (on Linux, `export AUTOGRAPH_VERBOSITY=10`) and attach the full output. Cause: converting <bound method Conv.call of <tensorflow.python.layers.convolutional.Conv2D object at 0x7f6c9054ebd0>>: AssertionError: Bad argument number for Name: 3, expecting 4
WARNING:tensorflow:Entity <bound method Conv.call of <tensorflow.python.layers.convolutional.Conv2D object at 0x7f6c9054ed50>> could not be transformed and will be executed as-is. Please report this to the AutgoGraph team. When filing the bug, set the verbosity to 10 (on Linux, `export AUTOGRAPH_VERBOSITY=10`) and attach the full output. Cause: converting <bound method Conv.call of <tensorflow.python.layers.convolutional.Conv2D object at 0x7f6c9054ed50>>: AssertionError: Bad argument number for Name: 3, expecting 4
W0114 15:35:16.209279 140105975121728 ag_logging.py:145] Entity <bound method Conv.call of <tensorflow.python.layers.convolutional.Conv2D object at 0x7f6c9054ed50>> could not be transformed and will be executed as-is. Please report this to the AutgoGraph team. When filing the bug, set the verbosity to 10 (on Linux, `export AUTOGRAPH_VERBOSITY=10`) and attach the full output. Cause: converting <bound method Conv.call of <tensorflow.python.layers.convolutional.Conv2D object at 0x7f6c9054ed50>>: AssertionError: Bad argument number for Name: 3, expecting 4
WARNING:tensorflow:Entity <bound method Pooling2D.call of <tensorflow.python.layers.pooling.MaxPooling2D object at 0x7f6c9054e9d0>> could not be transformed and will be executed as-is. Please report this to the AutgoGraph team. When filing the bug, set the verbosity to 10 (on Linux, `export AUTOGRAPH_VERBOSITY=10`) and attach the full output. Cause: converting <bound method Pooling2D.call of <tensorflow.python.layers.pooling.MaxPooling2D object at 0x7f6c9054e9d0>>: AssertionError: Bad argument number for Name: 3, expecting 4
W0114 15:35:16.266652 140105975121728 ag_logging.py:145] Entity <bound method Pooling2D.call of <tensorflow.python.layers.pooling.MaxPooling2D object at 0x7f6c9054e9d0>> could not be transformed and will be executed as-is. Please report this to the AutgoGraph team. When filing the bug, set the verbosity to 10 (on Linux, `export AUTOGRAPH_VERBOSITY=10`) and attach the full output. Cause: converting <bound method Pooling2D.call of <tensorflow.python.layers.pooling.MaxPooling2D object at 0x7f6c9054e9d0>>: AssertionError: Bad argument number for Name: 3, expecting 4
WARNING:tensorflow:Entity <bound method Conv.call of <tensorflow.python.layers.convolutional.Conv2D object at 0x7f6c905bdb10>> could not be transformed and will be executed as-is. Please report this to the AutgoGraph team. When filing the bug, set the verbosity to 10 (on Linux, `export AUTOGRAPH_VERBOSITY=10`) and attach the full output. Cause: converting <bound method Conv.call of <tensorflow.python.layers.convolutional.Conv2D object at 0x7f6c905bdb10>>: AssertionError: Bad argument number for Name: 3, expecting 4
W0114 15:35:16.360358 140105975121728 ag_logging.py:145] Entity <bound method Conv.call of <tensorflow.python.layers.convolutional.Conv2D object at 0x7f6c905bdb10>> could not be transformed and will be executed as-is. Please report this to the AutgoGraph team. When filing the bug, set the verbosity to 10 (on Linux, `export AUTOGRAPH_VERBOSITY=10`) and attach the full output. Cause: converting <bound method Conv.call of <tensorflow.python.layers.convolutional.Conv2D object at 0x7f6c905bdb10>>: AssertionError: Bad argument number for Name: 3, expecting 4
WARNING:tensorflow:Entity <bound method Conv.call of <tensorflow.python.layers.convolutional.Conv2D object at 0x7f6c9049eb10>> could not be transformed and will be executed as-is. Please report this to the AutgoGraph team. When filing the bug, set the verbosity to 10 (on Linux, `export AUTOGRAPH_VERBOSITY=10`) and attach the full output. Cause: converting <bound method Conv.call of <tensorflow.python.layers.convolutional.Conv2D object at 0x7f6c9049eb10>>: AssertionError: Bad argument number for Name: 3, expecting 4
W0114 15:35:16.454895 140105975121728 ag_logging.py:145] Entity <bound method Conv.call of <tensorflow.python.layers.convolutional.Conv2D object at 0x7f6c9049eb10>> could not be transformed and will be executed as-is. Please report this to the AutgoGraph team. When filing the bug, set the verbosity to 10 (on Linux, `export AUTOGRAPH_VERBOSITY=10`) and attach the full output. Cause: converting <bound method Conv.call of <tensorflow.python.layers.convolutional.Conv2D object at 0x7f6c9049eb10>>: AssertionError: Bad argument number for Name: 3, expecting 4
WARNING:tensorflow:Entity <bound method Pooling2D.call of <tensorflow.python.layers.pooling.MaxPooling2D object at 0x7f6c9054ea50>> could not be transformed and will be executed as-is. Please report this to the AutgoGraph team. When filing the bug, set the verbosity to 10 (on Linux, `export AUTOGRAPH_VERBOSITY=10`) and attach the full output. Cause: converting <bound method Pooling2D.call of <tensorflow.python.layers.pooling.MaxPooling2D object at 0x7f6c9054ea50>>: AssertionError: Bad argument number for Name: 3, expecting 4
W0114 15:35:16.512129 140105975121728 ag_logging.py:145] Entity <bound method Pooling2D.call of <tensorflow.python.layers.pooling.MaxPooling2D object at 0x7f6c9054ea50>> could not be transformed and will be executed as-is. Please report this to the AutgoGraph team. When filing the bug, set the verbosity to 10 (on Linux, `export AUTOGRAPH_VERBOSITY=10`) and attach the full output. Cause: converting <bound method Pooling2D.call of <tensorflow.python.layers.pooling.MaxPooling2D object at 0x7f6c9054ea50>>: AssertionError: Bad argument number for Name: 3, expecting 4
WARNING:tensorflow:Entity <bound method Conv.call of <tensorflow.python.layers.convolutional.Conv2D object at 0x7f6c904caf50>> could not be transformed and will be executed as-is. Please report this to the AutgoGraph team. When filing the bug, set the verbosity to 10 (on Linux, `export AUTOGRAPH_VERBOSITY=10`) and attach the full output. Cause: converting <bound method Conv.call of <tensorflow.python.layers.convolutional.Conv2D object at 0x7f6c904caf50>>: AssertionError: Bad argument number for Name: 3, expecting 4
W0114 15:35:16.605757 140105975121728 ag_logging.py:145] Entity <bound method Conv.call of <tensorflow.python.layers.convolutional.Conv2D object at 0x7f6c904caf50>> could not be transformed and will be executed as-is. Please report this to the AutgoGraph team. When filing the bug, set the verbosity to 10 (on Linux, `export AUTOGRAPH_VERBOSITY=10`) and attach the full output. Cause: converting <bound method Conv.call of <tensorflow.python.layers.convolutional.Conv2D object at 0x7f6c904caf50>>: AssertionError: Bad argument number for Name: 3, expecting 4
WARNING:tensorflow:Entity <bound method Conv.call of <tensorflow.python.layers.convolutional.Conv2D object at 0x7f6c90501d10>> could not be transformed and will be executed as-is. Please report this to the AutgoGraph team. When filing the bug, set the verbosity to 10 (on Linux, `export AUTOGRAPH_VERBOSITY=10`) and attach the full output. Cause: converting <bound method Conv.call of <tensorflow.python.layers.convolutional.Conv2D object at 0x7f6c90501d10>>: AssertionError: Bad argument number for Name: 3, expecting 4
W0114 15:35:16.701026 140105975121728 ag_logging.py:145] Entity <bound method Conv.call of <tensorflow.python.layers.convolutional.Conv2D object at 0x7f6c90501d10>> could not be transformed and will be executed as-is. Please report this to the AutgoGraph team. When filing the bug, set the verbosity to 10 (on Linux, `export AUTOGRAPH_VERBOSITY=10`) and attach the full output. Cause: converting <bound method Conv.call of <tensorflow.python.layers.convolutional.Conv2D object at 0x7f6c90501d10>>: AssertionError: Bad argument number for Name: 3, expecting 4
WARNING:tensorflow:Entity <bound method Conv.call of <tensorflow.python.layers.convolutional.Conv2D object at 0x7f6c90501d50>> could not be transformed and will be executed as-is. Please report this to the AutgoGraph team. When filing the bug, set the verbosity to 10 (on Linux, `export AUTOGRAPH_VERBOSITY=10`) and attach the full output. Cause: converting <bound method Conv.call of <tensorflow.python.layers.convolutional.Conv2D object at 0x7f6c90501d50>>: AssertionError: Bad argument number for Name: 3, expecting 4
W0114 15:35:16.795527 140105975121728 ag_logging.py:145] Entity <bound method Conv.call of <tensorflow.python.layers.convolutional.Conv2D object at 0x7f6c90501d50>> could not be transformed and will be executed as-is. Please report this to the AutgoGraph team. When filing the bug, set the verbosity to 10 (on Linux, `export AUTOGRAPH_VERBOSITY=10`) and attach the full output. Cause: converting <bound method Conv.call of <tensorflow.python.layers.convolutional.Conv2D object at 0x7f6c90501d50>>: AssertionError: Bad argument number for Name: 3, expecting 4
WARNING:tensorflow:Entity <bound method Pooling2D.call of <tensorflow.python.layers.pooling.MaxPooling2D object at 0x7f6c904e2fd0>> could not be transformed and will be executed as-is. Please report this to the AutgoGraph team. When filing the bug, set the verbosity to 10 (on Linux, `export AUTOGRAPH_VERBOSITY=10`) and attach the full output. Cause: converting <bound method Pooling2D.call of <tensorflow.python.layers.pooling.MaxPooling2D object at 0x7f6c904e2fd0>>: AssertionError: Bad argument number for Name: 3, expecting 4
W0114 15:35:16.852687 140105975121728 ag_logging.py:145] Entity <bound method Pooling2D.call of <tensorflow.python.layers.pooling.MaxPooling2D object at 0x7f6c904e2fd0>> could not be transformed and will be executed as-is. Please report this to the AutgoGraph team. When filing the bug, set the verbosity to 10 (on Linux, `export AUTOGRAPH_VERBOSITY=10`) and attach the full output. Cause: converting <bound method Pooling2D.call of <tensorflow.python.layers.pooling.MaxPooling2D object at 0x7f6c904e2fd0>>: AssertionError: Bad argument number for Name: 3, expecting 4
WARNING:tensorflow:Entity <bound method Conv.call of <tensorflow.python.layers.convolutional.Conv2D object at 0x7f6c904e7ed0>> could not be transformed and will be executed as-is. Please report this to the AutgoGraph team. When filing the bug, set the verbosity to 10 (on Linux, `export AUTOGRAPH_VERBOSITY=10`) and attach the full output. Cause: converting <bound method Conv.call of <tensorflow.python.layers.convolutional.Conv2D object at 0x7f6c904e7ed0>>: AssertionError: Bad argument number for Name: 3, expecting 4
W0114 15:35:16.945832 140105975121728 ag_logging.py:145] Entity <bound method Conv.call of <tensorflow.python.layers.convolutional.Conv2D object at 0x7f6c904e7ed0>> could not be transformed and will be executed as-is. Please report this to the AutgoGraph team. When filing the bug, set the verbosity to 10 (on Linux, `export AUTOGRAPH_VERBOSITY=10`) and attach the full output. Cause: converting <bound method Conv.call of <tensorflow.python.layers.convolutional.Conv2D object at 0x7f6c904e7ed0>>: AssertionError: Bad argument number for Name: 3, expecting 4
WARNING:tensorflow:Entity <bound method Conv.call of <tensorflow.python.layers.convolutional.Conv2D object at 0x7f6c9049e950>> could not be transformed and will be executed as-is. Please report this to the AutgoGraph team. When filing the bug, set the verbosity to 10 (on Linux, `export AUTOGRAPH_VERBOSITY=10`) and attach the full output. Cause: converting <bound method Conv.call of <tensorflow.python.layers.convolutional.Conv2D object at 0x7f6c9049e950>>: AssertionError: Bad argument number for Name: 3, expecting 4
W0114 15:35:17.040491 140105975121728 ag_logging.py:145] Entity <bound method Conv.call of <tensorflow.python.layers.convolutional.Conv2D object at 0x7f6c9049e950>> could not be transformed and will be executed as-is. Please report this to the AutgoGraph team. When filing the bug, set the verbosity to 10 (on Linux, `export AUTOGRAPH_VERBOSITY=10`) and attach the full output. Cause: converting <bound method Conv.call of <tensorflow.python.layers.convolutional.Conv2D object at 0x7f6c9049e950>>: AssertionError: Bad argument number for Name: 3, expecting 4
WARNING:tensorflow:Entity <bound method Conv.call of <tensorflow.python.layers.convolutional.Conv2D object at 0x7f6c904a4e90>> could not be transformed and will be executed as-is. Please report this to the AutgoGraph team. When filing the bug, set the verbosity to 10 (on Linux, `export AUTOGRAPH_VERBOSITY=10`) and attach the full output. Cause: converting <bound method Conv.call of <tensorflow.python.layers.convolutional.Conv2D object at 0x7f6c904a4e90>>: AssertionError: Bad argument number for Name: 3, expecting 4
W0114 15:35:17.135263 140105975121728 ag_logging.py:145] Entity <bound method Conv.call of <tensorflow.python.layers.convolutional.Conv2D object at 0x7f6c904a4e90>> could not be transformed and will be executed as-is. Please report this to the AutgoGraph team. When filing the bug, set the verbosity to 10 (on Linux, `export AUTOGRAPH_VERBOSITY=10`) and attach the full output. Cause: converting <bound method Conv.call of <tensorflow.python.layers.convolutional.Conv2D object at 0x7f6c904a4e90>>: AssertionError: Bad argument number for Name: 3, expecting 4
WARNING:tensorflow:Entity <bound method Pooling2D.call of <tensorflow.python.layers.pooling.MaxPooling2D object at 0x7f6c904fb0d0>> could not be transformed and will be executed as-is. Please report this to the AutgoGraph team. When filing the bug, set the verbosity to 10 (on Linux, `export AUTOGRAPH_VERBOSITY=10`) and attach the full output. Cause: converting <bound method Pooling2D.call of <tensorflow.python.layers.pooling.MaxPooling2D object at 0x7f6c904fb0d0>>: AssertionError: Bad argument number for Name: 3, expecting 4
W0114 15:35:17.192589 140105975121728 ag_logging.py:145] Entity <bound method Pooling2D.call of <tensorflow.python.layers.pooling.MaxPooling2D object at 0x7f6c904fb0d0>> could not be transformed and will be executed as-is. Please report this to the AutgoGraph team. When filing the bug, set the verbosity to 10 (on Linux, `export AUTOGRAPH_VERBOSITY=10`) and attach the full output. Cause: converting <bound method Pooling2D.call of <tensorflow.python.layers.pooling.MaxPooling2D object at 0x7f6c904fb0d0>>: AssertionError: Bad argument number for Name: 3, expecting 4
WARNING:tensorflow:Entity <bound method Conv.call of <tensorflow.python.layers.convolutional.Conv2D object at 0x7f6c90576bd0>> could not be transformed and will be executed as-is. Please report this to the AutgoGraph team. When filing the bug, set the verbosity to 10 (on Linux, `export AUTOGRAPH_VERBOSITY=10`) and attach the full output. Cause: converting <bound method Conv.call of <tensorflow.python.layers.convolutional.Conv2D object at 0x7f6c90576bd0>>: AssertionError: Bad argument number for Name: 3, expecting 4
W0114 15:35:17.286307 140105975121728 ag_logging.py:145] Entity <bound method Conv.call of <tensorflow.python.layers.convolutional.Conv2D object at 0x7f6c90576bd0>> could not be transformed and will be executed as-is. Please report this to the AutgoGraph team. When filing the bug, set the verbosity to 10 (on Linux, `export AUTOGRAPH_VERBOSITY=10`) and attach the full output. Cause: converting <bound method Conv.call of <tensorflow.python.layers.convolutional.Conv2D object at 0x7f6c90576bd0>>: AssertionError: Bad argument number for Name: 3, expecting 4
WARNING:tensorflow:Entity <bound method Conv.call of <tensorflow.python.layers.convolutional.Conv2D object at 0x7f6c9049edd0>> could not be transformed and will be executed as-is. Please report this to the AutgoGraph team. When filing the bug, set the verbosity to 10 (on Linux, `export AUTOGRAPH_VERBOSITY=10`) and attach the full output. Cause: converting <bound method Conv.call of <tensorflow.python.layers.convolutional.Conv2D object at 0x7f6c9049edd0>>: AssertionError: Bad argument number for Name: 3, expecting 4
W0114 15:35:17.380944 140105975121728 ag_logging.py:145] Entity <bound method Conv.call of <tensorflow.python.layers.convolutional.Conv2D object at 0x7f6c9049edd0>> could not be transformed and will be executed as-is. Please report this to the AutgoGraph team. When filing the bug, set the verbosity to 10 (on Linux, `export AUTOGRAPH_VERBOSITY=10`) and attach the full output. Cause: converting <bound method Conv.call of <tensorflow.python.layers.convolutional.Conv2D object at 0x7f6c9049edd0>>: AssertionError: Bad argument number for Name: 3, expecting 4
WARNING:tensorflow:Entity <bound method Conv.call of <tensorflow.python.layers.convolutional.Conv2D object at 0x7f6c9049e950>> could not be transformed and will be executed as-is. Please report this to the AutgoGraph team. When filing the bug, set the verbosity to 10 (on Linux, `export AUTOGRAPH_VERBOSITY=10`) and attach the full output. Cause: converting <bound method Conv.call of <tensorflow.python.layers.convolutional.Conv2D object at 0x7f6c9049e950>>: AssertionError: Bad argument number for Name: 3, expecting 4
W0114 15:35:17.475416 140105975121728 ag_logging.py:145] Entity <bound method Conv.call of <tensorflow.python.layers.convolutional.Conv2D object at 0x7f6c9049e950>> could not be transformed and will be executed as-is. Please report this to the AutgoGraph team. When filing the bug, set the verbosity to 10 (on Linux, `export AUTOGRAPH_VERBOSITY=10`) and attach the full output. Cause: converting <bound method Conv.call of <tensorflow.python.layers.convolutional.Conv2D object at 0x7f6c9049e950>>: AssertionError: Bad argument number for Name: 3, expecting 4
WARNING:tensorflow:Entity <bound method Pooling2D.call of <tensorflow.python.layers.pooling.MaxPooling2D object at 0x7f6c904e7250>> could not be transformed and will be executed as-is. Please report this to the AutgoGraph team. When filing the bug, set the verbosity to 10 (on Linux, `export AUTOGRAPH_VERBOSITY=10`) and attach the full output. Cause: converting <bound method Pooling2D.call of <tensorflow.python.layers.pooling.MaxPooling2D object at 0x7f6c904e7250>>: AssertionError: Bad argument number for Name: 3, expecting 4
W0114 15:35:17.532693 140105975121728 ag_logging.py:145] Entity <bound method Pooling2D.call of <tensorflow.python.layers.pooling.MaxPooling2D object at 0x7f6c904e7250>> could not be transformed and will be executed as-is. Please report this to the AutgoGraph team. When filing the bug, set the verbosity to 10 (on Linux, `export AUTOGRAPH_VERBOSITY=10`) and attach the full output. Cause: converting <bound method Pooling2D.call of <tensorflow.python.layers.pooling.MaxPooling2D object at 0x7f6c904e7250>>: AssertionError: Bad argument number for Name: 3, expecting 4
WARNING:tensorflow:Entity <bound method Conv.call of <tensorflow.python.layers.convolutional.Conv2D object at 0x7f6c904167d0>> could not be transformed and will be executed as-is. Please report this to the AutgoGraph team. When filing the bug, set the verbosity to 10 (on Linux, `export AUTOGRAPH_VERBOSITY=10`) and attach the full output. Cause: converting <bound method Conv.call of <tensorflow.python.layers.convolutional.Conv2D object at 0x7f6c904167d0>>: AssertionError: Bad argument number for Name: 3, expecting 4
W0114 15:35:17.627704 140105975121728 ag_logging.py:145] Entity <bound method Conv.call of <tensorflow.python.layers.convolutional.Conv2D object at 0x7f6c904167d0>> could not be transformed and will be executed as-is. Please report this to the AutgoGraph team. When filing the bug, set the verbosity to 10 (on Linux, `export AUTOGRAPH_VERBOSITY=10`) and attach the full output. Cause: converting <bound method Conv.call of <tensorflow.python.layers.convolutional.Conv2D object at 0x7f6c904167d0>>: AssertionError: Bad argument number for Name: 3, expecting 4
WARNING:tensorflow:Entity <bound method Dropout.call of <tensorflow.python.layers.core.Dropout object at 0x7f6c9030a710>> could not be transformed and will be executed as-is. Please report this to the AutgoGraph team. When filing the bug, set the verbosity to 10 (on Linux, `export AUTOGRAPH_VERBOSITY=10`) and attach the full output. Cause: converting <bound method Dropout.call of <tensorflow.python.layers.core.Dropout object at 0x7f6c9030a710>>: AssertionError: Bad argument number for Name: 3, expecting 4
W0114 15:35:17.646215 140105975121728 ag_logging.py:145] Entity <bound method Dropout.call of <tensorflow.python.layers.core.Dropout object at 0x7f6c9030a710>> could not be transformed and will be executed as-is. Please report this to the AutgoGraph team. When filing the bug, set the verbosity to 10 (on Linux, `export AUTOGRAPH_VERBOSITY=10`) and attach the full output. Cause: converting <bound method Dropout.call of <tensorflow.python.layers.core.Dropout object at 0x7f6c9030a710>>: AssertionError: Bad argument number for Name: 3, expecting 4
WARNING:tensorflow:Entity <bound method Conv.call of <tensorflow.python.layers.convolutional.Conv2D object at 0x7f6c904e7250>> could not be transformed and will be executed as-is. Please report this to the AutgoGraph team. When filing the bug, set the verbosity to 10 (on Linux, `export AUTOGRAPH_VERBOSITY=10`) and attach the full output. Cause: converting <bound method Conv.call of <tensorflow.python.layers.convolutional.Conv2D object at 0x7f6c904e7250>>: AssertionError: Bad argument number for Name: 3, expecting 4
W0114 15:35:17.750436 140105975121728 ag_logging.py:145] Entity <bound method Conv.call of <tensorflow.python.layers.convolutional.Conv2D object at 0x7f6c904e7250>> could not be transformed and will be executed as-is. Please report this to the AutgoGraph team. When filing the bug, set the verbosity to 10 (on Linux, `export AUTOGRAPH_VERBOSITY=10`) and attach the full output. Cause: converting <bound method Conv.call of <tensorflow.python.layers.convolutional.Conv2D object at 0x7f6c904e7250>>: AssertionError: Bad argument number for Name: 3, expecting 4
WARNING:tensorflow:Entity <bound method Dropout.call of <tensorflow.python.layers.core.Dropout object at 0x7f6c90495650>> could not be transformed and will be executed as-is. Please report this to the AutgoGraph team. When filing the bug, set the verbosity to 10 (on Linux, `export AUTOGRAPH_VERBOSITY=10`) and attach the full output. Cause: converting <bound method Dropout.call of <tensorflow.python.layers.core.Dropout object at 0x7f6c90495650>>: AssertionError: Bad argument number for Name: 3, expecting 4
W0114 15:35:17.768832 140105975121728 ag_logging.py:145] Entity <bound method Dropout.call of <tensorflow.python.layers.core.Dropout object at 0x7f6c90495650>> could not be transformed and will be executed as-is. Please report this to the AutgoGraph team. When filing the bug, set the verbosity to 10 (on Linux, `export AUTOGRAPH_VERBOSITY=10`) and attach the full output. Cause: converting <bound method Dropout.call of <tensorflow.python.layers.core.Dropout object at 0x7f6c90495650>>: AssertionError: Bad argument number for Name: 3, expecting 4
WARNING:tensorflow:Entity <bound method Conv.call of <tensorflow.python.layers.convolutional.Conv2D object at 0x7f6c9030a710>> could not be transformed and will be executed as-is. Please report this to the AutgoGraph team. When filing the bug, set the verbosity to 10 (on Linux, `export AUTOGRAPH_VERBOSITY=10`) and attach the full output. Cause: converting <bound method Conv.call of <tensorflow.python.layers.convolutional.Conv2D object at 0x7f6c9030a710>>: AssertionError: Bad argument number for Name: 3, expecting 4
W0114 15:35:17.872531 140105975121728 ag_logging.py:145] Entity <bound method Conv.call of <tensorflow.python.layers.convolutional.Conv2D object at 0x7f6c9030a710>> could not be transformed and will be executed as-is. Please report this to the AutgoGraph team. When filing the bug, set the verbosity to 10 (on Linux, `export AUTOGRAPH_VERBOSITY=10`) and attach the full output. Cause: converting <bound method Conv.call of <tensorflow.python.layers.convolutional.Conv2D object at 0x7f6c9030a710>>: AssertionError: Bad argument number for Name: 3, expecting 4
WARNING:tensorflow:From train_image_classifier_biasCNN.py:567: The name tf.losses.softmax_cross_entropy is deprecated. Please use tf.compat.v1.losses.softmax_cross_entropy instead.

W0114 15:35:17.875571 140105975121728 deprecation_wrapper.py:119] From train_image_classifier_biasCNN.py:567: The name tf.losses.softmax_cross_entropy is deprecated. Please use tf.compat.v1.losses.softmax_cross_entropy instead.

WARNING:tensorflow:From /home/AD/mmhender/anaconda3/lib/python3.7/site-packages/tensorflow/python/ops/losses/losses_impl.py:121: add_dispatch_support.<locals>.wrapper (from tensorflow.python.ops.array_ops) is deprecated and will be removed in a future version.
Instructions for updating:
Use tf.where in 2.0, which has the same broadcast rule as np.where
W0114 15:35:17.908284 140105975121728 deprecation.py:323] From /home/AD/mmhender/anaconda3/lib/python3.7/site-packages/tensorflow/python/ops/losses/losses_impl.py:121: add_dispatch_support.<locals>.wrapper (from tensorflow.python.ops.array_ops) is deprecated and will be removed in a future version.
Instructions for updating:
Use tf.where in 2.0, which has the same broadcast rule as np.where
WARNING:tensorflow:From train_image_classifier_biasCNN.py:588: The name tf.summary.image is deprecated. Please use tf.compat.v1.summary.image instead.

W0114 15:35:17.917957 140105975121728 deprecation_wrapper.py:119] From train_image_classifier_biasCNN.py:588: The name tf.summary.image is deprecated. Please use tf.compat.v1.summary.image instead.

WARNING:tensorflow:From train_image_classifier_biasCNN.py:589: The name tf.summary.histogram is deprecated. Please use tf.compat.v1.summary.histogram instead.

W0114 15:35:17.933188 140105975121728 deprecation_wrapper.py:119] From train_image_classifier_biasCNN.py:589: The name tf.summary.histogram is deprecated. Please use tf.compat.v1.summary.histogram instead.

WARNING:tensorflow:From train_image_classifier_biasCNN.py:590: The name tf.summary.scalar is deprecated. Please use tf.compat.v1.summary.scalar instead.

W0114 15:35:17.934462 140105975121728 deprecation_wrapper.py:119] From train_image_classifier_biasCNN.py:590: The name tf.summary.scalar is deprecated. Please use tf.compat.v1.summary.scalar instead.

WARNING:tensorflow:From train_image_classifier_biasCNN.py:301: The name tf.train.exponential_decay is deprecated. Please use tf.compat.v1.train.exponential_decay instead.

W0114 15:35:18.565743 140105975121728 deprecation_wrapper.py:119] From train_image_classifier_biasCNN.py:301: The name tf.train.exponential_decay is deprecated. Please use tf.compat.v1.train.exponential_decay instead.

WARNING:tensorflow:From train_image_classifier_biasCNN.py:362: The name tf.train.RMSPropOptimizer is deprecated. Please use tf.compat.v1.train.RMSPropOptimizer instead.

W0114 15:35:18.571488 140105975121728 deprecation_wrapper.py:119] From train_image_classifier_biasCNN.py:362: The name tf.train.RMSPropOptimizer is deprecated. Please use tf.compat.v1.train.RMSPropOptimizer instead.

WARNING:tensorflow:From /home/AD/mmhender/anaconda3/lib/python3.7/site-packages/tensorflow/python/training/rmsprop.py:119: calling Ones.__init__ (from tensorflow.python.ops.init_ops) with dtype is deprecated and will be removed in a future version.
Instructions for updating:
Call initializer instance with the dtype argument instead of passing it to the constructor
W0114 15:35:19.045966 140105975121728 deprecation.py:506] From /home/AD/mmhender/anaconda3/lib/python3.7/site-packages/tensorflow/python/training/rmsprop.py:119: calling Ones.__init__ (from tensorflow.python.ops.init_ops) with dtype is deprecated and will be removed in a future version.
Instructions for updating:
Call initializer instance with the dtype argument instead of passing it to the constructor
INFO:tensorflow:Scale of 0 disables regularizer.
I0114 15:35:19.436428 140105975121728 regularizers.py:98] Scale of 0 disables regularizer.
WARNING:tensorflow:Entity <bound method Conv.call of <tensorflow.python.layers.convolutional.Conv2D object at 0x7f6c8a8f1ed0>> could not be transformed and will be executed as-is. Please report this to the AutgoGraph team. When filing the bug, set the verbosity to 10 (on Linux, `export AUTOGRAPH_VERBOSITY=10`) and attach the full output. Cause: converting <bound method Conv.call of <tensorflow.python.layers.convolutional.Conv2D object at 0x7f6c8a8f1ed0>>: AssertionError: Bad argument number for Name: 3, expecting 4
W0114 15:35:19.519271 140105975121728 ag_logging.py:145] Entity <bound method Conv.call of <tensorflow.python.layers.convolutional.Conv2D object at 0x7f6c8a8f1ed0>> could not be transformed and will be executed as-is. Please report this to the AutgoGraph team. When filing the bug, set the verbosity to 10 (on Linux, `export AUTOGRAPH_VERBOSITY=10`) and attach the full output. Cause: converting <bound method Conv.call of <tensorflow.python.layers.convolutional.Conv2D object at 0x7f6c8a8f1ed0>>: AssertionError: Bad argument number for Name: 3, expecting 4
WARNING:tensorflow:Entity <bound method Conv.call of <tensorflow.python.layers.convolutional.Conv2D object at 0x7f6c8aa5ce10>> could not be transformed and will be executed as-is. Please report this to the AutgoGraph team. When filing the bug, set the verbosity to 10 (on Linux, `export AUTOGRAPH_VERBOSITY=10`) and attach the full output. Cause: converting <bound method Conv.call of <tensorflow.python.layers.convolutional.Conv2D object at 0x7f6c8aa5ce10>>: AssertionError: Bad argument number for Name: 3, expecting 4
W0114 15:35:19.599973 140105975121728 ag_logging.py:145] Entity <bound method Conv.call of <tensorflow.python.layers.convolutional.Conv2D object at 0x7f6c8aa5ce10>> could not be transformed and will be executed as-is. Please report this to the AutgoGraph team. When filing the bug, set the verbosity to 10 (on Linux, `export AUTOGRAPH_VERBOSITY=10`) and attach the full output. Cause: converting <bound method Conv.call of <tensorflow.python.layers.convolutional.Conv2D object at 0x7f6c8aa5ce10>>: AssertionError: Bad argument number for Name: 3, expecting 4
WARNING:tensorflow:Entity <bound method Pooling2D.call of <tensorflow.python.layers.pooling.MaxPooling2D object at 0x7f6c8aa163d0>> could not be transformed and will be executed as-is. Please report this to the AutgoGraph team. When filing the bug, set the verbosity to 10 (on Linux, `export AUTOGRAPH_VERBOSITY=10`) and attach the full output. Cause: converting <bound method Pooling2D.call of <tensorflow.python.layers.pooling.MaxPooling2D object at 0x7f6c8aa163d0>>: AssertionError: Bad argument number for Name: 3, expecting 4
W0114 15:35:19.657033 140105975121728 ag_logging.py:145] Entity <bound method Pooling2D.call of <tensorflow.python.layers.pooling.MaxPooling2D object at 0x7f6c8aa163d0>> could not be transformed and will be executed as-is. Please report this to the AutgoGraph team. When filing the bug, set the verbosity to 10 (on Linux, `export AUTOGRAPH_VERBOSITY=10`) and attach the full output. Cause: converting <bound method Pooling2D.call of <tensorflow.python.layers.pooling.MaxPooling2D object at 0x7f6c8aa163d0>>: AssertionError: Bad argument number for Name: 3, expecting 4
WARNING:tensorflow:Entity <bound method Conv.call of <tensorflow.python.layers.convolutional.Conv2D object at 0x7f6c8a906950>> could not be transformed and will be executed as-is. Please report this to the AutgoGraph team. When filing the bug, set the verbosity to 10 (on Linux, `export AUTOGRAPH_VERBOSITY=10`) and attach the full output. Cause: converting <bound method Conv.call of <tensorflow.python.layers.convolutional.Conv2D object at 0x7f6c8a906950>>: AssertionError: Bad argument number for Name: 3, expecting 4
W0114 15:35:19.736416 140105975121728 ag_logging.py:145] Entity <bound method Conv.call of <tensorflow.python.layers.convolutional.Conv2D object at 0x7f6c8a906950>> could not be transformed and will be executed as-is. Please report this to the AutgoGraph team. When filing the bug, set the verbosity to 10 (on Linux, `export AUTOGRAPH_VERBOSITY=10`) and attach the full output. Cause: converting <bound method Conv.call of <tensorflow.python.layers.convolutional.Conv2D object at 0x7f6c8a906950>>: AssertionError: Bad argument number for Name: 3, expecting 4
WARNING:tensorflow:Entity <bound method Conv.call of <tensorflow.python.layers.convolutional.Conv2D object at 0x7f6c8a7e1b10>> could not be transformed and will be executed as-is. Please report this to the AutgoGraph team. When filing the bug, set the verbosity to 10 (on Linux, `export AUTOGRAPH_VERBOSITY=10`) and attach the full output. Cause: converting <bound method Conv.call of <tensorflow.python.layers.convolutional.Conv2D object at 0x7f6c8a7e1b10>>: AssertionError: Bad argument number for Name: 3, expecting 4
W0114 15:35:19.817316 140105975121728 ag_logging.py:145] Entity <bound method Conv.call of <tensorflow.python.layers.convolutional.Conv2D object at 0x7f6c8a7e1b10>> could not be transformed and will be executed as-is. Please report this to the AutgoGraph team. When filing the bug, set the verbosity to 10 (on Linux, `export AUTOGRAPH_VERBOSITY=10`) and attach the full output. Cause: converting <bound method Conv.call of <tensorflow.python.layers.convolutional.Conv2D object at 0x7f6c8a7e1b10>>: AssertionError: Bad argument number for Name: 3, expecting 4
WARNING:tensorflow:Entity <bound method Pooling2D.call of <tensorflow.python.layers.pooling.MaxPooling2D object at 0x7f6c8aa385d0>> could not be transformed and will be executed as-is. Please report this to the AutgoGraph team. When filing the bug, set the verbosity to 10 (on Linux, `export AUTOGRAPH_VERBOSITY=10`) and attach the full output. Cause: converting <bound method Pooling2D.call of <tensorflow.python.layers.pooling.MaxPooling2D object at 0x7f6c8aa385d0>>: AssertionError: Bad argument number for Name: 3, expecting 4
W0114 15:35:19.874747 140105975121728 ag_logging.py:145] Entity <bound method Pooling2D.call of <tensorflow.python.layers.pooling.MaxPooling2D object at 0x7f6c8aa385d0>> could not be transformed and will be executed as-is. Please report this to the AutgoGraph team. When filing the bug, set the verbosity to 10 (on Linux, `export AUTOGRAPH_VERBOSITY=10`) and attach the full output. Cause: converting <bound method Pooling2D.call of <tensorflow.python.layers.pooling.MaxPooling2D object at 0x7f6c8aa385d0>>: AssertionError: Bad argument number for Name: 3, expecting 4
WARNING:tensorflow:Entity <bound method Conv.call of <tensorflow.python.layers.convolutional.Conv2D object at 0x7f6c8a7e1b10>> could not be transformed and will be executed as-is. Please report this to the AutgoGraph team. When filing the bug, set the verbosity to 10 (on Linux, `export AUTOGRAPH_VERBOSITY=10`) and attach the full output. Cause: converting <bound method Conv.call of <tensorflow.python.layers.convolutional.Conv2D object at 0x7f6c8a7e1b10>>: AssertionError: Bad argument number for Name: 3, expecting 4
W0114 15:35:19.954509 140105975121728 ag_logging.py:145] Entity <bound method Conv.call of <tensorflow.python.layers.convolutional.Conv2D object at 0x7f6c8a7e1b10>> could not be transformed and will be executed as-is. Please report this to the AutgoGraph team. When filing the bug, set the verbosity to 10 (on Linux, `export AUTOGRAPH_VERBOSITY=10`) and attach the full output. Cause: converting <bound method Conv.call of <tensorflow.python.layers.convolutional.Conv2D object at 0x7f6c8a7e1b10>>: AssertionError: Bad argument number for Name: 3, expecting 4
WARNING:tensorflow:Entity <bound method Conv.call of <tensorflow.python.layers.convolutional.Conv2D object at 0x7f6c90511b10>> could not be transformed and will be executed as-is. Please report this to the AutgoGraph team. When filing the bug, set the verbosity to 10 (on Linux, `export AUTOGRAPH_VERBOSITY=10`) and attach the full output. Cause: converting <bound method Conv.call of <tensorflow.python.layers.convolutional.Conv2D object at 0x7f6c90511b10>>: AssertionError: Bad argument number for Name: 3, expecting 4
W0114 15:35:20.035285 140105975121728 ag_logging.py:145] Entity <bound method Conv.call of <tensorflow.python.layers.convolutional.Conv2D object at 0x7f6c90511b10>> could not be transformed and will be executed as-is. Please report this to the AutgoGraph team. When filing the bug, set the verbosity to 10 (on Linux, `export AUTOGRAPH_VERBOSITY=10`) and attach the full output. Cause: converting <bound method Conv.call of <tensorflow.python.layers.convolutional.Conv2D object at 0x7f6c90511b10>>: AssertionError: Bad argument number for Name: 3, expecting 4
WARNING:tensorflow:Entity <bound method Conv.call of <tensorflow.python.layers.convolutional.Conv2D object at 0x7f6c90511c50>> could not be transformed and will be executed as-is. Please report this to the AutgoGraph team. When filing the bug, set the verbosity to 10 (on Linux, `export AUTOGRAPH_VERBOSITY=10`) and attach the full output. Cause: converting <bound method Conv.call of <tensorflow.python.layers.convolutional.Conv2D object at 0x7f6c90511c50>>: AssertionError: Bad argument number for Name: 3, expecting 4
W0114 15:35:20.116120 140105975121728 ag_logging.py:145] Entity <bound method Conv.call of <tensorflow.python.layers.convolutional.Conv2D object at 0x7f6c90511c50>> could not be transformed and will be executed as-is. Please report this to the AutgoGraph team. When filing the bug, set the verbosity to 10 (on Linux, `export AUTOGRAPH_VERBOSITY=10`) and attach the full output. Cause: converting <bound method Conv.call of <tensorflow.python.layers.convolutional.Conv2D object at 0x7f6c90511c50>>: AssertionError: Bad argument number for Name: 3, expecting 4
WARNING:tensorflow:Entity <bound method Pooling2D.call of <tensorflow.python.layers.pooling.MaxPooling2D object at 0x7f6c8a91c850>> could not be transformed and will be executed as-is. Please report this to the AutgoGraph team. When filing the bug, set the verbosity to 10 (on Linux, `export AUTOGRAPH_VERBOSITY=10`) and attach the full output. Cause: converting <bound method Pooling2D.call of <tensorflow.python.layers.pooling.MaxPooling2D object at 0x7f6c8a91c850>>: AssertionError: Bad argument number for Name: 3, expecting 4
W0114 15:35:20.173525 140105975121728 ag_logging.py:145] Entity <bound method Pooling2D.call of <tensorflow.python.layers.pooling.MaxPooling2D object at 0x7f6c8a91c850>> could not be transformed and will be executed as-is. Please report this to the AutgoGraph team. When filing the bug, set the verbosity to 10 (on Linux, `export AUTOGRAPH_VERBOSITY=10`) and attach the full output. Cause: converting <bound method Pooling2D.call of <tensorflow.python.layers.pooling.MaxPooling2D object at 0x7f6c8a91c850>>: AssertionError: Bad argument number for Name: 3, expecting 4
WARNING:tensorflow:Entity <bound method Conv.call of <tensorflow.python.layers.convolutional.Conv2D object at 0x7f6c8ac81490>> could not be transformed and will be executed as-is. Please report this to the AutgoGraph team. When filing the bug, set the verbosity to 10 (on Linux, `export AUTOGRAPH_VERBOSITY=10`) and attach the full output. Cause: converting <bound method Conv.call of <tensorflow.python.layers.convolutional.Conv2D object at 0x7f6c8ac81490>>: AssertionError: Bad argument number for Name: 3, expecting 4
W0114 15:35:20.253034 140105975121728 ag_logging.py:145] Entity <bound method Conv.call of <tensorflow.python.layers.convolutional.Conv2D object at 0x7f6c8ac81490>> could not be transformed and will be executed as-is. Please report this to the AutgoGraph team. When filing the bug, set the verbosity to 10 (on Linux, `export AUTOGRAPH_VERBOSITY=10`) and attach the full output. Cause: converting <bound method Conv.call of <tensorflow.python.layers.convolutional.Conv2D object at 0x7f6c8ac81490>>: AssertionError: Bad argument number for Name: 3, expecting 4
WARNING:tensorflow:Entity <bound method Conv.call of <tensorflow.python.layers.convolutional.Conv2D object at 0x7f6c90511bd0>> could not be transformed and will be executed as-is. Please report this to the AutgoGraph team. When filing the bug, set the verbosity to 10 (on Linux, `export AUTOGRAPH_VERBOSITY=10`) and attach the full output. Cause: converting <bound method Conv.call of <tensorflow.python.layers.convolutional.Conv2D object at 0x7f6c90511bd0>>: AssertionError: Bad argument number for Name: 3, expecting 4
W0114 15:35:20.333858 140105975121728 ag_logging.py:145] Entity <bound method Conv.call of <tensorflow.python.layers.convolutional.Conv2D object at 0x7f6c90511bd0>> could not be transformed and will be executed as-is. Please report this to the AutgoGraph team. When filing the bug, set the verbosity to 10 (on Linux, `export AUTOGRAPH_VERBOSITY=10`) and attach the full output. Cause: converting <bound method Conv.call of <tensorflow.python.layers.convolutional.Conv2D object at 0x7f6c90511bd0>>: AssertionError: Bad argument number for Name: 3, expecting 4
WARNING:tensorflow:Entity <bound method Conv.call of <tensorflow.python.layers.convolutional.Conv2D object at 0x7f6c8a790d90>> could not be transformed and will be executed as-is. Please report this to the AutgoGraph team. When filing the bug, set the verbosity to 10 (on Linux, `export AUTOGRAPH_VERBOSITY=10`) and attach the full output. Cause: converting <bound method Conv.call of <tensorflow.python.layers.convolutional.Conv2D object at 0x7f6c8a790d90>>: AssertionError: Bad argument number for Name: 3, expecting 4
W0114 15:35:20.414789 140105975121728 ag_logging.py:145] Entity <bound method Conv.call of <tensorflow.python.layers.convolutional.Conv2D object at 0x7f6c8a790d90>> could not be transformed and will be executed as-is. Please report this to the AutgoGraph team. When filing the bug, set the verbosity to 10 (on Linux, `export AUTOGRAPH_VERBOSITY=10`) and attach the full output. Cause: converting <bound method Conv.call of <tensorflow.python.layers.convolutional.Conv2D object at 0x7f6c8a790d90>>: AssertionError: Bad argument number for Name: 3, expecting 4
WARNING:tensorflow:Entity <bound method Pooling2D.call of <tensorflow.python.layers.pooling.MaxPooling2D object at 0x7f6c8a8cf250>> could not be transformed and will be executed as-is. Please report this to the AutgoGraph team. When filing the bug, set the verbosity to 10 (on Linux, `export AUTOGRAPH_VERBOSITY=10`) and attach the full output. Cause: converting <bound method Pooling2D.call of <tensorflow.python.layers.pooling.MaxPooling2D object at 0x7f6c8a8cf250>>: AssertionError: Bad argument number for Name: 3, expecting 4
W0114 15:35:20.472127 140105975121728 ag_logging.py:145] Entity <bound method Pooling2D.call of <tensorflow.python.layers.pooling.MaxPooling2D object at 0x7f6c8a8cf250>> could not be transformed and will be executed as-is. Please report this to the AutgoGraph team. When filing the bug, set the verbosity to 10 (on Linux, `export AUTOGRAPH_VERBOSITY=10`) and attach the full output. Cause: converting <bound method Pooling2D.call of <tensorflow.python.layers.pooling.MaxPooling2D object at 0x7f6c8a8cf250>>: AssertionError: Bad argument number for Name: 3, expecting 4
WARNING:tensorflow:Entity <bound method Conv.call of <tensorflow.python.layers.convolutional.Conv2D object at 0x7f6c90511e90>> could not be transformed and will be executed as-is. Please report this to the AutgoGraph team. When filing the bug, set the verbosity to 10 (on Linux, `export AUTOGRAPH_VERBOSITY=10`) and attach the full output. Cause: converting <bound method Conv.call of <tensorflow.python.layers.convolutional.Conv2D object at 0x7f6c90511e90>>: AssertionError: Bad argument number for Name: 3, expecting 4
W0114 15:35:20.552014 140105975121728 ag_logging.py:145] Entity <bound method Conv.call of <tensorflow.python.layers.convolutional.Conv2D object at 0x7f6c90511e90>> could not be transformed and will be executed as-is. Please report this to the AutgoGraph team. When filing the bug, set the verbosity to 10 (on Linux, `export AUTOGRAPH_VERBOSITY=10`) and attach the full output. Cause: converting <bound method Conv.call of <tensorflow.python.layers.convolutional.Conv2D object at 0x7f6c90511e90>>: AssertionError: Bad argument number for Name: 3, expecting 4
WARNING:tensorflow:Entity <bound method Conv.call of <tensorflow.python.layers.convolutional.Conv2D object at 0x7f6c8a7f8710>> could not be transformed and will be executed as-is. Please report this to the AutgoGraph team. When filing the bug, set the verbosity to 10 (on Linux, `export AUTOGRAPH_VERBOSITY=10`) and attach the full output. Cause: converting <bound method Conv.call of <tensorflow.python.layers.convolutional.Conv2D object at 0x7f6c8a7f8710>>: AssertionError: Bad argument number for Name: 3, expecting 4
W0114 15:35:20.632930 140105975121728 ag_logging.py:145] Entity <bound method Conv.call of <tensorflow.python.layers.convolutional.Conv2D object at 0x7f6c8a7f8710>> could not be transformed and will be executed as-is. Please report this to the AutgoGraph team. When filing the bug, set the verbosity to 10 (on Linux, `export AUTOGRAPH_VERBOSITY=10`) and attach the full output. Cause: converting <bound method Conv.call of <tensorflow.python.layers.convolutional.Conv2D object at 0x7f6c8a7f8710>>: AssertionError: Bad argument number for Name: 3, expecting 4
WARNING:tensorflow:Entity <bound method Conv.call of <tensorflow.python.layers.convolutional.Conv2D object at 0x7f6c90511f10>> could not be transformed and will be executed as-is. Please report this to the AutgoGraph team. When filing the bug, set the verbosity to 10 (on Linux, `export AUTOGRAPH_VERBOSITY=10`) and attach the full output. Cause: converting <bound method Conv.call of <tensorflow.python.layers.convolutional.Conv2D object at 0x7f6c90511f10>>: AssertionError: Bad argument number for Name: 3, expecting 4
W0114 15:35:20.713870 140105975121728 ag_logging.py:145] Entity <bound method Conv.call of <tensorflow.python.layers.convolutional.Conv2D object at 0x7f6c90511f10>> could not be transformed and will be executed as-is. Please report this to the AutgoGraph team. When filing the bug, set the verbosity to 10 (on Linux, `export AUTOGRAPH_VERBOSITY=10`) and attach the full output. Cause: converting <bound method Conv.call of <tensorflow.python.layers.convolutional.Conv2D object at 0x7f6c90511f10>>: AssertionError: Bad argument number for Name: 3, expecting 4
WARNING:tensorflow:Entity <bound method Pooling2D.call of <tensorflow.python.layers.pooling.MaxPooling2D object at 0x7f6c8a893650>> could not be transformed and will be executed as-is. Please report this to the AutgoGraph team. When filing the bug, set the verbosity to 10 (on Linux, `export AUTOGRAPH_VERBOSITY=10`) and attach the full output. Cause: converting <bound method Pooling2D.call of <tensorflow.python.layers.pooling.MaxPooling2D object at 0x7f6c8a893650>>: AssertionError: Bad argument number for Name: 3, expecting 4
W0114 15:35:20.771175 140105975121728 ag_logging.py:145] Entity <bound method Pooling2D.call of <tensorflow.python.layers.pooling.MaxPooling2D object at 0x7f6c8a893650>> could not be transformed and will be executed as-is. Please report this to the AutgoGraph team. When filing the bug, set the verbosity to 10 (on Linux, `export AUTOGRAPH_VERBOSITY=10`) and attach the full output. Cause: converting <bound method Pooling2D.call of <tensorflow.python.layers.pooling.MaxPooling2D object at 0x7f6c8a893650>>: AssertionError: Bad argument number for Name: 3, expecting 4
WARNING:tensorflow:Entity <bound method Conv.call of <tensorflow.python.layers.convolutional.Conv2D object at 0x7f6c904ca150>> could not be transformed and will be executed as-is. Please report this to the AutgoGraph team. When filing the bug, set the verbosity to 10 (on Linux, `export AUTOGRAPH_VERBOSITY=10`) and attach the full output. Cause: converting <bound method Conv.call of <tensorflow.python.layers.convolutional.Conv2D object at 0x7f6c904ca150>>: AssertionError: Bad argument number for Name: 3, expecting 4
W0114 15:35:20.850297 140105975121728 ag_logging.py:145] Entity <bound method Conv.call of <tensorflow.python.layers.convolutional.Conv2D object at 0x7f6c904ca150>> could not be transformed and will be executed as-is. Please report this to the AutgoGraph team. When filing the bug, set the verbosity to 10 (on Linux, `export AUTOGRAPH_VERBOSITY=10`) and attach the full output. Cause: converting <bound method Conv.call of <tensorflow.python.layers.convolutional.Conv2D object at 0x7f6c904ca150>>: AssertionError: Bad argument number for Name: 3, expecting 4
WARNING:tensorflow:Entity <bound method Dropout.call of <tensorflow.python.layers.core.Dropout object at 0x7f6c8aa09cd0>> could not be transformed and will be executed as-is. Please report this to the AutgoGraph team. When filing the bug, set the verbosity to 10 (on Linux, `export AUTOGRAPH_VERBOSITY=10`) and attach the full output. Cause: converting <bound method Dropout.call of <tensorflow.python.layers.core.Dropout object at 0x7f6c8aa09cd0>>: AssertionError: Bad argument number for Name: 3, expecting 4
W0114 15:35:20.868671 140105975121728 ag_logging.py:145] Entity <bound method Dropout.call of <tensorflow.python.layers.core.Dropout object at 0x7f6c8aa09cd0>> could not be transformed and will be executed as-is. Please report this to the AutgoGraph team. When filing the bug, set the verbosity to 10 (on Linux, `export AUTOGRAPH_VERBOSITY=10`) and attach the full output. Cause: converting <bound method Dropout.call of <tensorflow.python.layers.core.Dropout object at 0x7f6c8aa09cd0>>: AssertionError: Bad argument number for Name: 3, expecting 4
WARNING:tensorflow:Entity <bound method Conv.call of <tensorflow.python.layers.convolutional.Conv2D object at 0x7f6c90511ed0>> could not be transformed and will be executed as-is. Please report this to the AutgoGraph team. When filing the bug, set the verbosity to 10 (on Linux, `export AUTOGRAPH_VERBOSITY=10`) and attach the full output. Cause: converting <bound method Conv.call of <tensorflow.python.layers.convolutional.Conv2D object at 0x7f6c90511ed0>>: AssertionError: Bad argument number for Name: 3, expecting 4
W0114 15:35:20.947664 140105975121728 ag_logging.py:145] Entity <bound method Conv.call of <tensorflow.python.layers.convolutional.Conv2D object at 0x7f6c90511ed0>> could not be transformed and will be executed as-is. Please report this to the AutgoGraph team. When filing the bug, set the verbosity to 10 (on Linux, `export AUTOGRAPH_VERBOSITY=10`) and attach the full output. Cause: converting <bound method Conv.call of <tensorflow.python.layers.convolutional.Conv2D object at 0x7f6c90511ed0>>: AssertionError: Bad argument number for Name: 3, expecting 4
WARNING:tensorflow:Entity <bound method Dropout.call of <tensorflow.python.layers.core.Dropout object at 0x7f6c8a794d10>> could not be transformed and will be executed as-is. Please report this to the AutgoGraph team. When filing the bug, set the verbosity to 10 (on Linux, `export AUTOGRAPH_VERBOSITY=10`) and attach the full output. Cause: converting <bound method Dropout.call of <tensorflow.python.layers.core.Dropout object at 0x7f6c8a794d10>>: AssertionError: Bad argument number for Name: 3, expecting 4
W0114 15:35:20.966049 140105975121728 ag_logging.py:145] Entity <bound method Dropout.call of <tensorflow.python.layers.core.Dropout object at 0x7f6c8a794d10>> could not be transformed and will be executed as-is. Please report this to the AutgoGraph team. When filing the bug, set the verbosity to 10 (on Linux, `export AUTOGRAPH_VERBOSITY=10`) and attach the full output. Cause: converting <bound method Dropout.call of <tensorflow.python.layers.core.Dropout object at 0x7f6c8a794d10>>: AssertionError: Bad argument number for Name: 3, expecting 4
WARNING:tensorflow:Entity <bound method Conv.call of <tensorflow.python.layers.convolutional.Conv2D object at 0x7f6c904f7590>> could not be transformed and will be executed as-is. Please report this to the AutgoGraph team. When filing the bug, set the verbosity to 10 (on Linux, `export AUTOGRAPH_VERBOSITY=10`) and attach the full output. Cause: converting <bound method Conv.call of <tensorflow.python.layers.convolutional.Conv2D object at 0x7f6c904f7590>>: AssertionError: Bad argument number for Name: 3, expecting 4
W0114 15:35:21.044949 140105975121728 ag_logging.py:145] Entity <bound method Conv.call of <tensorflow.python.layers.convolutional.Conv2D object at 0x7f6c904f7590>> could not be transformed and will be executed as-is. Please report this to the AutgoGraph team. When filing the bug, set the verbosity to 10 (on Linux, `export AUTOGRAPH_VERBOSITY=10`) and attach the full output. Cause: converting <bound method Conv.call of <tensorflow.python.layers.convolutional.Conv2D object at 0x7f6c904f7590>>: AssertionError: Bad argument number for Name: 3, expecting 4
WARNING:tensorflow:From train_image_classifier_biasCNN.py:683: The name tf.metrics.accuracy is deprecated. Please use tf.compat.v1.metrics.accuracy instead.

W0114 15:35:21.091053 140105975121728 deprecation_wrapper.py:119] From train_image_classifier_biasCNN.py:683: The name tf.metrics.accuracy is deprecated. Please use tf.compat.v1.metrics.accuracy instead.

WARNING:tensorflow:From train_image_classifier_biasCNN.py:684: streaming_recall_at_k (from tensorflow.contrib.metrics.python.ops.metric_ops) is deprecated and will be removed after 2016-11-08.
Instructions for updating:
Please use `streaming_sparse_recall_at_k`, and reshape labels from [batch_size] to [batch_size, 1].
W0114 15:35:21.106866 140105975121728 deprecation.py:323] From train_image_classifier_biasCNN.py:684: streaming_recall_at_k (from tensorflow.contrib.metrics.python.ops.metric_ops) is deprecated and will be removed after 2016-11-08.
Instructions for updating:
Please use `streaming_sparse_recall_at_k`, and reshape labels from [batch_size] to [batch_size, 1].
WARNING:tensorflow:From /home/AD/mmhender/anaconda3/lib/python3.7/site-packages/tensorflow/contrib/metrics/python/ops/metric_ops.py:2166: streaming_mean (from tensorflow.contrib.metrics.python.ops.metric_ops) is deprecated and will be removed in a future version.
Instructions for updating:
Please switch to tf.metrics.mean
W0114 15:35:21.108964 140105975121728 deprecation.py:323] From /home/AD/mmhender/anaconda3/lib/python3.7/site-packages/tensorflow/contrib/metrics/python/ops/metric_ops.py:2166: streaming_mean (from tensorflow.contrib.metrics.python.ops.metric_ops) is deprecated and will be removed in a future version.
Instructions for updating:
Please switch to tf.metrics.mean
WARNING:tensorflow:From /home/AD/mmhender/anaconda3/lib/python3.7/site-packages/tensorflow/python/util/tf_should_use.py:193: initialize_variables (from tensorflow.python.ops.variables) is deprecated and will be removed after 2017-03-02.
Instructions for updating:
Use `tf.variables_initializer` instead.
W0114 15:35:21.169223 140105975121728 deprecation.py:323] From /home/AD/mmhender/anaconda3/lib/python3.7/site-packages/tensorflow/python/util/tf_should_use.py:193: initialize_variables (from tensorflow.python.ops.variables) is deprecated and will be removed after 2017-03-02.
Instructions for updating:
Use `tf.variables_initializer` instead.
WARNING:tensorflow:From train_image_classifier_biasCNN.py:714: The name tf.summary.merge is deprecated. Please use tf.compat.v1.summary.merge instead.

W0114 15:35:21.169988 140105975121728 deprecation_wrapper.py:119] From train_image_classifier_biasCNN.py:714: The name tf.summary.merge is deprecated. Please use tf.compat.v1.summary.merge instead.

WARNING:tensorflow:From train_image_classifier_biasCNN.py:736: to_int64 (from tensorflow.python.ops.math_ops) is deprecated and will be removed in a future version.
Instructions for updating:
Use `tf.cast` instead.
W0114 15:35:21.279459 140105975121728 deprecation.py:323] From train_image_classifier_biasCNN.py:736: to_int64 (from tensorflow.python.ops.math_ops) is deprecated and will be removed in a future version.
Instructions for updating:
Use `tf.cast` instead.
WARNING:tensorflow:From /home/AD/mmhender/anaconda3/lib/python3.7/site-packages/tensorflow/contrib/slim/python/slim/learning.py:742: Supervisor.__init__ (from tensorflow.python.training.supervisor) is deprecated and will be removed in a future version.
Instructions for updating:
Please switch to tf.train.MonitoredTrainingSession
W0114 15:35:21.380896 140105975121728 deprecation.py:323] From /home/AD/mmhender/anaconda3/lib/python3.7/site-packages/tensorflow/contrib/slim/python/slim/learning.py:742: Supervisor.__init__ (from tensorflow.python.training.supervisor) is deprecated and will be removed in a future version.
Instructions for updating:
Please switch to tf.train.MonitoredTrainingSession
2020-01-14 15:35:21.589123: I tensorflow/stream_executor/platform/default/dso_loader.cc:42] Successfully opened dynamic library libcuda.so.1
2020-01-14 15:35:24.750868: I tensorflow/stream_executor/cuda/cuda_gpu_executor.cc:1005] successful NUMA node read from SysFS had negative value (-1), but there must be at least one NUMA node, so returning NUMA node zero
2020-01-14 15:35:24.751671: I tensorflow/core/common_runtime/gpu/gpu_device.cc:1640] Found device 0 with properties: 
name: Tesla K80 major: 3 minor: 7 memoryClockRate(GHz): 0.8235
pciBusID: 0000:06:00.0
2020-01-14 15:35:24.751755: I tensorflow/stream_executor/cuda/cuda_gpu_executor.cc:1005] successful NUMA node read from SysFS had negative value (-1), but there must be at least one NUMA node, so returning NUMA node zero
2020-01-14 15:35:24.752483: I tensorflow/core/common_runtime/gpu/gpu_device.cc:1640] Found device 1 with properties: 
name: Tesla K80 major: 3 minor: 7 memoryClockRate(GHz): 0.8235
pciBusID: 0000:07:00.0
2020-01-14 15:35:24.753800: I tensorflow/stream_executor/platform/default/dso_loader.cc:42] Successfully opened dynamic library libcudart.so.10.1
2020-01-14 15:35:24.757290: I tensorflow/stream_executor/platform/default/dso_loader.cc:42] Successfully opened dynamic library libcublas.so.10
2020-01-14 15:35:24.759580: I tensorflow/stream_executor/platform/default/dso_loader.cc:42] Successfully opened dynamic library libcufft.so.10
2020-01-14 15:35:24.760499: I tensorflow/stream_executor/platform/default/dso_loader.cc:42] Successfully opened dynamic library libcurand.so.10
2020-01-14 15:35:24.762734: I tensorflow/stream_executor/platform/default/dso_loader.cc:42] Successfully opened dynamic library libcusolver.so.10
2020-01-14 15:35:24.764068: I tensorflow/stream_executor/platform/default/dso_loader.cc:42] Successfully opened dynamic library libcusparse.so.10
2020-01-14 15:35:24.768712: I tensorflow/stream_executor/platform/default/dso_loader.cc:42] Successfully opened dynamic library libcudnn.so.7
2020-01-14 15:35:24.768896: I tensorflow/stream_executor/cuda/cuda_gpu_executor.cc:1005] successful NUMA node read from SysFS had negative value (-1), but there must be at least one NUMA node, so returning NUMA node zero
2020-01-14 15:35:24.769822: I tensorflow/stream_executor/cuda/cuda_gpu_executor.cc:1005] successful NUMA node read from SysFS had negative value (-1), but there must be at least one NUMA node, so returning NUMA node zero
2020-01-14 15:35:24.770683: I tensorflow/stream_executor/cuda/cuda_gpu_executor.cc:1005] successful NUMA node read from SysFS had negative value (-1), but there must be at least one NUMA node, so returning NUMA node zero
2020-01-14 15:35:24.771533: I tensorflow/stream_executor/cuda/cuda_gpu_executor.cc:1005] successful NUMA node read from SysFS had negative value (-1), but there must be at least one NUMA node, so returning NUMA node zero
2020-01-14 15:35:24.772323: I tensorflow/core/common_runtime/gpu/gpu_device.cc:1763] Adding visible gpu devices: 0, 1
2020-01-14 15:35:24.772851: I tensorflow/core/platform/cpu_feature_guard.cc:142] Your CPU supports instructions that this TensorFlow binary was not compiled to use: SSE4.1 SSE4.2 AVX
2020-01-14 15:35:24.800898: I tensorflow/core/platform/profile_utils/cpu_utils.cc:94] CPU Frequency: 2199950000 Hz
2020-01-14 15:35:24.804974: I tensorflow/compiler/xla/service/service.cc:168] XLA service 0x56448089d020 executing computations on platform Host. Devices:
2020-01-14 15:35:24.805019: I tensorflow/compiler/xla/service/service.cc:175]   StreamExecutor device (0): <undefined>, <undefined>
2020-01-14 15:35:24.918767: I tensorflow/stream_executor/cuda/cuda_gpu_executor.cc:1005] successful NUMA node read from SysFS had negative value (-1), but there must be at least one NUMA node, so returning NUMA node zero
2020-01-14 15:35:24.919566: I tensorflow/core/common_runtime/gpu/gpu_device.cc:1640] Found device 0 with properties: 
name: Tesla K80 major: 3 minor: 7 memoryClockRate(GHz): 0.8235
pciBusID: 0000:06:00.0
2020-01-14 15:35:24.919656: I tensorflow/stream_executor/cuda/cuda_gpu_executor.cc:1005] successful NUMA node read from SysFS had negative value (-1), but there must be at least one NUMA node, so returning NUMA node zero
2020-01-14 15:35:24.920375: I tensorflow/core/common_runtime/gpu/gpu_device.cc:1640] Found device 1 with properties: 
name: Tesla K80 major: 3 minor: 7 memoryClockRate(GHz): 0.8235
pciBusID: 0000:07:00.0
2020-01-14 15:35:24.920452: I tensorflow/stream_executor/platform/default/dso_loader.cc:42] Successfully opened dynamic library libcudart.so.10.1
2020-01-14 15:35:24.920481: I tensorflow/stream_executor/platform/default/dso_loader.cc:42] Successfully opened dynamic library libcublas.so.10
2020-01-14 15:35:24.920510: I tensorflow/stream_executor/platform/default/dso_loader.cc:42] Successfully opened dynamic library libcufft.so.10
2020-01-14 15:35:24.920553: I tensorflow/stream_executor/platform/default/dso_loader.cc:42] Successfully opened dynamic library libcurand.so.10
2020-01-14 15:35:24.920583: I tensorflow/stream_executor/platform/default/dso_loader.cc:42] Successfully opened dynamic library libcusolver.so.10
2020-01-14 15:35:24.920612: I tensorflow/stream_executor/platform/default/dso_loader.cc:42] Successfully opened dynamic library libcusparse.so.10
2020-01-14 15:35:24.920641: I tensorflow/stream_executor/platform/default/dso_loader.cc:42] Successfully opened dynamic library libcudnn.so.7
2020-01-14 15:35:24.920714: I tensorflow/stream_executor/cuda/cuda_gpu_executor.cc:1005] successful NUMA node read from SysFS had negative value (-1), but there must be at least one NUMA node, so returning NUMA node zero
2020-01-14 15:35:24.921482: I tensorflow/stream_executor/cuda/cuda_gpu_executor.cc:1005] successful NUMA node read from SysFS had negative value (-1), but there must be at least one NUMA node, so returning NUMA node zero
2020-01-14 15:35:24.922248: I tensorflow/stream_executor/cuda/cuda_gpu_executor.cc:1005] successful NUMA node read from SysFS had negative value (-1), but there must be at least one NUMA node, so returning NUMA node zero
2020-01-14 15:35:24.923014: I tensorflow/stream_executor/cuda/cuda_gpu_executor.cc:1005] successful NUMA node read from SysFS had negative value (-1), but there must be at least one NUMA node, so returning NUMA node zero
2020-01-14 15:35:24.923733: I tensorflow/core/common_runtime/gpu/gpu_device.cc:1763] Adding visible gpu devices: 0, 1
2020-01-14 15:35:24.923783: I tensorflow/stream_executor/platform/default/dso_loader.cc:42] Successfully opened dynamic library libcudart.so.10.1
2020-01-14 15:35:24.926250: I tensorflow/core/common_runtime/gpu/gpu_device.cc:1181] Device interconnect StreamExecutor with strength 1 edge matrix:
2020-01-14 15:35:24.926268: I tensorflow/core/common_runtime/gpu/gpu_device.cc:1187]      0 1 
2020-01-14 15:35:24.926279: I tensorflow/core/common_runtime/gpu/gpu_device.cc:1200] 0:   N Y 
2020-01-14 15:35:24.926286: I tensorflow/core/common_runtime/gpu/gpu_device.cc:1200] 1:   Y N 
2020-01-14 15:35:24.926433: I tensorflow/stream_executor/cuda/cuda_gpu_executor.cc:1005] successful NUMA node read from SysFS had negative value (-1), but there must be at least one NUMA node, so returning NUMA node zero
2020-01-14 15:35:24.927221: I tensorflow/stream_executor/cuda/cuda_gpu_executor.cc:1005] successful NUMA node read from SysFS had negative value (-1), but there must be at least one NUMA node, so returning NUMA node zero
2020-01-14 15:35:24.928000: I tensorflow/stream_executor/cuda/cuda_gpu_executor.cc:1005] successful NUMA node read from SysFS had negative value (-1), but there must be at least one NUMA node, so returning NUMA node zero
2020-01-14 15:35:24.928810: I tensorflow/stream_executor/cuda/cuda_gpu_executor.cc:1005] successful NUMA node read from SysFS had negative value (-1), but there must be at least one NUMA node, so returning NUMA node zero
2020-01-14 15:35:24.929577: I tensorflow/core/common_runtime/gpu/gpu_device.cc:1326] Created TensorFlow device (/job:localhost/replica:0/task:0/device:GPU:0 with 10805 MB memory) -> physical GPU (device: 0, name: Tesla K80, pci bus id: 0000:06:00.0, compute capability: 3.7)
2020-01-14 15:35:24.930614: I tensorflow/stream_executor/cuda/cuda_gpu_executor.cc:1005] successful NUMA node read from SysFS had negative value (-1), but there must be at least one NUMA node, so returning NUMA node zero
2020-01-14 15:35:24.931395: I tensorflow/stream_executor/cuda/cuda_gpu_executor.cc:1005] successful NUMA node read from SysFS had negative value (-1), but there must be at least one NUMA node, so returning NUMA node zero
2020-01-14 15:35:24.932125: I tensorflow/core/common_runtime/gpu/gpu_device.cc:1326] Created TensorFlow device (/job:localhost/replica:0/task:0/device:GPU:1 with 10805 MB memory) -> physical GPU (device: 1, name: Tesla K80, pci bus id: 0000:07:00.0, compute capability: 3.7)
2020-01-14 15:35:24.934838: I tensorflow/compiler/xla/service/service.cc:168] XLA service 0x564483871740 executing computations on platform CUDA. Devices:
2020-01-14 15:35:24.934858: I tensorflow/compiler/xla/service/service.cc:175]   StreamExecutor device (0): Tesla K80, Compute Capability 3.7
2020-01-14 15:35:24.934868: I tensorflow/compiler/xla/service/service.cc:175]   StreamExecutor device (1): Tesla K80, Compute Capability 3.7
WARNING:tensorflow:From /home/AD/mmhender/anaconda3/lib/python3.7/site-packages/tensorflow/python/training/saver.py:1276: checkpoint_exists (from tensorflow.python.training.checkpoint_management) is deprecated and will be removed in a future version.
Instructions for updating:
Use standard file APIs to check for files with this prefix.
W0114 15:35:24.941299 140105975121728 deprecation.py:323] From /home/AD/mmhender/anaconda3/lib/python3.7/site-packages/tensorflow/python/training/saver.py:1276: checkpoint_exists (from tensorflow.python.training.checkpoint_management) is deprecated and will be removed in a future version.
Instructions for updating:
Use standard file APIs to check for files with this prefix.
INFO:tensorflow:Restoring parameters from /cube/neurocube/local/serenceslab/maggie/biasCNN/logs/vgg16/ImageNet/scratch_imagenet_rot_22/test/model.ckpt-0
I0114 15:35:24.944059 140105975121728 saver.py:1280] Restoring parameters from /cube/neurocube/local/serenceslab/maggie/biasCNN/logs/vgg16/ImageNet/scratch_imagenet_rot_22/test/model.ckpt-0
2020-01-14 15:35:25.155896: W tensorflow/compiler/jit/mark_for_compilation_pass.cc:1412] (One-time warning): Not using XLA:CPU for cluster because envvar TF_XLA_FLAGS=--tf_xla_cpu_global_jit was not set.  If you want XLA:CPU, either set that envvar, or use experimental_jit_scope to enable XLA:CPU.  To confirm that XLA is active, pass --vmodule=xla_compilation_cache=1 (as a proper command-line flag, not via TF_XLA_FLAGS) or set the envvar XLA_FLAGS=--xla_hlo_profile.
WARNING:tensorflow:From /home/AD/mmhender/anaconda3/lib/python3.7/site-packages/tensorflow/python/training/saver.py:1066: get_checkpoint_mtimes (from tensorflow.python.training.checkpoint_management) is deprecated and will be removed in a future version.
Instructions for updating:
Use standard file utilities to get mtimes.
W0114 15:35:33.430734 140105975121728 deprecation.py:323] From /home/AD/mmhender/anaconda3/lib/python3.7/site-packages/tensorflow/python/training/saver.py:1066: get_checkpoint_mtimes (from tensorflow.python.training.checkpoint_management) is deprecated and will be removed in a future version.
Instructions for updating:
Use standard file utilities to get mtimes.
INFO:tensorflow:Running local_init_op.
I0114 15:35:33.432358 140105975121728 session_manager.py:500] Running local_init_op.
INFO:tensorflow:Done running local_init_op.
I0114 15:35:34.182073 140105975121728 session_manager.py:502] Done running local_init_op.
INFO:tensorflow:Starting Session.
I0114 15:35:35.723551 140105975121728 learning.py:754] Starting Session.
INFO:tensorflow:Saving checkpoint to path /cube/neurocube/local/serenceslab/maggie/biasCNN/logs/vgg16/ImageNet/scratch_imagenet_rot_22/test/model.ckpt
I0114 15:35:35.761648 140094384109312 supervisor.py:1117] Saving checkpoint to path /cube/neurocube/local/serenceslab/maggie/biasCNN/logs/vgg16/ImageNet/scratch_imagenet_rot_22/test/model.ckpt
INFO:tensorflow:Starting Queues.
I0114 15:35:35.772322 140105975121728 learning.py:768] Starting Queues.
INFO:tensorflow:global_step/sec: 0
I0114 15:35:37.051945 140094375716608 supervisor.py:1099] global_step/sec: 0
2020-01-14 15:35:38.447240: I tensorflow/stream_executor/platform/default/dso_loader.cc:42] Successfully opened dynamic library libcudnn.so.7
2020-01-14 15:35:45.534704: W tensorflow/core/common_runtime/bfc_allocator.cc:237] Allocator (GPU_0_bfc) ran out of memory trying to allocate 3.02GiB with freed_by_count=0. The caller indicates that this is not a failure, but may mean that there could be performance gains if more memory were available.
INFO:tensorflow:Recording summary at step 0.
I0114 15:35:53.254253 140094367323904 supervisor.py:1050] Recording summary at step 0.
INFO:tensorflow:global_step/sec: 0
I0114 15:35:56.401659 140094375716608 supervisor.py:1099] global_step/sec: 0
INFO:tensorflow:Recording summary at step 0.
I0114 15:36:00.808674 140094367323904 supervisor.py:1050] Recording summary at step 0.
INFO:tensorflow:global step 10: loss = 7.2262 (1.455 sec/step)
I0114 15:36:15.722776 140105975121728 learning.py:507] global step 10: loss = 7.2262 (1.455 sec/step)
INFO:tensorflow:EVALUATING MODEL AT STEP 10

I0114 15:36:15.727675 140105975121728 learning_biasCNN_NEW.py:48] EVALUATING MODEL AT STEP 10

2020-01-14 15:36:16.349482: W tensorflow/core/common_runtime/bfc_allocator.cc:237] Allocator (GPU_0_bfc) ran out of memory trying to allocate 3.02GiB with freed_by_count=0. The caller indicates that this is not a failure, but may mean that there could be performance gains if more memory were available.
INFO:tensorflow:global_step/sec: 0.5
I0114 15:36:16.401640 140094375716608 supervisor.py:1099] global_step/sec: 0.5
INFO:tensorflow:Recording summary at step 11.
I0114 15:36:21.156699 140094367323904 supervisor.py:1050] Recording summary at step 11.
INFO:tensorflow:global step 20: loss = 7.2024 (1.472 sec/step)
I0114 15:36:33.637339 140105975121728 learning.py:507] global step 20: loss = 7.2024 (1.472 sec/step)
INFO:tensorflow:EVALUATING MODEL AT STEP 20

I0114 15:36:33.643434 140105975121728 learning_biasCNN_NEW.py:48] EVALUATING MODEL AT STEP 20

INFO:tensorflow:global_step/sec: 0.549996
I0114 15:36:36.401803 140094375716608 supervisor.py:1099] global_step/sec: 0.549996
INFO:tensorflow:Recording summary at step 23.
I0114 15:36:41.053313 140094367323904 supervisor.py:1050] Recording summary at step 23.
INFO:tensorflow:global step 30: loss = 7.1624 (1.456 sec/step)
I0114 15:36:51.214219 140105975121728 learning.py:507] global step 30: loss = 7.1624 (1.456 sec/step)
INFO:tensorflow:EVALUATING MODEL AT STEP 30

I0114 15:36:51.219632 140105975121728 learning_biasCNN_NEW.py:48] EVALUATING MODEL AT STEP 30

INFO:tensorflow:global_step/sec: 0.549999
I0114 15:36:56.401873 140094375716608 supervisor.py:1099] global_step/sec: 0.549999
INFO:tensorflow:Recording summary at step 34.
I0114 15:37:01.251039 140094367323904 supervisor.py:1050] Recording summary at step 34.
INFO:tensorflow:global step 40: loss = 7.1679 (1.463 sec/step)
I0114 15:37:08.582650 140105975121728 learning.py:507] global step 40: loss = 7.1679 (1.463 sec/step)
INFO:tensorflow:EVALUATING MODEL AT STEP 40

I0114 15:37:08.587235 140105975121728 learning_biasCNN_NEW.py:48] EVALUATING MODEL AT STEP 40

INFO:tensorflow:global_step/sec: 0.600003
I0114 15:37:16.401762 140094375716608 supervisor.py:1099] global_step/sec: 0.600003
INFO:tensorflow:Recording summary at step 46.
I0114 15:37:21.076918 140094367323904 supervisor.py:1050] Recording summary at step 46.
INFO:tensorflow:global step 50: loss = 7.1678 (1.564 sec/step)
I0114 15:37:26.649617 140105975121728 learning.py:507] global step 50: loss = 7.1678 (1.564 sec/step)
INFO:tensorflow:RESETTING STREAMING EVAL METRICS AT STEP 50

I0114 15:37:26.654010 140105975121728 learning_biasCNN_NEW.py:41] RESETTING STREAMING EVAL METRICS AT STEP 50

INFO:tensorflow:EVALUATING MODEL AT STEP 50

I0114 15:37:26.701021 140105975121728 learning_biasCNN_NEW.py:48] EVALUATING MODEL AT STEP 50

INFO:tensorflow:global_step/sec: 0.549995
I0114 15:37:36.402042 140094375716608 supervisor.py:1099] global_step/sec: 0.549995
INFO:tensorflow:Recording summary at step 57.
I0114 15:37:41.242919 140094367323904 supervisor.py:1050] Recording summary at step 57.
INFO:tensorflow:global step 60: loss = 7.2007 (1.490 sec/step)
I0114 15:37:44.293548 140105975121728 learning.py:507] global step 60: loss = 7.2007 (1.490 sec/step)
INFO:tensorflow:EVALUATING MODEL AT STEP 60

I0114 15:37:44.298447 140105975121728 learning_biasCNN_NEW.py:48] EVALUATING MODEL AT STEP 60

INFO:tensorflow:global_step/sec: 0.599999
I0114 15:37:56.402054 140094375716608 supervisor.py:1099] global_step/sec: 0.599999
INFO:tensorflow:Recording summary at step 69.
I0114 15:38:00.856873 140094367323904 supervisor.py:1050] Recording summary at step 69.
INFO:tensorflow:global step 70: loss = 7.1847 (1.430 sec/step)
I0114 15:38:01.858706 140105975121728 learning.py:507] global step 70: loss = 7.1847 (1.430 sec/step)
INFO:tensorflow:EVALUATING MODEL AT STEP 70

I0114 15:38:01.863676 140105975121728 learning_biasCNN_NEW.py:48] EVALUATING MODEL AT STEP 70

slurmstepd-ssrde-c-406: error: *** JOB 16064 ON ssrde-c-406 CANCELLED AT 2020-01-14T15:38:07 ***
