script=/cube/neurocube/local/serenceslab/maggie/biasCNN/code/shell_scripts/TrainImageNetRots/train_net_cluster.sh
which_model=vgg_16
params=params1
rot=0_square
from_scratch=0
saving to /cube/neurocube/local/serenceslab/maggie/biasCNN/logs/vgg16/ImageNet/scratch_imagenet_rot_0_square/test
1000000
python train_image_classifier_biasCNN.py --train_dir=/cube/neurocube/local/serenceslab/maggie/biasCNN/logs/vgg16/ImageNet/scratch_imagenet_rot_0_square/test --dataset_name=imagenet --dataset_split_name=train --dataset_dir=/cube/neurocube/local/serenceslab/maggie/biasCNN/datasets/ImageNet/ILSVRC2012//tfrecord_rot_0_square/ --model_name=vgg_16 --max_number_of_steps=1000000 --flipLR=False --random_scale=False --is_windowed=True --weight_decay=0.00005 --rmsprop_decay=0.90 --rmsprop_momentum=0.80 --learning_rate=0.005 --learning_rate_decay_factor=0.94 --max_checkpoints_to_keep=5 --keep_checkpoint_every_n_hours=0.5 --batch_size=32
/home/AD/mmhender/anaconda3/lib/python3.7/site-packages/tensorflow/python/framework/dtypes.py:516: FutureWarning: Passing (type, 1) or '1type' as a synonym of type is deprecated; in a future version of numpy, it will be understood as (type, (1,)) / '(1,)type'.
  _np_qint8 = np.dtype([("qint8", np.int8, 1)])
/home/AD/mmhender/anaconda3/lib/python3.7/site-packages/tensorflow/python/framework/dtypes.py:517: FutureWarning: Passing (type, 1) or '1type' as a synonym of type is deprecated; in a future version of numpy, it will be understood as (type, (1,)) / '(1,)type'.
  _np_quint8 = np.dtype([("quint8", np.uint8, 1)])
/home/AD/mmhender/anaconda3/lib/python3.7/site-packages/tensorflow/python/framework/dtypes.py:518: FutureWarning: Passing (type, 1) or '1type' as a synonym of type is deprecated; in a future version of numpy, it will be understood as (type, (1,)) / '(1,)type'.
  _np_qint16 = np.dtype([("qint16", np.int16, 1)])
/home/AD/mmhender/anaconda3/lib/python3.7/site-packages/tensorflow/python/framework/dtypes.py:519: FutureWarning: Passing (type, 1) or '1type' as a synonym of type is deprecated; in a future version of numpy, it will be understood as (type, (1,)) / '(1,)type'.
  _np_quint16 = np.dtype([("quint16", np.uint16, 1)])
/home/AD/mmhender/anaconda3/lib/python3.7/site-packages/tensorflow/python/framework/dtypes.py:520: FutureWarning: Passing (type, 1) or '1type' as a synonym of type is deprecated; in a future version of numpy, it will be understood as (type, (1,)) / '(1,)type'.
  _np_qint32 = np.dtype([("qint32", np.int32, 1)])
/home/AD/mmhender/anaconda3/lib/python3.7/site-packages/tensorflow/python/framework/dtypes.py:525: FutureWarning: Passing (type, 1) or '1type' as a synonym of type is deprecated; in a future version of numpy, it will be understood as (type, (1,)) / '(1,)type'.
  np_resource = np.dtype([("resource", np.ubyte, 1)])
/home/AD/mmhender/anaconda3/lib/python3.7/site-packages/tensorboard/compat/tensorflow_stub/dtypes.py:541: FutureWarning: Passing (type, 1) or '1type' as a synonym of type is deprecated; in a future version of numpy, it will be understood as (type, (1,)) / '(1,)type'.
  _np_qint8 = np.dtype([("qint8", np.int8, 1)])
/home/AD/mmhender/anaconda3/lib/python3.7/site-packages/tensorboard/compat/tensorflow_stub/dtypes.py:542: FutureWarning: Passing (type, 1) or '1type' as a synonym of type is deprecated; in a future version of numpy, it will be understood as (type, (1,)) / '(1,)type'.
  _np_quint8 = np.dtype([("quint8", np.uint8, 1)])
/home/AD/mmhender/anaconda3/lib/python3.7/site-packages/tensorboard/compat/tensorflow_stub/dtypes.py:543: FutureWarning: Passing (type, 1) or '1type' as a synonym of type is deprecated; in a future version of numpy, it will be understood as (type, (1,)) / '(1,)type'.
  _np_qint16 = np.dtype([("qint16", np.int16, 1)])
/home/AD/mmhender/anaconda3/lib/python3.7/site-packages/tensorboard/compat/tensorflow_stub/dtypes.py:544: FutureWarning: Passing (type, 1) or '1type' as a synonym of type is deprecated; in a future version of numpy, it will be understood as (type, (1,)) / '(1,)type'.
  _np_quint16 = np.dtype([("quint16", np.uint16, 1)])
/home/AD/mmhender/anaconda3/lib/python3.7/site-packages/tensorboard/compat/tensorflow_stub/dtypes.py:545: FutureWarning: Passing (type, 1) or '1type' as a synonym of type is deprecated; in a future version of numpy, it will be understood as (type, (1,)) / '(1,)type'.
  _np_qint32 = np.dtype([("qint32", np.int32, 1)])
/home/AD/mmhender/anaconda3/lib/python3.7/site-packages/tensorboard/compat/tensorflow_stub/dtypes.py:550: FutureWarning: Passing (type, 1) or '1type' as a synonym of type is deprecated; in a future version of numpy, it will be understood as (type, (1,)) / '(1,)type'.
  np_resource = np.dtype([("resource", np.ubyte, 1)])
WARNING:tensorflow:
The TensorFlow contrib module will not be included in TensorFlow 2.0.
For more information, please see:
  * https://github.com/tensorflow/community/blob/master/rfcs/20180907-contrib-sunset.md
  * https://github.com/tensorflow/addons
  * https://github.com/tensorflow/io (for I/O related ops)
If you depend on functionality not listed there, please file an issue.

WARNING:tensorflow:From /cube/neurocube/local/serenceslab/maggie/tensorflow/models/research/slim/nets/inception_resnet_v2.py:373: The name tf.GraphKeys is deprecated. Please use tf.compat.v1.GraphKeys instead.

WARNING:tensorflow:From /cube/neurocube/local/serenceslab/maggie/tensorflow/models/research/slim/nets/mobilenet/mobilenet.py:389: The name tf.nn.avg_pool is deprecated. Please use tf.nn.avg_pool2d instead.

WARNING:tensorflow:From train_image_classifier_biasCNN.py:762: The name tf.app.run is deprecated. Please use tf.compat.v1.app.run instead.

WARNING:tensorflow:From train_image_classifier_biasCNN.py:445: The name tf.logging.set_verbosity is deprecated. Please use tf.compat.v1.logging.set_verbosity instead.

W0114 15:40:17.367271 139807972955968 deprecation_wrapper.py:119] From train_image_classifier_biasCNN.py:445: The name tf.logging.set_verbosity is deprecated. Please use tf.compat.v1.logging.set_verbosity instead.

WARNING:tensorflow:From train_image_classifier_biasCNN.py:445: The name tf.logging.INFO is deprecated. Please use tf.compat.v1.logging.INFO instead.

W0114 15:40:17.367700 139807972955968 deprecation_wrapper.py:119] From train_image_classifier_biasCNN.py:445: The name tf.logging.INFO is deprecated. Please use tf.compat.v1.logging.INFO instead.

WARNING:tensorflow:From train_image_classifier_biasCNN.py:459: create_global_step (from tensorflow.contrib.framework.python.ops.variables) is deprecated and will be removed in a future version.
Instructions for updating:
Please switch to tf.train.create_global_step
W0114 15:40:17.369175 139807972955968 deprecation.py:323] From train_image_classifier_biasCNN.py:459: create_global_step (from tensorflow.contrib.framework.python.ops.variables) is deprecated and will be removed in a future version.
Instructions for updating:
Please switch to tf.train.create_global_step
WARNING:tensorflow:From /cube/neurocube/local/serenceslab/maggie/tensorflow/models/research/slim/datasets/imagenet.py:151: The name tf.FixedLenFeature is deprecated. Please use tf.io.FixedLenFeature instead.

W0114 15:40:17.379275 139807972955968 deprecation_wrapper.py:119] From /cube/neurocube/local/serenceslab/maggie/tensorflow/models/research/slim/datasets/imagenet.py:151: The name tf.FixedLenFeature is deprecated. Please use tf.io.FixedLenFeature instead.

WARNING:tensorflow:From /cube/neurocube/local/serenceslab/maggie/tensorflow/models/research/slim/datasets/imagenet.py:159: The name tf.VarLenFeature is deprecated. Please use tf.io.VarLenFeature instead.

W0114 15:40:17.379525 139807972955968 deprecation_wrapper.py:119] From /cube/neurocube/local/serenceslab/maggie/tensorflow/models/research/slim/datasets/imagenet.py:159: The name tf.VarLenFeature is deprecated. Please use tf.io.VarLenFeature instead.

WARNING:tensorflow:From /cube/neurocube/local/serenceslab/maggie/tensorflow/models/research/slim/datasets/dataset_utils.py:127: The name tf.gfile.Exists is deprecated. Please use tf.io.gfile.exists instead.

W0114 15:40:17.379780 139807972955968 deprecation_wrapper.py:119] From /cube/neurocube/local/serenceslab/maggie/tensorflow/models/research/slim/datasets/dataset_utils.py:127: The name tf.gfile.Exists is deprecated. Please use tf.io.gfile.exists instead.

WARNING:tensorflow:From /cube/neurocube/local/serenceslab/maggie/tensorflow/models/research/slim/datasets/dataset_utils.py:141: The name tf.gfile.Open is deprecated. Please use tf.io.gfile.GFile instead.

W0114 15:40:17.380030 139807972955968 deprecation_wrapper.py:119] From /cube/neurocube/local/serenceslab/maggie/tensorflow/models/research/slim/datasets/dataset_utils.py:141: The name tf.gfile.Open is deprecated. Please use tf.io.gfile.GFile instead.

WARNING:tensorflow:From /home/AD/mmhender/anaconda3/lib/python3.7/site-packages/tensorflow/contrib/slim/python/slim/data/parallel_reader.py:246: string_input_producer (from tensorflow.python.training.input) is deprecated and will be removed in a future version.
Instructions for updating:
Queue-based input pipelines have been replaced by `tf.data`. Use `tf.data.Dataset.from_tensor_slices(string_tensor).shuffle(tf.shape(input_tensor, out_type=tf.int64)[0]).repeat(num_epochs)`. If `shuffle=False`, omit the `.shuffle(...)`.
W0114 15:40:17.516496 139807972955968 deprecation.py:323] From /home/AD/mmhender/anaconda3/lib/python3.7/site-packages/tensorflow/contrib/slim/python/slim/data/parallel_reader.py:246: string_input_producer (from tensorflow.python.training.input) is deprecated and will be removed in a future version.
Instructions for updating:
Queue-based input pipelines have been replaced by `tf.data`. Use `tf.data.Dataset.from_tensor_slices(string_tensor).shuffle(tf.shape(input_tensor, out_type=tf.int64)[0]).repeat(num_epochs)`. If `shuffle=False`, omit the `.shuffle(...)`.
WARNING:tensorflow:From /home/AD/mmhender/anaconda3/lib/python3.7/site-packages/tensorflow/python/training/input.py:278: input_producer (from tensorflow.python.training.input) is deprecated and will be removed in a future version.
Instructions for updating:
Queue-based input pipelines have been replaced by `tf.data`. Use `tf.data.Dataset.from_tensor_slices(input_tensor).shuffle(tf.shape(input_tensor, out_type=tf.int64)[0]).repeat(num_epochs)`. If `shuffle=False`, omit the `.shuffle(...)`.
W0114 15:40:17.533077 139807972955968 deprecation.py:323] From /home/AD/mmhender/anaconda3/lib/python3.7/site-packages/tensorflow/python/training/input.py:278: input_producer (from tensorflow.python.training.input) is deprecated and will be removed in a future version.
Instructions for updating:
Queue-based input pipelines have been replaced by `tf.data`. Use `tf.data.Dataset.from_tensor_slices(input_tensor).shuffle(tf.shape(input_tensor, out_type=tf.int64)[0]).repeat(num_epochs)`. If `shuffle=False`, omit the `.shuffle(...)`.
WARNING:tensorflow:From /home/AD/mmhender/anaconda3/lib/python3.7/site-packages/tensorflow/python/training/input.py:190: limit_epochs (from tensorflow.python.training.input) is deprecated and will be removed in a future version.
Instructions for updating:
Queue-based input pipelines have been replaced by `tf.data`. Use `tf.data.Dataset.from_tensors(tensor).repeat(num_epochs)`.
W0114 15:40:17.534250 139807972955968 deprecation.py:323] From /home/AD/mmhender/anaconda3/lib/python3.7/site-packages/tensorflow/python/training/input.py:190: limit_epochs (from tensorflow.python.training.input) is deprecated and will be removed in a future version.
Instructions for updating:
Queue-based input pipelines have been replaced by `tf.data`. Use `tf.data.Dataset.from_tensors(tensor).repeat(num_epochs)`.
WARNING:tensorflow:From /home/AD/mmhender/anaconda3/lib/python3.7/site-packages/tensorflow/python/training/input.py:199: QueueRunner.__init__ (from tensorflow.python.training.queue_runner_impl) is deprecated and will be removed in a future version.
Instructions for updating:
To construct input pipelines, use the `tf.data` module.
W0114 15:40:17.536568 139807972955968 deprecation.py:323] From /home/AD/mmhender/anaconda3/lib/python3.7/site-packages/tensorflow/python/training/input.py:199: QueueRunner.__init__ (from tensorflow.python.training.queue_runner_impl) is deprecated and will be removed in a future version.
Instructions for updating:
To construct input pipelines, use the `tf.data` module.
WARNING:tensorflow:From /home/AD/mmhender/anaconda3/lib/python3.7/site-packages/tensorflow/python/training/input.py:199: add_queue_runner (from tensorflow.python.training.queue_runner_impl) is deprecated and will be removed in a future version.
Instructions for updating:
To construct input pipelines, use the `tf.data` module.
W0114 15:40:17.538068 139807972955968 deprecation.py:323] From /home/AD/mmhender/anaconda3/lib/python3.7/site-packages/tensorflow/python/training/input.py:199: add_queue_runner (from tensorflow.python.training.queue_runner_impl) is deprecated and will be removed in a future version.
Instructions for updating:
To construct input pipelines, use the `tf.data` module.
WARNING:tensorflow:From /home/AD/mmhender/anaconda3/lib/python3.7/site-packages/tensorflow/contrib/slim/python/slim/data/parallel_reader.py:95: TFRecordReader.__init__ (from tensorflow.python.ops.io_ops) is deprecated and will be removed in a future version.
Instructions for updating:
Queue-based input pipelines have been replaced by `tf.data`. Use `tf.data.TFRecordDataset`.
W0114 15:40:17.549184 139807972955968 deprecation.py:323] From /home/AD/mmhender/anaconda3/lib/python3.7/site-packages/tensorflow/contrib/slim/python/slim/data/parallel_reader.py:95: TFRecordReader.__init__ (from tensorflow.python.ops.io_ops) is deprecated and will be removed in a future version.
Instructions for updating:
Queue-based input pipelines have been replaced by `tf.data`. Use `tf.data.TFRecordDataset`.
WARNING:tensorflow:From /cube/neurocube/local/serenceslab/maggie/tensorflow/models/research/slim/preprocessing/vgg_preprocessing_biasCNN.py:327: The name tf.assert_equal is deprecated. Please use tf.compat.v1.assert_equal instead.

W0114 15:40:17.709664 139807972955968 deprecation_wrapper.py:119] From /cube/neurocube/local/serenceslab/maggie/tensorflow/models/research/slim/preprocessing/vgg_preprocessing_biasCNN.py:327: The name tf.assert_equal is deprecated. Please use tf.compat.v1.assert_equal instead.

ERROR:tensorflow:==================================
Object was never used (type <class 'tensorflow.python.framework.ops.Operation'>):
<tf.Operation 'assert_equal/Assert/Assert' type=Assert>
If you want to mark it as used call its "mark_used()" method.
It was originally created here:
  File "train_image_classifier_biasCNN.py", line 762, in <module>
    tf.app.run()  File "/home/AD/mmhender/anaconda3/lib/python3.7/site-packages/tensorflow/python/platform/app.py", line 40, in run
    _run(main=main, argv=argv, flags_parser=_parse_flags_tolerate_undef)  File "/home/AD/mmhender/anaconda3/lib/python3.7/site-packages/absl/app.py", line 299, in run
    _run_main(main, args)  File "/home/AD/mmhender/anaconda3/lib/python3.7/site-packages/absl/app.py", line 250, in _run_main
    sys.exit(main(argv))  File "train_image_classifier_biasCNN.py", line 512, in main
    image = image_preprocessing_fn(image, train_image_size, train_image_size)  File "/cube/neurocube/local/serenceslab/maggie/tensorflow/models/research/slim/preprocessing/preprocessing_biasCNN.py", line 54, in preprocessing_fn
    image, output_height, output_width, is_training=is_training, flipLR=flipLR, random_scale=random_scale, is_windowed=is_windowed, **kwargs)  File "/cube/neurocube/local/serenceslab/maggie/tensorflow/models/research/slim/preprocessing/vgg_preprocessing_biasCNN.py", line 408, in preprocess_image
    resize_side_min, resize_side_max, flipLR, random_scale, is_windowed)  File "/cube/neurocube/local/serenceslab/maggie/tensorflow/models/research/slim/preprocessing/vgg_preprocessing_biasCNN.py", line 327, in preprocess_for_train
    tf.assert_equal(shape[0],shape[1])  File "/home/AD/mmhender/anaconda3/lib/python3.7/site-packages/tensorflow/python/ops/check_ops.py", line 557, in assert_equal
    return control_flow_ops.Assert(condition, data, summarize=summarize)  File "/home/AD/mmhender/anaconda3/lib/python3.7/site-packages/tensorflow/python/util/tf_should_use.py", line 193, in wrapped
    return _add_should_use_warning(fn(*args, **kwargs))
==================================
E0114 15:40:17.731044 139807972955968 tf_should_use.py:71] ==================================
Object was never used (type <class 'tensorflow.python.framework.ops.Operation'>):
<tf.Operation 'assert_equal/Assert/Assert' type=Assert>
If you want to mark it as used call its "mark_used()" method.
It was originally created here:
  File "train_image_classifier_biasCNN.py", line 762, in <module>
    tf.app.run()  File "/home/AD/mmhender/anaconda3/lib/python3.7/site-packages/tensorflow/python/platform/app.py", line 40, in run
    _run(main=main, argv=argv, flags_parser=_parse_flags_tolerate_undef)  File "/home/AD/mmhender/anaconda3/lib/python3.7/site-packages/absl/app.py", line 299, in run
    _run_main(main, args)  File "/home/AD/mmhender/anaconda3/lib/python3.7/site-packages/absl/app.py", line 250, in _run_main
    sys.exit(main(argv))  File "train_image_classifier_biasCNN.py", line 512, in main
    image = image_preprocessing_fn(image, train_image_size, train_image_size)  File "/cube/neurocube/local/serenceslab/maggie/tensorflow/models/research/slim/preprocessing/preprocessing_biasCNN.py", line 54, in preprocessing_fn
    image, output_height, output_width, is_training=is_training, flipLR=flipLR, random_scale=random_scale, is_windowed=is_windowed, **kwargs)  File "/cube/neurocube/local/serenceslab/maggie/tensorflow/models/research/slim/preprocessing/vgg_preprocessing_biasCNN.py", line 408, in preprocess_image
    resize_side_min, resize_side_max, flipLR, random_scale, is_windowed)  File "/cube/neurocube/local/serenceslab/maggie/tensorflow/models/research/slim/preprocessing/vgg_preprocessing_biasCNN.py", line 327, in preprocess_for_train
    tf.assert_equal(shape[0],shape[1])  File "/home/AD/mmhender/anaconda3/lib/python3.7/site-packages/tensorflow/python/ops/check_ops.py", line 557, in assert_equal
    return control_flow_ops.Assert(condition, data, summarize=summarize)  File "/home/AD/mmhender/anaconda3/lib/python3.7/site-packages/tensorflow/python/util/tf_should_use.py", line 193, in wrapped
    return _add_should_use_warning(fn(*args, **kwargs))
==================================
ERROR:tensorflow:==================================
Object was never used (type <class 'tensorflow.python.framework.ops.Operation'>):
<tf.Operation 'assert_equal_1/Assert/Assert' type=Assert>
If you want to mark it as used call its "mark_used()" method.
It was originally created here:
  File "train_image_classifier_biasCNN.py", line 762, in <module>
    tf.app.run()  File "/home/AD/mmhender/anaconda3/lib/python3.7/site-packages/tensorflow/python/platform/app.py", line 40, in run
    _run(main=main, argv=argv, flags_parser=_parse_flags_tolerate_undef)  File "/home/AD/mmhender/anaconda3/lib/python3.7/site-packages/absl/app.py", line 299, in run
    _run_main(main, args)  File "/home/AD/mmhender/anaconda3/lib/python3.7/site-packages/absl/app.py", line 250, in _run_main
    sys.exit(main(argv))  File "train_image_classifier_biasCNN.py", line 512, in main
    image = image_preprocessing_fn(image, train_image_size, train_image_size)  File "/cube/neurocube/local/serenceslab/maggie/tensorflow/models/research/slim/preprocessing/preprocessing_biasCNN.py", line 54, in preprocessing_fn
    image, output_height, output_width, is_training=is_training, flipLR=flipLR, random_scale=random_scale, is_windowed=is_windowed, **kwargs)  File "/cube/neurocube/local/serenceslab/maggie/tensorflow/models/research/slim/preprocessing/vgg_preprocessing_biasCNN.py", line 408, in preprocess_image
    resize_side_min, resize_side_max, flipLR, random_scale, is_windowed)  File "/cube/neurocube/local/serenceslab/maggie/tensorflow/models/research/slim/preprocessing/vgg_preprocessing_biasCNN.py", line 328, in preprocess_for_train
    tf.assert_equal(shape[0],output_height)  File "/home/AD/mmhender/anaconda3/lib/python3.7/site-packages/tensorflow/python/ops/check_ops.py", line 557, in assert_equal
    return control_flow_ops.Assert(condition, data, summarize=summarize)  File "/home/AD/mmhender/anaconda3/lib/python3.7/site-packages/tensorflow/python/util/tf_should_use.py", line 193, in wrapped
    return _add_should_use_warning(fn(*args, **kwargs))
==================================
E0114 15:40:17.744870 139807972955968 tf_should_use.py:71] ==================================
Object was never used (type <class 'tensorflow.python.framework.ops.Operation'>):
<tf.Operation 'assert_equal_1/Assert/Assert' type=Assert>
If you want to mark it as used call its "mark_used()" method.
It was originally created here:
  File "train_image_classifier_biasCNN.py", line 762, in <module>
    tf.app.run()  File "/home/AD/mmhender/anaconda3/lib/python3.7/site-packages/tensorflow/python/platform/app.py", line 40, in run
    _run(main=main, argv=argv, flags_parser=_parse_flags_tolerate_undef)  File "/home/AD/mmhender/anaconda3/lib/python3.7/site-packages/absl/app.py", line 299, in run
    _run_main(main, args)  File "/home/AD/mmhender/anaconda3/lib/python3.7/site-packages/absl/app.py", line 250, in _run_main
    sys.exit(main(argv))  File "train_image_classifier_biasCNN.py", line 512, in main
    image = image_preprocessing_fn(image, train_image_size, train_image_size)  File "/cube/neurocube/local/serenceslab/maggie/tensorflow/models/research/slim/preprocessing/preprocessing_biasCNN.py", line 54, in preprocessing_fn
    image, output_height, output_width, is_training=is_training, flipLR=flipLR, random_scale=random_scale, is_windowed=is_windowed, **kwargs)  File "/cube/neurocube/local/serenceslab/maggie/tensorflow/models/research/slim/preprocessing/vgg_preprocessing_biasCNN.py", line 408, in preprocess_image
    resize_side_min, resize_side_max, flipLR, random_scale, is_windowed)  File "/cube/neurocube/local/serenceslab/maggie/tensorflow/models/research/slim/preprocessing/vgg_preprocessing_biasCNN.py", line 328, in preprocess_for_train
    tf.assert_equal(shape[0],output_height)  File "/home/AD/mmhender/anaconda3/lib/python3.7/site-packages/tensorflow/python/ops/check_ops.py", line 557, in assert_equal
    return control_flow_ops.Assert(condition, data, summarize=summarize)  File "/home/AD/mmhender/anaconda3/lib/python3.7/site-packages/tensorflow/python/util/tf_should_use.py", line 193, in wrapped
    return _add_should_use_warning(fn(*args, **kwargs))
==================================
WARNING:tensorflow:From /cube/neurocube/local/serenceslab/maggie/tensorflow/models/research/slim/preprocessing/vgg_preprocessing_biasCNN.py:335: to_float (from tensorflow.python.ops.math_ops) is deprecated and will be removed in a future version.
Instructions for updating:
Use `tf.cast` instead.
W0114 15:40:17.745121 139807972955968 deprecation.py:323] From /cube/neurocube/local/serenceslab/maggie/tensorflow/models/research/slim/preprocessing/vgg_preprocessing_biasCNN.py:335: to_float (from tensorflow.python.ops.math_ops) is deprecated and will be removed in a future version.
Instructions for updating:
Use `tf.cast` instead.
WARNING:tensorflow:From train_image_classifier_biasCNN.py:518: batch (from tensorflow.python.training.input) is deprecated and will be removed in a future version.
Instructions for updating:
Queue-based input pipelines have been replaced by `tf.data`. Use `tf.data.Dataset.batch(batch_size)` (or `padded_batch(...)` if `dynamic_pad=True`).
W0114 15:40:17.755177 139807972955968 deprecation.py:323] From train_image_classifier_biasCNN.py:518: batch (from tensorflow.python.training.input) is deprecated and will be removed in a future version.
Instructions for updating:
Queue-based input pipelines have been replaced by `tf.data`. Use `tf.data.Dataset.batch(batch_size)` (or `padded_batch(...)` if `dynamic_pad=True`).
ERROR:tensorflow:==================================
Object was never used (type <class 'tensorflow.python.framework.ops.Operation'>):
<tf.Operation 'assert_equal_2/Assert/Assert' type=Assert>
If you want to mark it as used call its "mark_used()" method.
It was originally created here:
  File "train_image_classifier_biasCNN.py", line 762, in <module>
    tf.app.run()  File "/home/AD/mmhender/anaconda3/lib/python3.7/site-packages/tensorflow/python/platform/app.py", line 40, in run
    _run(main=main, argv=argv, flags_parser=_parse_flags_tolerate_undef)  File "/home/AD/mmhender/anaconda3/lib/python3.7/site-packages/absl/app.py", line 299, in run
    _run_main(main, args)  File "/home/AD/mmhender/anaconda3/lib/python3.7/site-packages/absl/app.py", line 250, in _run_main
    sys.exit(main(argv))  File "train_image_classifier_biasCNN.py", line 537, in main
    image_val = image_preprocessing_fn_val(image_val, eval_image_size, eval_image_size)  File "/cube/neurocube/local/serenceslab/maggie/tensorflow/models/research/slim/preprocessing/preprocessing_biasCNN.py", line 54, in preprocessing_fn
    image, output_height, output_width, is_training=is_training, flipLR=flipLR, random_scale=random_scale, is_windowed=is_windowed, **kwargs)  File "/cube/neurocube/local/serenceslab/maggie/tensorflow/models/research/slim/preprocessing/vgg_preprocessing_biasCNN.py", line 411, in preprocess_image
    resize_side_min, is_windowed)  File "/cube/neurocube/local/serenceslab/maggie/tensorflow/models/research/slim/preprocessing/vgg_preprocessing_biasCNN.py", line 363, in preprocess_for_eval
    tf.assert_equal(shape[0],shape[1])  File "/home/AD/mmhender/anaconda3/lib/python3.7/site-packages/tensorflow/python/ops/check_ops.py", line 557, in assert_equal
    return control_flow_ops.Assert(condition, data, summarize=summarize)  File "/home/AD/mmhender/anaconda3/lib/python3.7/site-packages/tensorflow/python/util/tf_should_use.py", line 193, in wrapped
    return _add_should_use_warning(fn(*args, **kwargs))
==================================
E0114 15:40:17.983389 139807972955968 tf_should_use.py:71] ==================================
Object was never used (type <class 'tensorflow.python.framework.ops.Operation'>):
<tf.Operation 'assert_equal_2/Assert/Assert' type=Assert>
If you want to mark it as used call its "mark_used()" method.
It was originally created here:
  File "train_image_classifier_biasCNN.py", line 762, in <module>
    tf.app.run()  File "/home/AD/mmhender/anaconda3/lib/python3.7/site-packages/tensorflow/python/platform/app.py", line 40, in run
    _run(main=main, argv=argv, flags_parser=_parse_flags_tolerate_undef)  File "/home/AD/mmhender/anaconda3/lib/python3.7/site-packages/absl/app.py", line 299, in run
    _run_main(main, args)  File "/home/AD/mmhender/anaconda3/lib/python3.7/site-packages/absl/app.py", line 250, in _run_main
    sys.exit(main(argv))  File "train_image_classifier_biasCNN.py", line 537, in main
    image_val = image_preprocessing_fn_val(image_val, eval_image_size, eval_image_size)  File "/cube/neurocube/local/serenceslab/maggie/tensorflow/models/research/slim/preprocessing/preprocessing_biasCNN.py", line 54, in preprocessing_fn
    image, output_height, output_width, is_training=is_training, flipLR=flipLR, random_scale=random_scale, is_windowed=is_windowed, **kwargs)  File "/cube/neurocube/local/serenceslab/maggie/tensorflow/models/research/slim/preprocessing/vgg_preprocessing_biasCNN.py", line 411, in preprocess_image
    resize_side_min, is_windowed)  File "/cube/neurocube/local/serenceslab/maggie/tensorflow/models/research/slim/preprocessing/vgg_preprocessing_biasCNN.py", line 363, in preprocess_for_eval
    tf.assert_equal(shape[0],shape[1])  File "/home/AD/mmhender/anaconda3/lib/python3.7/site-packages/tensorflow/python/ops/check_ops.py", line 557, in assert_equal
    return control_flow_ops.Assert(condition, data, summarize=summarize)  File "/home/AD/mmhender/anaconda3/lib/python3.7/site-packages/tensorflow/python/util/tf_should_use.py", line 193, in wrapped
    return _add_should_use_warning(fn(*args, **kwargs))
==================================
ERROR:tensorflow:==================================
Object was never used (type <class 'tensorflow.python.framework.ops.Operation'>):
<tf.Operation 'assert_equal_3/Assert/Assert' type=Assert>
If you want to mark it as used call its "mark_used()" method.
It was originally created here:
  File "train_image_classifier_biasCNN.py", line 762, in <module>
    tf.app.run()  File "/home/AD/mmhender/anaconda3/lib/python3.7/site-packages/tensorflow/python/platform/app.py", line 40, in run
    _run(main=main, argv=argv, flags_parser=_parse_flags_tolerate_undef)  File "/home/AD/mmhender/anaconda3/lib/python3.7/site-packages/absl/app.py", line 299, in run
    _run_main(main, args)  File "/home/AD/mmhender/anaconda3/lib/python3.7/site-packages/absl/app.py", line 250, in _run_main
    sys.exit(main(argv))  File "train_image_classifier_biasCNN.py", line 537, in main
    image_val = image_preprocessing_fn_val(image_val, eval_image_size, eval_image_size)  File "/cube/neurocube/local/serenceslab/maggie/tensorflow/models/research/slim/preprocessing/preprocessing_biasCNN.py", line 54, in preprocessing_fn
    image, output_height, output_width, is_training=is_training, flipLR=flipLR, random_scale=random_scale, is_windowed=is_windowed, **kwargs)  File "/cube/neurocube/local/serenceslab/maggie/tensorflow/models/research/slim/preprocessing/vgg_preprocessing_biasCNN.py", line 411, in preprocess_image
    resize_side_min, is_windowed)  File "/cube/neurocube/local/serenceslab/maggie/tensorflow/models/research/slim/preprocessing/vgg_preprocessing_biasCNN.py", line 364, in preprocess_for_eval
    tf.assert_equal(shape[0],output_height)  File "/home/AD/mmhender/anaconda3/lib/python3.7/site-packages/tensorflow/python/ops/check_ops.py", line 557, in assert_equal
    return control_flow_ops.Assert(condition, data, summarize=summarize)  File "/home/AD/mmhender/anaconda3/lib/python3.7/site-packages/tensorflow/python/util/tf_should_use.py", line 193, in wrapped
    return _add_should_use_warning(fn(*args, **kwargs))
==================================
E0114 15:40:17.997221 139807972955968 tf_should_use.py:71] ==================================
Object was never used (type <class 'tensorflow.python.framework.ops.Operation'>):
<tf.Operation 'assert_equal_3/Assert/Assert' type=Assert>
If you want to mark it as used call its "mark_used()" method.
It was originally created here:
  File "train_image_classifier_biasCNN.py", line 762, in <module>
    tf.app.run()  File "/home/AD/mmhender/anaconda3/lib/python3.7/site-packages/tensorflow/python/platform/app.py", line 40, in run
    _run(main=main, argv=argv, flags_parser=_parse_flags_tolerate_undef)  File "/home/AD/mmhender/anaconda3/lib/python3.7/site-packages/absl/app.py", line 299, in run
    _run_main(main, args)  File "/home/AD/mmhender/anaconda3/lib/python3.7/site-packages/absl/app.py", line 250, in _run_main
    sys.exit(main(argv))  File "train_image_classifier_biasCNN.py", line 537, in main
    image_val = image_preprocessing_fn_val(image_val, eval_image_size, eval_image_size)  File "/cube/neurocube/local/serenceslab/maggie/tensorflow/models/research/slim/preprocessing/preprocessing_biasCNN.py", line 54, in preprocessing_fn
    image, output_height, output_width, is_training=is_training, flipLR=flipLR, random_scale=random_scale, is_windowed=is_windowed, **kwargs)  File "/cube/neurocube/local/serenceslab/maggie/tensorflow/models/research/slim/preprocessing/vgg_preprocessing_biasCNN.py", line 411, in preprocess_image
    resize_side_min, is_windowed)  File "/cube/neurocube/local/serenceslab/maggie/tensorflow/models/research/slim/preprocessing/vgg_preprocessing_biasCNN.py", line 364, in preprocess_for_eval
    tf.assert_equal(shape[0],output_height)  File "/home/AD/mmhender/anaconda3/lib/python3.7/site-packages/tensorflow/python/ops/check_ops.py", line 557, in assert_equal
    return control_flow_ops.Assert(condition, data, summarize=summarize)  File "/home/AD/mmhender/anaconda3/lib/python3.7/site-packages/tensorflow/python/util/tf_should_use.py", line 193, in wrapped
    return _add_should_use_warning(fn(*args, **kwargs))
==================================
WARNING:tensorflow:From train_image_classifier_biasCNN.py:572: The name tf.get_collection is deprecated. Please use tf.compat.v1.get_collection instead.

W0114 15:40:18.023013 139807972955968 deprecation_wrapper.py:119] From train_image_classifier_biasCNN.py:572: The name tf.get_collection is deprecated. Please use tf.compat.v1.get_collection instead.

WARNING:tensorflow:Entity <bound method Conv.call of <tensorflow.python.layers.convolutional.Conv2D object at 0x7f2727fc4c10>> could not be transformed and will be executed as-is. Please report this to the AutgoGraph team. When filing the bug, set the verbosity to 10 (on Linux, `export AUTOGRAPH_VERBOSITY=10`) and attach the full output. Cause: converting <bound method Conv.call of <tensorflow.python.layers.convolutional.Conv2D object at 0x7f2727fc4c10>>: AssertionError: Bad argument number for Name: 3, expecting 4
W0114 15:40:18.257061 139807972955968 ag_logging.py:145] Entity <bound method Conv.call of <tensorflow.python.layers.convolutional.Conv2D object at 0x7f2727fc4c10>> could not be transformed and will be executed as-is. Please report this to the AutgoGraph team. When filing the bug, set the verbosity to 10 (on Linux, `export AUTOGRAPH_VERBOSITY=10`) and attach the full output. Cause: converting <bound method Conv.call of <tensorflow.python.layers.convolutional.Conv2D object at 0x7f2727fc4c10>>: AssertionError: Bad argument number for Name: 3, expecting 4
WARNING:tensorflow:Entity <bound method Conv.call of <tensorflow.python.layers.convolutional.Conv2D object at 0x7f2727fc4c90>> could not be transformed and will be executed as-is. Please report this to the AutgoGraph team. When filing the bug, set the verbosity to 10 (on Linux, `export AUTOGRAPH_VERBOSITY=10`) and attach the full output. Cause: converting <bound method Conv.call of <tensorflow.python.layers.convolutional.Conv2D object at 0x7f2727fc4c90>>: AssertionError: Bad argument number for Name: 3, expecting 4
W0114 15:40:18.388464 139807972955968 ag_logging.py:145] Entity <bound method Conv.call of <tensorflow.python.layers.convolutional.Conv2D object at 0x7f2727fc4c90>> could not be transformed and will be executed as-is. Please report this to the AutgoGraph team. When filing the bug, set the verbosity to 10 (on Linux, `export AUTOGRAPH_VERBOSITY=10`) and attach the full output. Cause: converting <bound method Conv.call of <tensorflow.python.layers.convolutional.Conv2D object at 0x7f2727fc4c90>>: AssertionError: Bad argument number for Name: 3, expecting 4
WARNING:tensorflow:Entity <bound method Pooling2D.call of <tensorflow.python.layers.pooling.MaxPooling2D object at 0x7f2727fc4a10>> could not be transformed and will be executed as-is. Please report this to the AutgoGraph team. When filing the bug, set the verbosity to 10 (on Linux, `export AUTOGRAPH_VERBOSITY=10`) and attach the full output. Cause: converting <bound method Pooling2D.call of <tensorflow.python.layers.pooling.MaxPooling2D object at 0x7f2727fc4a10>>: AssertionError: Bad argument number for Name: 3, expecting 4
W0114 15:40:18.467777 139807972955968 ag_logging.py:145] Entity <bound method Pooling2D.call of <tensorflow.python.layers.pooling.MaxPooling2D object at 0x7f2727fc4a10>> could not be transformed and will be executed as-is. Please report this to the AutgoGraph team. When filing the bug, set the verbosity to 10 (on Linux, `export AUTOGRAPH_VERBOSITY=10`) and attach the full output. Cause: converting <bound method Pooling2D.call of <tensorflow.python.layers.pooling.MaxPooling2D object at 0x7f2727fc4a10>>: AssertionError: Bad argument number for Name: 3, expecting 4
WARNING:tensorflow:Entity <bound method Conv.call of <tensorflow.python.layers.convolutional.Conv2D object at 0x7f2727fe1810>> could not be transformed and will be executed as-is. Please report this to the AutgoGraph team. When filing the bug, set the verbosity to 10 (on Linux, `export AUTOGRAPH_VERBOSITY=10`) and attach the full output. Cause: converting <bound method Conv.call of <tensorflow.python.layers.convolutional.Conv2D object at 0x7f2727fe1810>>: AssertionError: Bad argument number for Name: 3, expecting 4
W0114 15:40:18.597665 139807972955968 ag_logging.py:145] Entity <bound method Conv.call of <tensorflow.python.layers.convolutional.Conv2D object at 0x7f2727fe1810>> could not be transformed and will be executed as-is. Please report this to the AutgoGraph team. When filing the bug, set the verbosity to 10 (on Linux, `export AUTOGRAPH_VERBOSITY=10`) and attach the full output. Cause: converting <bound method Conv.call of <tensorflow.python.layers.convolutional.Conv2D object at 0x7f2727fe1810>>: AssertionError: Bad argument number for Name: 3, expecting 4
WARNING:tensorflow:Entity <bound method Conv.call of <tensorflow.python.layers.convolutional.Conv2D object at 0x7f2727fe1050>> could not be transformed and will be executed as-is. Please report this to the AutgoGraph team. When filing the bug, set the verbosity to 10 (on Linux, `export AUTOGRAPH_VERBOSITY=10`) and attach the full output. Cause: converting <bound method Conv.call of <tensorflow.python.layers.convolutional.Conv2D object at 0x7f2727fe1050>>: AssertionError: Bad argument number for Name: 3, expecting 4
W0114 15:40:18.728580 139807972955968 ag_logging.py:145] Entity <bound method Conv.call of <tensorflow.python.layers.convolutional.Conv2D object at 0x7f2727fe1050>> could not be transformed and will be executed as-is. Please report this to the AutgoGraph team. When filing the bug, set the verbosity to 10 (on Linux, `export AUTOGRAPH_VERBOSITY=10`) and attach the full output. Cause: converting <bound method Conv.call of <tensorflow.python.layers.convolutional.Conv2D object at 0x7f2727fe1050>>: AssertionError: Bad argument number for Name: 3, expecting 4
WARNING:tensorflow:Entity <bound method Pooling2D.call of <tensorflow.python.layers.pooling.MaxPooling2D object at 0x7f2727fc4a90>> could not be transformed and will be executed as-is. Please report this to the AutgoGraph team. When filing the bug, set the verbosity to 10 (on Linux, `export AUTOGRAPH_VERBOSITY=10`) and attach the full output. Cause: converting <bound method Pooling2D.call of <tensorflow.python.layers.pooling.MaxPooling2D object at 0x7f2727fc4a90>>: AssertionError: Bad argument number for Name: 3, expecting 4
W0114 15:40:18.799440 139807972955968 ag_logging.py:145] Entity <bound method Pooling2D.call of <tensorflow.python.layers.pooling.MaxPooling2D object at 0x7f2727fc4a90>> could not be transformed and will be executed as-is. Please report this to the AutgoGraph team. When filing the bug, set the verbosity to 10 (on Linux, `export AUTOGRAPH_VERBOSITY=10`) and attach the full output. Cause: converting <bound method Pooling2D.call of <tensorflow.python.layers.pooling.MaxPooling2D object at 0x7f2727fc4a90>>: AssertionError: Bad argument number for Name: 3, expecting 4
WARNING:tensorflow:Entity <bound method Conv.call of <tensorflow.python.layers.convolutional.Conv2D object at 0x7f2727f046d0>> could not be transformed and will be executed as-is. Please report this to the AutgoGraph team. When filing the bug, set the verbosity to 10 (on Linux, `export AUTOGRAPH_VERBOSITY=10`) and attach the full output. Cause: converting <bound method Conv.call of <tensorflow.python.layers.convolutional.Conv2D object at 0x7f2727f046d0>>: AssertionError: Bad argument number for Name: 3, expecting 4
W0114 15:40:18.938948 139807972955968 ag_logging.py:145] Entity <bound method Conv.call of <tensorflow.python.layers.convolutional.Conv2D object at 0x7f2727f046d0>> could not be transformed and will be executed as-is. Please report this to the AutgoGraph team. When filing the bug, set the verbosity to 10 (on Linux, `export AUTOGRAPH_VERBOSITY=10`) and attach the full output. Cause: converting <bound method Conv.call of <tensorflow.python.layers.convolutional.Conv2D object at 0x7f2727f046d0>>: AssertionError: Bad argument number for Name: 3, expecting 4
WARNING:tensorflow:Entity <bound method Conv.call of <tensorflow.python.layers.convolutional.Conv2D object at 0x7f2727f5fe90>> could not be transformed and will be executed as-is. Please report this to the AutgoGraph team. When filing the bug, set the verbosity to 10 (on Linux, `export AUTOGRAPH_VERBOSITY=10`) and attach the full output. Cause: converting <bound method Conv.call of <tensorflow.python.layers.convolutional.Conv2D object at 0x7f2727f5fe90>>: AssertionError: Bad argument number for Name: 3, expecting 4
W0114 15:40:19.116995 139807972955968 ag_logging.py:145] Entity <bound method Conv.call of <tensorflow.python.layers.convolutional.Conv2D object at 0x7f2727f5fe90>> could not be transformed and will be executed as-is. Please report this to the AutgoGraph team. When filing the bug, set the verbosity to 10 (on Linux, `export AUTOGRAPH_VERBOSITY=10`) and attach the full output. Cause: converting <bound method Conv.call of <tensorflow.python.layers.convolutional.Conv2D object at 0x7f2727f5fe90>>: AssertionError: Bad argument number for Name: 3, expecting 4
WARNING:tensorflow:Entity <bound method Conv.call of <tensorflow.python.layers.convolutional.Conv2D object at 0x7f2727f17810>> could not be transformed and will be executed as-is. Please report this to the AutgoGraph team. When filing the bug, set the verbosity to 10 (on Linux, `export AUTOGRAPH_VERBOSITY=10`) and attach the full output. Cause: converting <bound method Conv.call of <tensorflow.python.layers.convolutional.Conv2D object at 0x7f2727f17810>>: AssertionError: Bad argument number for Name: 3, expecting 4
W0114 15:40:19.226652 139807972955968 ag_logging.py:145] Entity <bound method Conv.call of <tensorflow.python.layers.convolutional.Conv2D object at 0x7f2727f17810>> could not be transformed and will be executed as-is. Please report this to the AutgoGraph team. When filing the bug, set the verbosity to 10 (on Linux, `export AUTOGRAPH_VERBOSITY=10`) and attach the full output. Cause: converting <bound method Conv.call of <tensorflow.python.layers.convolutional.Conv2D object at 0x7f2727f17810>>: AssertionError: Bad argument number for Name: 3, expecting 4
WARNING:tensorflow:Entity <bound method Pooling2D.call of <tensorflow.python.layers.pooling.MaxPooling2D object at 0x7f2727f04490>> could not be transformed and will be executed as-is. Please report this to the AutgoGraph team. When filing the bug, set the verbosity to 10 (on Linux, `export AUTOGRAPH_VERBOSITY=10`) and attach the full output. Cause: converting <bound method Pooling2D.call of <tensorflow.python.layers.pooling.MaxPooling2D object at 0x7f2727f04490>>: AssertionError: Bad argument number for Name: 3, expecting 4
W0114 15:40:19.291768 139807972955968 ag_logging.py:145] Entity <bound method Pooling2D.call of <tensorflow.python.layers.pooling.MaxPooling2D object at 0x7f2727f04490>> could not be transformed and will be executed as-is. Please report this to the AutgoGraph team. When filing the bug, set the verbosity to 10 (on Linux, `export AUTOGRAPH_VERBOSITY=10`) and attach the full output. Cause: converting <bound method Pooling2D.call of <tensorflow.python.layers.pooling.MaxPooling2D object at 0x7f2727f04490>>: AssertionError: Bad argument number for Name: 3, expecting 4
WARNING:tensorflow:Entity <bound method Conv.call of <tensorflow.python.layers.convolutional.Conv2D object at 0x7f2727fc4910>> could not be transformed and will be executed as-is. Please report this to the AutgoGraph team. When filing the bug, set the verbosity to 10 (on Linux, `export AUTOGRAPH_VERBOSITY=10`) and attach the full output. Cause: converting <bound method Conv.call of <tensorflow.python.layers.convolutional.Conv2D object at 0x7f2727fc4910>>: AssertionError: Bad argument number for Name: 3, expecting 4
W0114 15:40:19.397821 139807972955968 ag_logging.py:145] Entity <bound method Conv.call of <tensorflow.python.layers.convolutional.Conv2D object at 0x7f2727fc4910>> could not be transformed and will be executed as-is. Please report this to the AutgoGraph team. When filing the bug, set the verbosity to 10 (on Linux, `export AUTOGRAPH_VERBOSITY=10`) and attach the full output. Cause: converting <bound method Conv.call of <tensorflow.python.layers.convolutional.Conv2D object at 0x7f2727fc4910>>: AssertionError: Bad argument number for Name: 3, expecting 4
WARNING:tensorflow:Entity <bound method Conv.call of <tensorflow.python.layers.convolutional.Conv2D object at 0x7f2727ff0c90>> could not be transformed and will be executed as-is. Please report this to the AutgoGraph team. When filing the bug, set the verbosity to 10 (on Linux, `export AUTOGRAPH_VERBOSITY=10`) and attach the full output. Cause: converting <bound method Conv.call of <tensorflow.python.layers.convolutional.Conv2D object at 0x7f2727ff0c90>>: AssertionError: Bad argument number for Name: 3, expecting 4
W0114 15:40:19.505107 139807972955968 ag_logging.py:145] Entity <bound method Conv.call of <tensorflow.python.layers.convolutional.Conv2D object at 0x7f2727ff0c90>> could not be transformed and will be executed as-is. Please report this to the AutgoGraph team. When filing the bug, set the verbosity to 10 (on Linux, `export AUTOGRAPH_VERBOSITY=10`) and attach the full output. Cause: converting <bound method Conv.call of <tensorflow.python.layers.convolutional.Conv2D object at 0x7f2727ff0c90>>: AssertionError: Bad argument number for Name: 3, expecting 4
WARNING:tensorflow:Entity <bound method Conv.call of <tensorflow.python.layers.convolutional.Conv2D object at 0x7f2727ebb650>> could not be transformed and will be executed as-is. Please report this to the AutgoGraph team. When filing the bug, set the verbosity to 10 (on Linux, `export AUTOGRAPH_VERBOSITY=10`) and attach the full output. Cause: converting <bound method Conv.call of <tensorflow.python.layers.convolutional.Conv2D object at 0x7f2727ebb650>>: AssertionError: Bad argument number for Name: 3, expecting 4
W0114 15:40:19.611609 139807972955968 ag_logging.py:145] Entity <bound method Conv.call of <tensorflow.python.layers.convolutional.Conv2D object at 0x7f2727ebb650>> could not be transformed and will be executed as-is. Please report this to the AutgoGraph team. When filing the bug, set the verbosity to 10 (on Linux, `export AUTOGRAPH_VERBOSITY=10`) and attach the full output. Cause: converting <bound method Conv.call of <tensorflow.python.layers.convolutional.Conv2D object at 0x7f2727ebb650>>: AssertionError: Bad argument number for Name: 3, expecting 4
WARNING:tensorflow:Entity <bound method Pooling2D.call of <tensorflow.python.layers.pooling.MaxPooling2D object at 0x7f2727f7b6d0>> could not be transformed and will be executed as-is. Please report this to the AutgoGraph team. When filing the bug, set the verbosity to 10 (on Linux, `export AUTOGRAPH_VERBOSITY=10`) and attach the full output. Cause: converting <bound method Pooling2D.call of <tensorflow.python.layers.pooling.MaxPooling2D object at 0x7f2727f7b6d0>>: AssertionError: Bad argument number for Name: 3, expecting 4
W0114 15:40:19.675870 139807972955968 ag_logging.py:145] Entity <bound method Pooling2D.call of <tensorflow.python.layers.pooling.MaxPooling2D object at 0x7f2727f7b6d0>> could not be transformed and will be executed as-is. Please report this to the AutgoGraph team. When filing the bug, set the verbosity to 10 (on Linux, `export AUTOGRAPH_VERBOSITY=10`) and attach the full output. Cause: converting <bound method Pooling2D.call of <tensorflow.python.layers.pooling.MaxPooling2D object at 0x7f2727f7b6d0>>: AssertionError: Bad argument number for Name: 3, expecting 4
WARNING:tensorflow:Entity <bound method Conv.call of <tensorflow.python.layers.convolutional.Conv2D object at 0x7f2727e68bd0>> could not be transformed and will be executed as-is. Please report this to the AutgoGraph team. When filing the bug, set the verbosity to 10 (on Linux, `export AUTOGRAPH_VERBOSITY=10`) and attach the full output. Cause: converting <bound method Conv.call of <tensorflow.python.layers.convolutional.Conv2D object at 0x7f2727e68bd0>>: AssertionError: Bad argument number for Name: 3, expecting 4
W0114 15:40:19.781600 139807972955968 ag_logging.py:145] Entity <bound method Conv.call of <tensorflow.python.layers.convolutional.Conv2D object at 0x7f2727e68bd0>> could not be transformed and will be executed as-is. Please report this to the AutgoGraph team. When filing the bug, set the verbosity to 10 (on Linux, `export AUTOGRAPH_VERBOSITY=10`) and attach the full output. Cause: converting <bound method Conv.call of <tensorflow.python.layers.convolutional.Conv2D object at 0x7f2727e68bd0>>: AssertionError: Bad argument number for Name: 3, expecting 4
WARNING:tensorflow:Entity <bound method Conv.call of <tensorflow.python.layers.convolutional.Conv2D object at 0x7f2727f04410>> could not be transformed and will be executed as-is. Please report this to the AutgoGraph team. When filing the bug, set the verbosity to 10 (on Linux, `export AUTOGRAPH_VERBOSITY=10`) and attach the full output. Cause: converting <bound method Conv.call of <tensorflow.python.layers.convolutional.Conv2D object at 0x7f2727f04410>>: AssertionError: Bad argument number for Name: 3, expecting 4
W0114 15:40:19.888314 139807972955968 ag_logging.py:145] Entity <bound method Conv.call of <tensorflow.python.layers.convolutional.Conv2D object at 0x7f2727f04410>> could not be transformed and will be executed as-is. Please report this to the AutgoGraph team. When filing the bug, set the verbosity to 10 (on Linux, `export AUTOGRAPH_VERBOSITY=10`) and attach the full output. Cause: converting <bound method Conv.call of <tensorflow.python.layers.convolutional.Conv2D object at 0x7f2727f04410>>: AssertionError: Bad argument number for Name: 3, expecting 4
WARNING:tensorflow:Entity <bound method Conv.call of <tensorflow.python.layers.convolutional.Conv2D object at 0x7f2727e68990>> could not be transformed and will be executed as-is. Please report this to the AutgoGraph team. When filing the bug, set the verbosity to 10 (on Linux, `export AUTOGRAPH_VERBOSITY=10`) and attach the full output. Cause: converting <bound method Conv.call of <tensorflow.python.layers.convolutional.Conv2D object at 0x7f2727e68990>>: AssertionError: Bad argument number for Name: 3, expecting 4
W0114 15:40:19.995318 139807972955968 ag_logging.py:145] Entity <bound method Conv.call of <tensorflow.python.layers.convolutional.Conv2D object at 0x7f2727e68990>> could not be transformed and will be executed as-is. Please report this to the AutgoGraph team. When filing the bug, set the verbosity to 10 (on Linux, `export AUTOGRAPH_VERBOSITY=10`) and attach the full output. Cause: converting <bound method Conv.call of <tensorflow.python.layers.convolutional.Conv2D object at 0x7f2727e68990>>: AssertionError: Bad argument number for Name: 3, expecting 4
WARNING:tensorflow:Entity <bound method Pooling2D.call of <tensorflow.python.layers.pooling.MaxPooling2D object at 0x7f2727ecfbd0>> could not be transformed and will be executed as-is. Please report this to the AutgoGraph team. When filing the bug, set the verbosity to 10 (on Linux, `export AUTOGRAPH_VERBOSITY=10`) and attach the full output. Cause: converting <bound method Pooling2D.call of <tensorflow.python.layers.pooling.MaxPooling2D object at 0x7f2727ecfbd0>>: AssertionError: Bad argument number for Name: 3, expecting 4
W0114 15:40:20.059686 139807972955968 ag_logging.py:145] Entity <bound method Pooling2D.call of <tensorflow.python.layers.pooling.MaxPooling2D object at 0x7f2727ecfbd0>> could not be transformed and will be executed as-is. Please report this to the AutgoGraph team. When filing the bug, set the verbosity to 10 (on Linux, `export AUTOGRAPH_VERBOSITY=10`) and attach the full output. Cause: converting <bound method Pooling2D.call of <tensorflow.python.layers.pooling.MaxPooling2D object at 0x7f2727ecfbd0>>: AssertionError: Bad argument number for Name: 3, expecting 4
WARNING:tensorflow:Entity <bound method Conv.call of <tensorflow.python.layers.convolutional.Conv2D object at 0x7f2727f53490>> could not be transformed and will be executed as-is. Please report this to the AutgoGraph team. When filing the bug, set the verbosity to 10 (on Linux, `export AUTOGRAPH_VERBOSITY=10`) and attach the full output. Cause: converting <bound method Conv.call of <tensorflow.python.layers.convolutional.Conv2D object at 0x7f2727f53490>>: AssertionError: Bad argument number for Name: 3, expecting 4
W0114 15:40:20.167524 139807972955968 ag_logging.py:145] Entity <bound method Conv.call of <tensorflow.python.layers.convolutional.Conv2D object at 0x7f2727f53490>> could not be transformed and will be executed as-is. Please report this to the AutgoGraph team. When filing the bug, set the verbosity to 10 (on Linux, `export AUTOGRAPH_VERBOSITY=10`) and attach the full output. Cause: converting <bound method Conv.call of <tensorflow.python.layers.convolutional.Conv2D object at 0x7f2727f53490>>: AssertionError: Bad argument number for Name: 3, expecting 4
WARNING:tensorflow:Entity <bound method Dropout.call of <tensorflow.python.layers.core.Dropout object at 0x7f2727e70190>> could not be transformed and will be executed as-is. Please report this to the AutgoGraph team. When filing the bug, set the verbosity to 10 (on Linux, `export AUTOGRAPH_VERBOSITY=10`) and attach the full output. Cause: converting <bound method Dropout.call of <tensorflow.python.layers.core.Dropout object at 0x7f2727e70190>>: AssertionError: Bad argument number for Name: 3, expecting 4
W0114 15:40:20.188621 139807972955968 ag_logging.py:145] Entity <bound method Dropout.call of <tensorflow.python.layers.core.Dropout object at 0x7f2727e70190>> could not be transformed and will be executed as-is. Please report this to the AutgoGraph team. When filing the bug, set the verbosity to 10 (on Linux, `export AUTOGRAPH_VERBOSITY=10`) and attach the full output. Cause: converting <bound method Dropout.call of <tensorflow.python.layers.core.Dropout object at 0x7f2727e70190>>: AssertionError: Bad argument number for Name: 3, expecting 4
WARNING:tensorflow:Entity <bound method Conv.call of <tensorflow.python.layers.convolutional.Conv2D object at 0x7f2727f5a0d0>> could not be transformed and will be executed as-is. Please report this to the AutgoGraph team. When filing the bug, set the verbosity to 10 (on Linux, `export AUTOGRAPH_VERBOSITY=10`) and attach the full output. Cause: converting <bound method Conv.call of <tensorflow.python.layers.convolutional.Conv2D object at 0x7f2727f5a0d0>>: AssertionError: Bad argument number for Name: 3, expecting 4
W0114 15:40:20.306127 139807972955968 ag_logging.py:145] Entity <bound method Conv.call of <tensorflow.python.layers.convolutional.Conv2D object at 0x7f2727f5a0d0>> could not be transformed and will be executed as-is. Please report this to the AutgoGraph team. When filing the bug, set the verbosity to 10 (on Linux, `export AUTOGRAPH_VERBOSITY=10`) and attach the full output. Cause: converting <bound method Conv.call of <tensorflow.python.layers.convolutional.Conv2D object at 0x7f2727f5a0d0>>: AssertionError: Bad argument number for Name: 3, expecting 4
WARNING:tensorflow:Entity <bound method Dropout.call of <tensorflow.python.layers.core.Dropout object at 0x7f2727d61a10>> could not be transformed and will be executed as-is. Please report this to the AutgoGraph team. When filing the bug, set the verbosity to 10 (on Linux, `export AUTOGRAPH_VERBOSITY=10`) and attach the full output. Cause: converting <bound method Dropout.call of <tensorflow.python.layers.core.Dropout object at 0x7f2727d61a10>>: AssertionError: Bad argument number for Name: 3, expecting 4
W0114 15:40:20.326842 139807972955968 ag_logging.py:145] Entity <bound method Dropout.call of <tensorflow.python.layers.core.Dropout object at 0x7f2727d61a10>> could not be transformed and will be executed as-is. Please report this to the AutgoGraph team. When filing the bug, set the verbosity to 10 (on Linux, `export AUTOGRAPH_VERBOSITY=10`) and attach the full output. Cause: converting <bound method Dropout.call of <tensorflow.python.layers.core.Dropout object at 0x7f2727d61a10>>: AssertionError: Bad argument number for Name: 3, expecting 4
WARNING:tensorflow:Entity <bound method Conv.call of <tensorflow.python.layers.convolutional.Conv2D object at 0x7f2727dd0610>> could not be transformed and will be executed as-is. Please report this to the AutgoGraph team. When filing the bug, set the verbosity to 10 (on Linux, `export AUTOGRAPH_VERBOSITY=10`) and attach the full output. Cause: converting <bound method Conv.call of <tensorflow.python.layers.convolutional.Conv2D object at 0x7f2727dd0610>>: AssertionError: Bad argument number for Name: 3, expecting 4
W0114 15:40:20.443952 139807972955968 ag_logging.py:145] Entity <bound method Conv.call of <tensorflow.python.layers.convolutional.Conv2D object at 0x7f2727dd0610>> could not be transformed and will be executed as-is. Please report this to the AutgoGraph team. When filing the bug, set the verbosity to 10 (on Linux, `export AUTOGRAPH_VERBOSITY=10`) and attach the full output. Cause: converting <bound method Conv.call of <tensorflow.python.layers.convolutional.Conv2D object at 0x7f2727dd0610>>: AssertionError: Bad argument number for Name: 3, expecting 4
WARNING:tensorflow:From train_image_classifier_biasCNN.py:567: The name tf.losses.softmax_cross_entropy is deprecated. Please use tf.compat.v1.losses.softmax_cross_entropy instead.

W0114 15:40:20.447721 139807972955968 deprecation_wrapper.py:119] From train_image_classifier_biasCNN.py:567: The name tf.losses.softmax_cross_entropy is deprecated. Please use tf.compat.v1.losses.softmax_cross_entropy instead.

WARNING:tensorflow:From /home/AD/mmhender/anaconda3/lib/python3.7/site-packages/tensorflow/python/ops/losses/losses_impl.py:121: add_dispatch_support.<locals>.wrapper (from tensorflow.python.ops.array_ops) is deprecated and will be removed in a future version.
Instructions for updating:
Use tf.where in 2.0, which has the same broadcast rule as np.where
W0114 15:40:20.485711 139807972955968 deprecation.py:323] From /home/AD/mmhender/anaconda3/lib/python3.7/site-packages/tensorflow/python/ops/losses/losses_impl.py:121: add_dispatch_support.<locals>.wrapper (from tensorflow.python.ops.array_ops) is deprecated and will be removed in a future version.
Instructions for updating:
Use tf.where in 2.0, which has the same broadcast rule as np.where
WARNING:tensorflow:From train_image_classifier_biasCNN.py:588: The name tf.summary.image is deprecated. Please use tf.compat.v1.summary.image instead.

W0114 15:40:20.496706 139807972955968 deprecation_wrapper.py:119] From train_image_classifier_biasCNN.py:588: The name tf.summary.image is deprecated. Please use tf.compat.v1.summary.image instead.

WARNING:tensorflow:From train_image_classifier_biasCNN.py:589: The name tf.summary.histogram is deprecated. Please use tf.compat.v1.summary.histogram instead.

W0114 15:40:20.513957 139807972955968 deprecation_wrapper.py:119] From train_image_classifier_biasCNN.py:589: The name tf.summary.histogram is deprecated. Please use tf.compat.v1.summary.histogram instead.

WARNING:tensorflow:From train_image_classifier_biasCNN.py:590: The name tf.summary.scalar is deprecated. Please use tf.compat.v1.summary.scalar instead.

W0114 15:40:20.515442 139807972955968 deprecation_wrapper.py:119] From train_image_classifier_biasCNN.py:590: The name tf.summary.scalar is deprecated. Please use tf.compat.v1.summary.scalar instead.

WARNING:tensorflow:From train_image_classifier_biasCNN.py:301: The name tf.train.exponential_decay is deprecated. Please use tf.compat.v1.train.exponential_decay instead.

W0114 15:40:21.228458 139807972955968 deprecation_wrapper.py:119] From train_image_classifier_biasCNN.py:301: The name tf.train.exponential_decay is deprecated. Please use tf.compat.v1.train.exponential_decay instead.

WARNING:tensorflow:From train_image_classifier_biasCNN.py:362: The name tf.train.RMSPropOptimizer is deprecated. Please use tf.compat.v1.train.RMSPropOptimizer instead.

W0114 15:40:21.236481 139807972955968 deprecation_wrapper.py:119] From train_image_classifier_biasCNN.py:362: The name tf.train.RMSPropOptimizer is deprecated. Please use tf.compat.v1.train.RMSPropOptimizer instead.

WARNING:tensorflow:From /home/AD/mmhender/anaconda3/lib/python3.7/site-packages/tensorflow/python/training/rmsprop.py:119: calling Ones.__init__ (from tensorflow.python.ops.init_ops) with dtype is deprecated and will be removed in a future version.
Instructions for updating:
Call initializer instance with the dtype argument instead of passing it to the constructor
W0114 15:40:21.858516 139807972955968 deprecation.py:506] From /home/AD/mmhender/anaconda3/lib/python3.7/site-packages/tensorflow/python/training/rmsprop.py:119: calling Ones.__init__ (from tensorflow.python.ops.init_ops) with dtype is deprecated and will be removed in a future version.
Instructions for updating:
Call initializer instance with the dtype argument instead of passing it to the constructor
INFO:tensorflow:Scale of 0 disables regularizer.
I0114 15:40:22.294886 139807972955968 regularizers.py:98] Scale of 0 disables regularizer.
WARNING:tensorflow:Entity <bound method Conv.call of <tensorflow.python.layers.convolutional.Conv2D object at 0x7f272739dfd0>> could not be transformed and will be executed as-is. Please report this to the AutgoGraph team. When filing the bug, set the verbosity to 10 (on Linux, `export AUTOGRAPH_VERBOSITY=10`) and attach the full output. Cause: converting <bound method Conv.call of <tensorflow.python.layers.convolutional.Conv2D object at 0x7f272739dfd0>>: AssertionError: Bad argument number for Name: 3, expecting 4
W0114 15:40:22.397117 139807972955968 ag_logging.py:145] Entity <bound method Conv.call of <tensorflow.python.layers.convolutional.Conv2D object at 0x7f272739dfd0>> could not be transformed and will be executed as-is. Please report this to the AutgoGraph team. When filing the bug, set the verbosity to 10 (on Linux, `export AUTOGRAPH_VERBOSITY=10`) and attach the full output. Cause: converting <bound method Conv.call of <tensorflow.python.layers.convolutional.Conv2D object at 0x7f272739dfd0>>: AssertionError: Bad argument number for Name: 3, expecting 4
WARNING:tensorflow:Entity <bound method Conv.call of <tensorflow.python.layers.convolutional.Conv2D object at 0x7f27274ccc10>> could not be transformed and will be executed as-is. Please report this to the AutgoGraph team. When filing the bug, set the verbosity to 10 (on Linux, `export AUTOGRAPH_VERBOSITY=10`) and attach the full output. Cause: converting <bound method Conv.call of <tensorflow.python.layers.convolutional.Conv2D object at 0x7f27274ccc10>>: AssertionError: Bad argument number for Name: 3, expecting 4
W0114 15:40:22.488333 139807972955968 ag_logging.py:145] Entity <bound method Conv.call of <tensorflow.python.layers.convolutional.Conv2D object at 0x7f27274ccc10>> could not be transformed and will be executed as-is. Please report this to the AutgoGraph team. When filing the bug, set the verbosity to 10 (on Linux, `export AUTOGRAPH_VERBOSITY=10`) and attach the full output. Cause: converting <bound method Conv.call of <tensorflow.python.layers.convolutional.Conv2D object at 0x7f27274ccc10>>: AssertionError: Bad argument number for Name: 3, expecting 4
WARNING:tensorflow:Entity <bound method Pooling2D.call of <tensorflow.python.layers.pooling.MaxPooling2D object at 0x7f272748ac90>> could not be transformed and will be executed as-is. Please report this to the AutgoGraph team. When filing the bug, set the verbosity to 10 (on Linux, `export AUTOGRAPH_VERBOSITY=10`) and attach the full output. Cause: converting <bound method Pooling2D.call of <tensorflow.python.layers.pooling.MaxPooling2D object at 0x7f272748ac90>>: AssertionError: Bad argument number for Name: 3, expecting 4
W0114 15:40:22.552233 139807972955968 ag_logging.py:145] Entity <bound method Pooling2D.call of <tensorflow.python.layers.pooling.MaxPooling2D object at 0x7f272748ac90>> could not be transformed and will be executed as-is. Please report this to the AutgoGraph team. When filing the bug, set the verbosity to 10 (on Linux, `export AUTOGRAPH_VERBOSITY=10`) and attach the full output. Cause: converting <bound method Pooling2D.call of <tensorflow.python.layers.pooling.MaxPooling2D object at 0x7f272748ac90>>: AssertionError: Bad argument number for Name: 3, expecting 4
slurmstepd-ssrde-c-401: error: *** JOB 16066 ON ssrde-c-401 CANCELLED AT 2020-01-14T15:40:22 ***
