script=/cube/neurocube/local/serenceslab/maggie/biasCNN/code/shell_scripts/TrainImageNetRots/train_vgg16_cluster_params1_testrestart.sh
rot=45
saving to /cube/neurocube/local/serenceslab/maggie/biasCNN/logs/vgg16/ImageNet/scratch_vgg16_imagenet_rot_45/init1_testrestart
1500000
python train_image_classifier_biasCNN_TEST.py --train_dir=/cube/neurocube/local/serenceslab/maggie/biasCNN/logs/vgg16/ImageNet/scratch_vgg16_imagenet_rot_45/init1_testrestart --dataset_name=imagenet --dataset_split_name=train --dataset_dir=/cube/neurocube/local/serenceslab/maggie/biasCNN/datasets/ImageNet/ILSVRC2012//tfrecord_rot_45/ --model_name=vgg_16 --max_number_of_steps=1500000 --flipLR=False --random_scale=False --is_windowed=True --weight_decay=0.00005 --rmsprop_decay=0.90 --rmsprop_momentum=0.80 --learning_rate=0.005 --learning_rate_decay_factor=0.94 --max_checkpoints_to_keep=5 --keep_checkpoint_every_n_hours=0.5 --batch_size=32
/home/AD/mmhender/anaconda3/lib/python3.7/site-packages/tensorflow/python/framework/dtypes.py:516: FutureWarning: Passing (type, 1) or '1type' as a synonym of type is deprecated; in a future version of numpy, it will be understood as (type, (1,)) / '(1,)type'.
  _np_qint8 = np.dtype([("qint8", np.int8, 1)])
/home/AD/mmhender/anaconda3/lib/python3.7/site-packages/tensorflow/python/framework/dtypes.py:517: FutureWarning: Passing (type, 1) or '1type' as a synonym of type is deprecated; in a future version of numpy, it will be understood as (type, (1,)) / '(1,)type'.
  _np_quint8 = np.dtype([("quint8", np.uint8, 1)])
/home/AD/mmhender/anaconda3/lib/python3.7/site-packages/tensorflow/python/framework/dtypes.py:518: FutureWarning: Passing (type, 1) or '1type' as a synonym of type is deprecated; in a future version of numpy, it will be understood as (type, (1,)) / '(1,)type'.
  _np_qint16 = np.dtype([("qint16", np.int16, 1)])
/home/AD/mmhender/anaconda3/lib/python3.7/site-packages/tensorflow/python/framework/dtypes.py:519: FutureWarning: Passing (type, 1) or '1type' as a synonym of type is deprecated; in a future version of numpy, it will be understood as (type, (1,)) / '(1,)type'.
  _np_quint16 = np.dtype([("quint16", np.uint16, 1)])
/home/AD/mmhender/anaconda3/lib/python3.7/site-packages/tensorflow/python/framework/dtypes.py:520: FutureWarning: Passing (type, 1) or '1type' as a synonym of type is deprecated; in a future version of numpy, it will be understood as (type, (1,)) / '(1,)type'.
  _np_qint32 = np.dtype([("qint32", np.int32, 1)])
/home/AD/mmhender/anaconda3/lib/python3.7/site-packages/tensorflow/python/framework/dtypes.py:525: FutureWarning: Passing (type, 1) or '1type' as a synonym of type is deprecated; in a future version of numpy, it will be understood as (type, (1,)) / '(1,)type'.
  np_resource = np.dtype([("resource", np.ubyte, 1)])
/home/AD/mmhender/anaconda3/lib/python3.7/site-packages/tensorboard/compat/tensorflow_stub/dtypes.py:541: FutureWarning: Passing (type, 1) or '1type' as a synonym of type is deprecated; in a future version of numpy, it will be understood as (type, (1,)) / '(1,)type'.
  _np_qint8 = np.dtype([("qint8", np.int8, 1)])
/home/AD/mmhender/anaconda3/lib/python3.7/site-packages/tensorboard/compat/tensorflow_stub/dtypes.py:542: FutureWarning: Passing (type, 1) or '1type' as a synonym of type is deprecated; in a future version of numpy, it will be understood as (type, (1,)) / '(1,)type'.
  _np_quint8 = np.dtype([("quint8", np.uint8, 1)])
/home/AD/mmhender/anaconda3/lib/python3.7/site-packages/tensorboard/compat/tensorflow_stub/dtypes.py:543: FutureWarning: Passing (type, 1) or '1type' as a synonym of type is deprecated; in a future version of numpy, it will be understood as (type, (1,)) / '(1,)type'.
  _np_qint16 = np.dtype([("qint16", np.int16, 1)])
/home/AD/mmhender/anaconda3/lib/python3.7/site-packages/tensorboard/compat/tensorflow_stub/dtypes.py:544: FutureWarning: Passing (type, 1) or '1type' as a synonym of type is deprecated; in a future version of numpy, it will be understood as (type, (1,)) / '(1,)type'.
  _np_quint16 = np.dtype([("quint16", np.uint16, 1)])
/home/AD/mmhender/anaconda3/lib/python3.7/site-packages/tensorboard/compat/tensorflow_stub/dtypes.py:545: FutureWarning: Passing (type, 1) or '1type' as a synonym of type is deprecated; in a future version of numpy, it will be understood as (type, (1,)) / '(1,)type'.
  _np_qint32 = np.dtype([("qint32", np.int32, 1)])
/home/AD/mmhender/anaconda3/lib/python3.7/site-packages/tensorboard/compat/tensorflow_stub/dtypes.py:550: FutureWarning: Passing (type, 1) or '1type' as a synonym of type is deprecated; in a future version of numpy, it will be understood as (type, (1,)) / '(1,)type'.
  np_resource = np.dtype([("resource", np.ubyte, 1)])
WARNING:tensorflow:
The TensorFlow contrib module will not be included in TensorFlow 2.0.
For more information, please see:
  * https://github.com/tensorflow/community/blob/master/rfcs/20180907-contrib-sunset.md
  * https://github.com/tensorflow/addons
  * https://github.com/tensorflow/io (for I/O related ops)
If you depend on functionality not listed there, please file an issue.

WARNING:tensorflow:From /cube/neurocube/local/serenceslab/maggie/tensorflow/models/research/slim/nets/inception_resnet_v2.py:373: The name tf.GraphKeys is deprecated. Please use tf.compat.v1.GraphKeys instead.

WARNING:tensorflow:From /cube/neurocube/local/serenceslab/maggie/tensorflow/models/research/slim/nets/mobilenet/mobilenet.py:389: The name tf.nn.avg_pool is deprecated. Please use tf.nn.avg_pool2d instead.

WARNING:tensorflow:From train_image_classifier_biasCNN_TEST.py:762: The name tf.app.run is deprecated. Please use tf.compat.v1.app.run instead.

WARNING:tensorflow:From train_image_classifier_biasCNN_TEST.py:445: The name tf.logging.set_verbosity is deprecated. Please use tf.compat.v1.logging.set_verbosity instead.

W0114 14:23:04.152977 140655556867904 deprecation_wrapper.py:119] From train_image_classifier_biasCNN_TEST.py:445: The name tf.logging.set_verbosity is deprecated. Please use tf.compat.v1.logging.set_verbosity instead.

WARNING:tensorflow:From train_image_classifier_biasCNN_TEST.py:445: The name tf.logging.INFO is deprecated. Please use tf.compat.v1.logging.INFO instead.

W0114 14:23:04.153389 140655556867904 deprecation_wrapper.py:119] From train_image_classifier_biasCNN_TEST.py:445: The name tf.logging.INFO is deprecated. Please use tf.compat.v1.logging.INFO instead.

WARNING:tensorflow:From train_image_classifier_biasCNN_TEST.py:459: create_global_step (from tensorflow.contrib.framework.python.ops.variables) is deprecated and will be removed in a future version.
Instructions for updating:
Please switch to tf.train.create_global_step
W0114 14:23:04.154585 140655556867904 deprecation.py:323] From train_image_classifier_biasCNN_TEST.py:459: create_global_step (from tensorflow.contrib.framework.python.ops.variables) is deprecated and will be removed in a future version.
Instructions for updating:
Please switch to tf.train.create_global_step
WARNING:tensorflow:From /cube/neurocube/local/serenceslab/maggie/tensorflow/models/research/slim/datasets/imagenet.py:151: The name tf.FixedLenFeature is deprecated. Please use tf.io.FixedLenFeature instead.

W0114 14:23:04.161996 140655556867904 deprecation_wrapper.py:119] From /cube/neurocube/local/serenceslab/maggie/tensorflow/models/research/slim/datasets/imagenet.py:151: The name tf.FixedLenFeature is deprecated. Please use tf.io.FixedLenFeature instead.

WARNING:tensorflow:From /cube/neurocube/local/serenceslab/maggie/tensorflow/models/research/slim/datasets/imagenet.py:159: The name tf.VarLenFeature is deprecated. Please use tf.io.VarLenFeature instead.

W0114 14:23:04.162232 140655556867904 deprecation_wrapper.py:119] From /cube/neurocube/local/serenceslab/maggie/tensorflow/models/research/slim/datasets/imagenet.py:159: The name tf.VarLenFeature is deprecated. Please use tf.io.VarLenFeature instead.

WARNING:tensorflow:From /cube/neurocube/local/serenceslab/maggie/tensorflow/models/research/slim/datasets/dataset_utils.py:127: The name tf.gfile.Exists is deprecated. Please use tf.io.gfile.exists instead.

W0114 14:23:04.162484 140655556867904 deprecation_wrapper.py:119] From /cube/neurocube/local/serenceslab/maggie/tensorflow/models/research/slim/datasets/dataset_utils.py:127: The name tf.gfile.Exists is deprecated. Please use tf.io.gfile.exists instead.

WARNING:tensorflow:From /cube/neurocube/local/serenceslab/maggie/tensorflow/models/research/slim/datasets/dataset_utils.py:141: The name tf.gfile.Open is deprecated. Please use tf.io.gfile.GFile instead.

W0114 14:23:04.162732 140655556867904 deprecation_wrapper.py:119] From /cube/neurocube/local/serenceslab/maggie/tensorflow/models/research/slim/datasets/dataset_utils.py:141: The name tf.gfile.Open is deprecated. Please use tf.io.gfile.GFile instead.

WARNING:tensorflow:From /home/AD/mmhender/anaconda3/lib/python3.7/site-packages/tensorflow/contrib/slim/python/slim/data/parallel_reader.py:246: string_input_producer (from tensorflow.python.training.input) is deprecated and will be removed in a future version.
Instructions for updating:
Queue-based input pipelines have been replaced by `tf.data`. Use `tf.data.Dataset.from_tensor_slices(string_tensor).shuffle(tf.shape(input_tensor, out_type=tf.int64)[0]).repeat(num_epochs)`. If `shuffle=False`, omit the `.shuffle(...)`.
W0114 14:23:04.219652 140655556867904 deprecation.py:323] From /home/AD/mmhender/anaconda3/lib/python3.7/site-packages/tensorflow/contrib/slim/python/slim/data/parallel_reader.py:246: string_input_producer (from tensorflow.python.training.input) is deprecated and will be removed in a future version.
Instructions for updating:
Queue-based input pipelines have been replaced by `tf.data`. Use `tf.data.Dataset.from_tensor_slices(string_tensor).shuffle(tf.shape(input_tensor, out_type=tf.int64)[0]).repeat(num_epochs)`. If `shuffle=False`, omit the `.shuffle(...)`.
WARNING:tensorflow:From /home/AD/mmhender/anaconda3/lib/python3.7/site-packages/tensorflow/python/training/input.py:278: input_producer (from tensorflow.python.training.input) is deprecated and will be removed in a future version.
Instructions for updating:
Queue-based input pipelines have been replaced by `tf.data`. Use `tf.data.Dataset.from_tensor_slices(input_tensor).shuffle(tf.shape(input_tensor, out_type=tf.int64)[0]).repeat(num_epochs)`. If `shuffle=False`, omit the `.shuffle(...)`.
W0114 14:23:04.236881 140655556867904 deprecation.py:323] From /home/AD/mmhender/anaconda3/lib/python3.7/site-packages/tensorflow/python/training/input.py:278: input_producer (from tensorflow.python.training.input) is deprecated and will be removed in a future version.
Instructions for updating:
Queue-based input pipelines have been replaced by `tf.data`. Use `tf.data.Dataset.from_tensor_slices(input_tensor).shuffle(tf.shape(input_tensor, out_type=tf.int64)[0]).repeat(num_epochs)`. If `shuffle=False`, omit the `.shuffle(...)`.
WARNING:tensorflow:From /home/AD/mmhender/anaconda3/lib/python3.7/site-packages/tensorflow/python/training/input.py:190: limit_epochs (from tensorflow.python.training.input) is deprecated and will be removed in a future version.
Instructions for updating:
Queue-based input pipelines have been replaced by `tf.data`. Use `tf.data.Dataset.from_tensors(tensor).repeat(num_epochs)`.
W0114 14:23:04.238045 140655556867904 deprecation.py:323] From /home/AD/mmhender/anaconda3/lib/python3.7/site-packages/tensorflow/python/training/input.py:190: limit_epochs (from tensorflow.python.training.input) is deprecated and will be removed in a future version.
Instructions for updating:
Queue-based input pipelines have been replaced by `tf.data`. Use `tf.data.Dataset.from_tensors(tensor).repeat(num_epochs)`.
WARNING:tensorflow:From /home/AD/mmhender/anaconda3/lib/python3.7/site-packages/tensorflow/python/training/input.py:199: QueueRunner.__init__ (from tensorflow.python.training.queue_runner_impl) is deprecated and will be removed in a future version.
Instructions for updating:
To construct input pipelines, use the `tf.data` module.
W0114 14:23:04.240355 140655556867904 deprecation.py:323] From /home/AD/mmhender/anaconda3/lib/python3.7/site-packages/tensorflow/python/training/input.py:199: QueueRunner.__init__ (from tensorflow.python.training.queue_runner_impl) is deprecated and will be removed in a future version.
Instructions for updating:
To construct input pipelines, use the `tf.data` module.
WARNING:tensorflow:From /home/AD/mmhender/anaconda3/lib/python3.7/site-packages/tensorflow/python/training/input.py:199: add_queue_runner (from tensorflow.python.training.queue_runner_impl) is deprecated and will be removed in a future version.
Instructions for updating:
To construct input pipelines, use the `tf.data` module.
W0114 14:23:04.241849 140655556867904 deprecation.py:323] From /home/AD/mmhender/anaconda3/lib/python3.7/site-packages/tensorflow/python/training/input.py:199: add_queue_runner (from tensorflow.python.training.queue_runner_impl) is deprecated and will be removed in a future version.
Instructions for updating:
To construct input pipelines, use the `tf.data` module.
WARNING:tensorflow:From /home/AD/mmhender/anaconda3/lib/python3.7/site-packages/tensorflow/contrib/slim/python/slim/data/parallel_reader.py:95: TFRecordReader.__init__ (from tensorflow.python.ops.io_ops) is deprecated and will be removed in a future version.
Instructions for updating:
Queue-based input pipelines have been replaced by `tf.data`. Use `tf.data.TFRecordDataset`.
W0114 14:23:04.252836 140655556867904 deprecation.py:323] From /home/AD/mmhender/anaconda3/lib/python3.7/site-packages/tensorflow/contrib/slim/python/slim/data/parallel_reader.py:95: TFRecordReader.__init__ (from tensorflow.python.ops.io_ops) is deprecated and will be removed in a future version.
Instructions for updating:
Queue-based input pipelines have been replaced by `tf.data`. Use `tf.data.TFRecordDataset`.
WARNING:tensorflow:From /cube/neurocube/local/serenceslab/maggie/tensorflow/models/research/slim/preprocessing/vgg_preprocessing_biasCNN.py:327: The name tf.assert_equal is deprecated. Please use tf.compat.v1.assert_equal instead.

W0114 14:23:04.411590 140655556867904 deprecation_wrapper.py:119] From /cube/neurocube/local/serenceslab/maggie/tensorflow/models/research/slim/preprocessing/vgg_preprocessing_biasCNN.py:327: The name tf.assert_equal is deprecated. Please use tf.compat.v1.assert_equal instead.

ERROR:tensorflow:==================================
Object was never used (type <class 'tensorflow.python.framework.ops.Operation'>):
<tf.Operation 'assert_equal/Assert/Assert' type=Assert>
If you want to mark it as used call its "mark_used()" method.
It was originally created here:
  File "train_image_classifier_biasCNN_TEST.py", line 762, in <module>
    tf.app.run()  File "/home/AD/mmhender/anaconda3/lib/python3.7/site-packages/tensorflow/python/platform/app.py", line 40, in run
    _run(main=main, argv=argv, flags_parser=_parse_flags_tolerate_undef)  File "/home/AD/mmhender/anaconda3/lib/python3.7/site-packages/absl/app.py", line 299, in run
    _run_main(main, args)  File "/home/AD/mmhender/anaconda3/lib/python3.7/site-packages/absl/app.py", line 250, in _run_main
    sys.exit(main(argv))  File "train_image_classifier_biasCNN_TEST.py", line 512, in main
    image = image_preprocessing_fn(image, train_image_size, train_image_size)  File "/cube/neurocube/local/serenceslab/maggie/tensorflow/models/research/slim/preprocessing/preprocessing_biasCNN.py", line 54, in preprocessing_fn
    image, output_height, output_width, is_training=is_training, flipLR=flipLR, random_scale=random_scale, is_windowed=is_windowed, **kwargs)  File "/cube/neurocube/local/serenceslab/maggie/tensorflow/models/research/slim/preprocessing/vgg_preprocessing_biasCNN.py", line 408, in preprocess_image
    resize_side_min, resize_side_max, flipLR, random_scale, is_windowed)  File "/cube/neurocube/local/serenceslab/maggie/tensorflow/models/research/slim/preprocessing/vgg_preprocessing_biasCNN.py", line 327, in preprocess_for_train
    tf.assert_equal(shape[0],shape[1])  File "/home/AD/mmhender/anaconda3/lib/python3.7/site-packages/tensorflow/python/ops/check_ops.py", line 557, in assert_equal
    return control_flow_ops.Assert(condition, data, summarize=summarize)  File "/home/AD/mmhender/anaconda3/lib/python3.7/site-packages/tensorflow/python/util/tf_should_use.py", line 193, in wrapped
    return _add_should_use_warning(fn(*args, **kwargs))
==================================
E0114 14:23:04.432852 140655556867904 tf_should_use.py:71] ==================================
Object was never used (type <class 'tensorflow.python.framework.ops.Operation'>):
<tf.Operation 'assert_equal/Assert/Assert' type=Assert>
If you want to mark it as used call its "mark_used()" method.
It was originally created here:
  File "train_image_classifier_biasCNN_TEST.py", line 762, in <module>
    tf.app.run()  File "/home/AD/mmhender/anaconda3/lib/python3.7/site-packages/tensorflow/python/platform/app.py", line 40, in run
    _run(main=main, argv=argv, flags_parser=_parse_flags_tolerate_undef)  File "/home/AD/mmhender/anaconda3/lib/python3.7/site-packages/absl/app.py", line 299, in run
    _run_main(main, args)  File "/home/AD/mmhender/anaconda3/lib/python3.7/site-packages/absl/app.py", line 250, in _run_main
    sys.exit(main(argv))  File "train_image_classifier_biasCNN_TEST.py", line 512, in main
    image = image_preprocessing_fn(image, train_image_size, train_image_size)  File "/cube/neurocube/local/serenceslab/maggie/tensorflow/models/research/slim/preprocessing/preprocessing_biasCNN.py", line 54, in preprocessing_fn
    image, output_height, output_width, is_training=is_training, flipLR=flipLR, random_scale=random_scale, is_windowed=is_windowed, **kwargs)  File "/cube/neurocube/local/serenceslab/maggie/tensorflow/models/research/slim/preprocessing/vgg_preprocessing_biasCNN.py", line 408, in preprocess_image
    resize_side_min, resize_side_max, flipLR, random_scale, is_windowed)  File "/cube/neurocube/local/serenceslab/maggie/tensorflow/models/research/slim/preprocessing/vgg_preprocessing_biasCNN.py", line 327, in preprocess_for_train
    tf.assert_equal(shape[0],shape[1])  File "/home/AD/mmhender/anaconda3/lib/python3.7/site-packages/tensorflow/python/ops/check_ops.py", line 557, in assert_equal
    return control_flow_ops.Assert(condition, data, summarize=summarize)  File "/home/AD/mmhender/anaconda3/lib/python3.7/site-packages/tensorflow/python/util/tf_should_use.py", line 193, in wrapped
    return _add_should_use_warning(fn(*args, **kwargs))
==================================
ERROR:tensorflow:==================================
Object was never used (type <class 'tensorflow.python.framework.ops.Operation'>):
<tf.Operation 'assert_equal_1/Assert/Assert' type=Assert>
If you want to mark it as used call its "mark_used()" method.
It was originally created here:
  File "train_image_classifier_biasCNN_TEST.py", line 762, in <module>
    tf.app.run()  File "/home/AD/mmhender/anaconda3/lib/python3.7/site-packages/tensorflow/python/platform/app.py", line 40, in run
    _run(main=main, argv=argv, flags_parser=_parse_flags_tolerate_undef)  File "/home/AD/mmhender/anaconda3/lib/python3.7/site-packages/absl/app.py", line 299, in run
    _run_main(main, args)  File "/home/AD/mmhender/anaconda3/lib/python3.7/site-packages/absl/app.py", line 250, in _run_main
    sys.exit(main(argv))  File "train_image_classifier_biasCNN_TEST.py", line 512, in main
    image = image_preprocessing_fn(image, train_image_size, train_image_size)  File "/cube/neurocube/local/serenceslab/maggie/tensorflow/models/research/slim/preprocessing/preprocessing_biasCNN.py", line 54, in preprocessing_fn
    image, output_height, output_width, is_training=is_training, flipLR=flipLR, random_scale=random_scale, is_windowed=is_windowed, **kwargs)  File "/cube/neurocube/local/serenceslab/maggie/tensorflow/models/research/slim/preprocessing/vgg_preprocessing_biasCNN.py", line 408, in preprocess_image
    resize_side_min, resize_side_max, flipLR, random_scale, is_windowed)  File "/cube/neurocube/local/serenceslab/maggie/tensorflow/models/research/slim/preprocessing/vgg_preprocessing_biasCNN.py", line 328, in preprocess_for_train
    tf.assert_equal(shape[0],output_height)  File "/home/AD/mmhender/anaconda3/lib/python3.7/site-packages/tensorflow/python/ops/check_ops.py", line 557, in assert_equal
    return control_flow_ops.Assert(condition, data, summarize=summarize)  File "/home/AD/mmhender/anaconda3/lib/python3.7/site-packages/tensorflow/python/util/tf_should_use.py", line 193, in wrapped
    return _add_should_use_warning(fn(*args, **kwargs))
==================================
E0114 14:23:04.451182 140655556867904 tf_should_use.py:71] ==================================
Object was never used (type <class 'tensorflow.python.framework.ops.Operation'>):
<tf.Operation 'assert_equal_1/Assert/Assert' type=Assert>
If you want to mark it as used call its "mark_used()" method.
It was originally created here:
  File "train_image_classifier_biasCNN_TEST.py", line 762, in <module>
    tf.app.run()  File "/home/AD/mmhender/anaconda3/lib/python3.7/site-packages/tensorflow/python/platform/app.py", line 40, in run
    _run(main=main, argv=argv, flags_parser=_parse_flags_tolerate_undef)  File "/home/AD/mmhender/anaconda3/lib/python3.7/site-packages/absl/app.py", line 299, in run
    _run_main(main, args)  File "/home/AD/mmhender/anaconda3/lib/python3.7/site-packages/absl/app.py", line 250, in _run_main
    sys.exit(main(argv))  File "train_image_classifier_biasCNN_TEST.py", line 512, in main
    image = image_preprocessing_fn(image, train_image_size, train_image_size)  File "/cube/neurocube/local/serenceslab/maggie/tensorflow/models/research/slim/preprocessing/preprocessing_biasCNN.py", line 54, in preprocessing_fn
    image, output_height, output_width, is_training=is_training, flipLR=flipLR, random_scale=random_scale, is_windowed=is_windowed, **kwargs)  File "/cube/neurocube/local/serenceslab/maggie/tensorflow/models/research/slim/preprocessing/vgg_preprocessing_biasCNN.py", line 408, in preprocess_image
    resize_side_min, resize_side_max, flipLR, random_scale, is_windowed)  File "/cube/neurocube/local/serenceslab/maggie/tensorflow/models/research/slim/preprocessing/vgg_preprocessing_biasCNN.py", line 328, in preprocess_for_train
    tf.assert_equal(shape[0],output_height)  File "/home/AD/mmhender/anaconda3/lib/python3.7/site-packages/tensorflow/python/ops/check_ops.py", line 557, in assert_equal
    return control_flow_ops.Assert(condition, data, summarize=summarize)  File "/home/AD/mmhender/anaconda3/lib/python3.7/site-packages/tensorflow/python/util/tf_should_use.py", line 193, in wrapped
    return _add_should_use_warning(fn(*args, **kwargs))
==================================
WARNING:tensorflow:From /cube/neurocube/local/serenceslab/maggie/tensorflow/models/research/slim/preprocessing/vgg_preprocessing_biasCNN.py:335: to_float (from tensorflow.python.ops.math_ops) is deprecated and will be removed in a future version.
Instructions for updating:
Use `tf.cast` instead.
W0114 14:23:04.451433 140655556867904 deprecation.py:323] From /cube/neurocube/local/serenceslab/maggie/tensorflow/models/research/slim/preprocessing/vgg_preprocessing_biasCNN.py:335: to_float (from tensorflow.python.ops.math_ops) is deprecated and will be removed in a future version.
Instructions for updating:
Use `tf.cast` instead.
WARNING:tensorflow:From train_image_classifier_biasCNN_TEST.py:518: batch (from tensorflow.python.training.input) is deprecated and will be removed in a future version.
Instructions for updating:
Queue-based input pipelines have been replaced by `tf.data`. Use `tf.data.Dataset.batch(batch_size)` (or `padded_batch(...)` if `dynamic_pad=True`).
W0114 14:23:04.461335 140655556867904 deprecation.py:323] From train_image_classifier_biasCNN_TEST.py:518: batch (from tensorflow.python.training.input) is deprecated and will be removed in a future version.
Instructions for updating:
Queue-based input pipelines have been replaced by `tf.data`. Use `tf.data.Dataset.batch(batch_size)` (or `padded_batch(...)` if `dynamic_pad=True`).
ERROR:tensorflow:==================================
Object was never used (type <class 'tensorflow.python.framework.ops.Operation'>):
<tf.Operation 'assert_equal_2/Assert/Assert' type=Assert>
If you want to mark it as used call its "mark_used()" method.
It was originally created here:
  File "train_image_classifier_biasCNN_TEST.py", line 762, in <module>
    tf.app.run()  File "/home/AD/mmhender/anaconda3/lib/python3.7/site-packages/tensorflow/python/platform/app.py", line 40, in run
    _run(main=main, argv=argv, flags_parser=_parse_flags_tolerate_undef)  File "/home/AD/mmhender/anaconda3/lib/python3.7/site-packages/absl/app.py", line 299, in run
    _run_main(main, args)  File "/home/AD/mmhender/anaconda3/lib/python3.7/site-packages/absl/app.py", line 250, in _run_main
    sys.exit(main(argv))  File "train_image_classifier_biasCNN_TEST.py", line 537, in main
    image_val = image_preprocessing_fn_val(image_val, eval_image_size, eval_image_size)  File "/cube/neurocube/local/serenceslab/maggie/tensorflow/models/research/slim/preprocessing/preprocessing_biasCNN.py", line 54, in preprocessing_fn
    image, output_height, output_width, is_training=is_training, flipLR=flipLR, random_scale=random_scale, is_windowed=is_windowed, **kwargs)  File "/cube/neurocube/local/serenceslab/maggie/tensorflow/models/research/slim/preprocessing/vgg_preprocessing_biasCNN.py", line 411, in preprocess_image
    resize_side_min, is_windowed)  File "/cube/neurocube/local/serenceslab/maggie/tensorflow/models/research/slim/preprocessing/vgg_preprocessing_biasCNN.py", line 363, in preprocess_for_eval
    tf.assert_equal(shape[0],shape[1])  File "/home/AD/mmhender/anaconda3/lib/python3.7/site-packages/tensorflow/python/ops/check_ops.py", line 557, in assert_equal
    return control_flow_ops.Assert(condition, data, summarize=summarize)  File "/home/AD/mmhender/anaconda3/lib/python3.7/site-packages/tensorflow/python/util/tf_should_use.py", line 193, in wrapped
    return _add_should_use_warning(fn(*args, **kwargs))
==================================
E0114 14:23:04.718896 140655556867904 tf_should_use.py:71] ==================================
Object was never used (type <class 'tensorflow.python.framework.ops.Operation'>):
<tf.Operation 'assert_equal_2/Assert/Assert' type=Assert>
If you want to mark it as used call its "mark_used()" method.
It was originally created here:
  File "train_image_classifier_biasCNN_TEST.py", line 762, in <module>
    tf.app.run()  File "/home/AD/mmhender/anaconda3/lib/python3.7/site-packages/tensorflow/python/platform/app.py", line 40, in run
    _run(main=main, argv=argv, flags_parser=_parse_flags_tolerate_undef)  File "/home/AD/mmhender/anaconda3/lib/python3.7/site-packages/absl/app.py", line 299, in run
    _run_main(main, args)  File "/home/AD/mmhender/anaconda3/lib/python3.7/site-packages/absl/app.py", line 250, in _run_main
    sys.exit(main(argv))  File "train_image_classifier_biasCNN_TEST.py", line 537, in main
    image_val = image_preprocessing_fn_val(image_val, eval_image_size, eval_image_size)  File "/cube/neurocube/local/serenceslab/maggie/tensorflow/models/research/slim/preprocessing/preprocessing_biasCNN.py", line 54, in preprocessing_fn
    image, output_height, output_width, is_training=is_training, flipLR=flipLR, random_scale=random_scale, is_windowed=is_windowed, **kwargs)  File "/cube/neurocube/local/serenceslab/maggie/tensorflow/models/research/slim/preprocessing/vgg_preprocessing_biasCNN.py", line 411, in preprocess_image
    resize_side_min, is_windowed)  File "/cube/neurocube/local/serenceslab/maggie/tensorflow/models/research/slim/preprocessing/vgg_preprocessing_biasCNN.py", line 363, in preprocess_for_eval
    tf.assert_equal(shape[0],shape[1])  File "/home/AD/mmhender/anaconda3/lib/python3.7/site-packages/tensorflow/python/ops/check_ops.py", line 557, in assert_equal
    return control_flow_ops.Assert(condition, data, summarize=summarize)  File "/home/AD/mmhender/anaconda3/lib/python3.7/site-packages/tensorflow/python/util/tf_should_use.py", line 193, in wrapped
    return _add_should_use_warning(fn(*args, **kwargs))
==================================
ERROR:tensorflow:==================================
Object was never used (type <class 'tensorflow.python.framework.ops.Operation'>):
<tf.Operation 'assert_equal_3/Assert/Assert' type=Assert>
If you want to mark it as used call its "mark_used()" method.
It was originally created here:
  File "train_image_classifier_biasCNN_TEST.py", line 762, in <module>
    tf.app.run()  File "/home/AD/mmhender/anaconda3/lib/python3.7/site-packages/tensorflow/python/platform/app.py", line 40, in run
    _run(main=main, argv=argv, flags_parser=_parse_flags_tolerate_undef)  File "/home/AD/mmhender/anaconda3/lib/python3.7/site-packages/absl/app.py", line 299, in run
    _run_main(main, args)  File "/home/AD/mmhender/anaconda3/lib/python3.7/site-packages/absl/app.py", line 250, in _run_main
    sys.exit(main(argv))  File "train_image_classifier_biasCNN_TEST.py", line 537, in main
    image_val = image_preprocessing_fn_val(image_val, eval_image_size, eval_image_size)  File "/cube/neurocube/local/serenceslab/maggie/tensorflow/models/research/slim/preprocessing/preprocessing_biasCNN.py", line 54, in preprocessing_fn
    image, output_height, output_width, is_training=is_training, flipLR=flipLR, random_scale=random_scale, is_windowed=is_windowed, **kwargs)  File "/cube/neurocube/local/serenceslab/maggie/tensorflow/models/research/slim/preprocessing/vgg_preprocessing_biasCNN.py", line 411, in preprocess_image
    resize_side_min, is_windowed)  File "/cube/neurocube/local/serenceslab/maggie/tensorflow/models/research/slim/preprocessing/vgg_preprocessing_biasCNN.py", line 364, in preprocess_for_eval
    tf.assert_equal(shape[0],output_height)  File "/home/AD/mmhender/anaconda3/lib/python3.7/site-packages/tensorflow/python/ops/check_ops.py", line 557, in assert_equal
    return control_flow_ops.Assert(condition, data, summarize=summarize)  File "/home/AD/mmhender/anaconda3/lib/python3.7/site-packages/tensorflow/python/util/tf_should_use.py", line 193, in wrapped
    return _add_should_use_warning(fn(*args, **kwargs))
==================================
E0114 14:23:04.733805 140655556867904 tf_should_use.py:71] ==================================
Object was never used (type <class 'tensorflow.python.framework.ops.Operation'>):
<tf.Operation 'assert_equal_3/Assert/Assert' type=Assert>
If you want to mark it as used call its "mark_used()" method.
It was originally created here:
  File "train_image_classifier_biasCNN_TEST.py", line 762, in <module>
    tf.app.run()  File "/home/AD/mmhender/anaconda3/lib/python3.7/site-packages/tensorflow/python/platform/app.py", line 40, in run
    _run(main=main, argv=argv, flags_parser=_parse_flags_tolerate_undef)  File "/home/AD/mmhender/anaconda3/lib/python3.7/site-packages/absl/app.py", line 299, in run
    _run_main(main, args)  File "/home/AD/mmhender/anaconda3/lib/python3.7/site-packages/absl/app.py", line 250, in _run_main
    sys.exit(main(argv))  File "train_image_classifier_biasCNN_TEST.py", line 537, in main
    image_val = image_preprocessing_fn_val(image_val, eval_image_size, eval_image_size)  File "/cube/neurocube/local/serenceslab/maggie/tensorflow/models/research/slim/preprocessing/preprocessing_biasCNN.py", line 54, in preprocessing_fn
    image, output_height, output_width, is_training=is_training, flipLR=flipLR, random_scale=random_scale, is_windowed=is_windowed, **kwargs)  File "/cube/neurocube/local/serenceslab/maggie/tensorflow/models/research/slim/preprocessing/vgg_preprocessing_biasCNN.py", line 411, in preprocess_image
    resize_side_min, is_windowed)  File "/cube/neurocube/local/serenceslab/maggie/tensorflow/models/research/slim/preprocessing/vgg_preprocessing_biasCNN.py", line 364, in preprocess_for_eval
    tf.assert_equal(shape[0],output_height)  File "/home/AD/mmhender/anaconda3/lib/python3.7/site-packages/tensorflow/python/ops/check_ops.py", line 557, in assert_equal
    return control_flow_ops.Assert(condition, data, summarize=summarize)  File "/home/AD/mmhender/anaconda3/lib/python3.7/site-packages/tensorflow/python/util/tf_should_use.py", line 193, in wrapped
    return _add_should_use_warning(fn(*args, **kwargs))
==================================
WARNING:tensorflow:From train_image_classifier_biasCNN_TEST.py:572: The name tf.get_collection is deprecated. Please use tf.compat.v1.get_collection instead.

W0114 14:23:04.761239 140655556867904 deprecation_wrapper.py:119] From train_image_classifier_biasCNN_TEST.py:572: The name tf.get_collection is deprecated. Please use tf.compat.v1.get_collection instead.

WARNING:tensorflow:Entity <bound method Conv.call of <tensorflow.python.layers.convolutional.Conv2D object at 0x7fec77ec4bd0>> could not be transformed and will be executed as-is. Please report this to the AutgoGraph team. When filing the bug, set the verbosity to 10 (on Linux, `export AUTOGRAPH_VERBOSITY=10`) and attach the full output. Cause: converting <bound method Conv.call of <tensorflow.python.layers.convolutional.Conv2D object at 0x7fec77ec4bd0>>: AssertionError: Bad argument number for Name: 3, expecting 4
W0114 14:23:05.173258 140655556867904 ag_logging.py:145] Entity <bound method Conv.call of <tensorflow.python.layers.convolutional.Conv2D object at 0x7fec77ec4bd0>> could not be transformed and will be executed as-is. Please report this to the AutgoGraph team. When filing the bug, set the verbosity to 10 (on Linux, `export AUTOGRAPH_VERBOSITY=10`) and attach the full output. Cause: converting <bound method Conv.call of <tensorflow.python.layers.convolutional.Conv2D object at 0x7fec77ec4bd0>>: AssertionError: Bad argument number for Name: 3, expecting 4
WARNING:tensorflow:Entity <bound method Conv.call of <tensorflow.python.layers.convolutional.Conv2D object at 0x7fec77ec4d50>> could not be transformed and will be executed as-is. Please report this to the AutgoGraph team. When filing the bug, set the verbosity to 10 (on Linux, `export AUTOGRAPH_VERBOSITY=10`) and attach the full output. Cause: converting <bound method Conv.call of <tensorflow.python.layers.convolutional.Conv2D object at 0x7fec77ec4d50>>: AssertionError: Bad argument number for Name: 3, expecting 4
W0114 14:23:05.286437 140655556867904 ag_logging.py:145] Entity <bound method Conv.call of <tensorflow.python.layers.convolutional.Conv2D object at 0x7fec77ec4d50>> could not be transformed and will be executed as-is. Please report this to the AutgoGraph team. When filing the bug, set the verbosity to 10 (on Linux, `export AUTOGRAPH_VERBOSITY=10`) and attach the full output. Cause: converting <bound method Conv.call of <tensorflow.python.layers.convolutional.Conv2D object at 0x7fec77ec4d50>>: AssertionError: Bad argument number for Name: 3, expecting 4
WARNING:tensorflow:Entity <bound method Pooling2D.call of <tensorflow.python.layers.pooling.MaxPooling2D object at 0x7fec77ec49d0>> could not be transformed and will be executed as-is. Please report this to the AutgoGraph team. When filing the bug, set the verbosity to 10 (on Linux, `export AUTOGRAPH_VERBOSITY=10`) and attach the full output. Cause: converting <bound method Pooling2D.call of <tensorflow.python.layers.pooling.MaxPooling2D object at 0x7fec77ec49d0>>: AssertionError: Bad argument number for Name: 3, expecting 4
W0114 14:23:05.350386 140655556867904 ag_logging.py:145] Entity <bound method Pooling2D.call of <tensorflow.python.layers.pooling.MaxPooling2D object at 0x7fec77ec49d0>> could not be transformed and will be executed as-is. Please report this to the AutgoGraph team. When filing the bug, set the verbosity to 10 (on Linux, `export AUTOGRAPH_VERBOSITY=10`) and attach the full output. Cause: converting <bound method Pooling2D.call of <tensorflow.python.layers.pooling.MaxPooling2D object at 0x7fec77ec49d0>>: AssertionError: Bad argument number for Name: 3, expecting 4
WARNING:tensorflow:Entity <bound method Conv.call of <tensorflow.python.layers.convolutional.Conv2D object at 0x7fec77ed26d0>> could not be transformed and will be executed as-is. Please report this to the AutgoGraph team. When filing the bug, set the verbosity to 10 (on Linux, `export AUTOGRAPH_VERBOSITY=10`) and attach the full output. Cause: converting <bound method Conv.call of <tensorflow.python.layers.convolutional.Conv2D object at 0x7fec77ed26d0>>: AssertionError: Bad argument number for Name: 3, expecting 4
W0114 14:23:05.454837 140655556867904 ag_logging.py:145] Entity <bound method Conv.call of <tensorflow.python.layers.convolutional.Conv2D object at 0x7fec77ed26d0>> could not be transformed and will be executed as-is. Please report this to the AutgoGraph team. When filing the bug, set the verbosity to 10 (on Linux, `export AUTOGRAPH_VERBOSITY=10`) and attach the full output. Cause: converting <bound method Conv.call of <tensorflow.python.layers.convolutional.Conv2D object at 0x7fec77ed26d0>>: AssertionError: Bad argument number for Name: 3, expecting 4
WARNING:tensorflow:Entity <bound method Conv.call of <tensorflow.python.layers.convolutional.Conv2D object at 0x7fec77ed20d0>> could not be transformed and will be executed as-is. Please report this to the AutgoGraph team. When filing the bug, set the verbosity to 10 (on Linux, `export AUTOGRAPH_VERBOSITY=10`) and attach the full output. Cause: converting <bound method Conv.call of <tensorflow.python.layers.convolutional.Conv2D object at 0x7fec77ed20d0>>: AssertionError: Bad argument number for Name: 3, expecting 4
W0114 14:23:05.560107 140655556867904 ag_logging.py:145] Entity <bound method Conv.call of <tensorflow.python.layers.convolutional.Conv2D object at 0x7fec77ed20d0>> could not be transformed and will be executed as-is. Please report this to the AutgoGraph team. When filing the bug, set the verbosity to 10 (on Linux, `export AUTOGRAPH_VERBOSITY=10`) and attach the full output. Cause: converting <bound method Conv.call of <tensorflow.python.layers.convolutional.Conv2D object at 0x7fec77ed20d0>>: AssertionError: Bad argument number for Name: 3, expecting 4
WARNING:tensorflow:Entity <bound method Pooling2D.call of <tensorflow.python.layers.pooling.MaxPooling2D object at 0x7fec77ed23d0>> could not be transformed and will be executed as-is. Please report this to the AutgoGraph team. When filing the bug, set the verbosity to 10 (on Linux, `export AUTOGRAPH_VERBOSITY=10`) and attach the full output. Cause: converting <bound method Pooling2D.call of <tensorflow.python.layers.pooling.MaxPooling2D object at 0x7fec77ed23d0>>: AssertionError: Bad argument number for Name: 3, expecting 4
W0114 14:23:05.623692 140655556867904 ag_logging.py:145] Entity <bound method Pooling2D.call of <tensorflow.python.layers.pooling.MaxPooling2D object at 0x7fec77ed23d0>> could not be transformed and will be executed as-is. Please report this to the AutgoGraph team. When filing the bug, set the verbosity to 10 (on Linux, `export AUTOGRAPH_VERBOSITY=10`) and attach the full output. Cause: converting <bound method Pooling2D.call of <tensorflow.python.layers.pooling.MaxPooling2D object at 0x7fec77ed23d0>>: AssertionError: Bad argument number for Name: 3, expecting 4
WARNING:tensorflow:Entity <bound method Conv.call of <tensorflow.python.layers.convolutional.Conv2D object at 0x7fec77ec4b90>> could not be transformed and will be executed as-is. Please report this to the AutgoGraph team. When filing the bug, set the verbosity to 10 (on Linux, `export AUTOGRAPH_VERBOSITY=10`) and attach the full output. Cause: converting <bound method Conv.call of <tensorflow.python.layers.convolutional.Conv2D object at 0x7fec77ec4b90>>: AssertionError: Bad argument number for Name: 3, expecting 4
W0114 14:23:05.727843 140655556867904 ag_logging.py:145] Entity <bound method Conv.call of <tensorflow.python.layers.convolutional.Conv2D object at 0x7fec77ec4b90>> could not be transformed and will be executed as-is. Please report this to the AutgoGraph team. When filing the bug, set the verbosity to 10 (on Linux, `export AUTOGRAPH_VERBOSITY=10`) and attach the full output. Cause: converting <bound method Conv.call of <tensorflow.python.layers.convolutional.Conv2D object at 0x7fec77ec4b90>>: AssertionError: Bad argument number for Name: 3, expecting 4
WARNING:tensorflow:Entity <bound method Conv.call of <tensorflow.python.layers.convolutional.Conv2D object at 0x7fec77e748d0>> could not be transformed and will be executed as-is. Please report this to the AutgoGraph team. When filing the bug, set the verbosity to 10 (on Linux, `export AUTOGRAPH_VERBOSITY=10`) and attach the full output. Cause: converting <bound method Conv.call of <tensorflow.python.layers.convolutional.Conv2D object at 0x7fec77e748d0>>: AssertionError: Bad argument number for Name: 3, expecting 4
W0114 14:23:05.833433 140655556867904 ag_logging.py:145] Entity <bound method Conv.call of <tensorflow.python.layers.convolutional.Conv2D object at 0x7fec77e748d0>> could not be transformed and will be executed as-is. Please report this to the AutgoGraph team. When filing the bug, set the verbosity to 10 (on Linux, `export AUTOGRAPH_VERBOSITY=10`) and attach the full output. Cause: converting <bound method Conv.call of <tensorflow.python.layers.convolutional.Conv2D object at 0x7fec77e748d0>>: AssertionError: Bad argument number for Name: 3, expecting 4
WARNING:tensorflow:Entity <bound method Conv.call of <tensorflow.python.layers.convolutional.Conv2D object at 0x7fec77e18ed0>> could not be transformed and will be executed as-is. Please report this to the AutgoGraph team. When filing the bug, set the verbosity to 10 (on Linux, `export AUTOGRAPH_VERBOSITY=10`) and attach the full output. Cause: converting <bound method Conv.call of <tensorflow.python.layers.convolutional.Conv2D object at 0x7fec77e18ed0>>: AssertionError: Bad argument number for Name: 3, expecting 4
W0114 14:23:05.938882 140655556867904 ag_logging.py:145] Entity <bound method Conv.call of <tensorflow.python.layers.convolutional.Conv2D object at 0x7fec77e18ed0>> could not be transformed and will be executed as-is. Please report this to the AutgoGraph team. When filing the bug, set the verbosity to 10 (on Linux, `export AUTOGRAPH_VERBOSITY=10`) and attach the full output. Cause: converting <bound method Conv.call of <tensorflow.python.layers.convolutional.Conv2D object at 0x7fec77e18ed0>>: AssertionError: Bad argument number for Name: 3, expecting 4
WARNING:tensorflow:Entity <bound method Pooling2D.call of <tensorflow.python.layers.pooling.MaxPooling2D object at 0x7fec77e17790>> could not be transformed and will be executed as-is. Please report this to the AutgoGraph team. When filing the bug, set the verbosity to 10 (on Linux, `export AUTOGRAPH_VERBOSITY=10`) and attach the full output. Cause: converting <bound method Pooling2D.call of <tensorflow.python.layers.pooling.MaxPooling2D object at 0x7fec77e17790>>: AssertionError: Bad argument number for Name: 3, expecting 4
W0114 14:23:06.002537 140655556867904 ag_logging.py:145] Entity <bound method Pooling2D.call of <tensorflow.python.layers.pooling.MaxPooling2D object at 0x7fec77e17790>> could not be transformed and will be executed as-is. Please report this to the AutgoGraph team. When filing the bug, set the verbosity to 10 (on Linux, `export AUTOGRAPH_VERBOSITY=10`) and attach the full output. Cause: converting <bound method Pooling2D.call of <tensorflow.python.layers.pooling.MaxPooling2D object at 0x7fec77e17790>>: AssertionError: Bad argument number for Name: 3, expecting 4
WARNING:tensorflow:Entity <bound method Conv.call of <tensorflow.python.layers.convolutional.Conv2D object at 0x7fec77e18cd0>> could not be transformed and will be executed as-is. Please report this to the AutgoGraph team. When filing the bug, set the verbosity to 10 (on Linux, `export AUTOGRAPH_VERBOSITY=10`) and attach the full output. Cause: converting <bound method Conv.call of <tensorflow.python.layers.convolutional.Conv2D object at 0x7fec77e18cd0>>: AssertionError: Bad argument number for Name: 3, expecting 4
W0114 14:23:06.106325 140655556867904 ag_logging.py:145] Entity <bound method Conv.call of <tensorflow.python.layers.convolutional.Conv2D object at 0x7fec77e18cd0>> could not be transformed and will be executed as-is. Please report this to the AutgoGraph team. When filing the bug, set the verbosity to 10 (on Linux, `export AUTOGRAPH_VERBOSITY=10`) and attach the full output. Cause: converting <bound method Conv.call of <tensorflow.python.layers.convolutional.Conv2D object at 0x7fec77e18cd0>>: AssertionError: Bad argument number for Name: 3, expecting 4
WARNING:tensorflow:Entity <bound method Conv.call of <tensorflow.python.layers.convolutional.Conv2D object at 0x7fec77e188d0>> could not be transformed and will be executed as-is. Please report this to the AutgoGraph team. When filing the bug, set the verbosity to 10 (on Linux, `export AUTOGRAPH_VERBOSITY=10`) and attach the full output. Cause: converting <bound method Conv.call of <tensorflow.python.layers.convolutional.Conv2D object at 0x7fec77e188d0>>: AssertionError: Bad argument number for Name: 3, expecting 4
W0114 14:23:06.212139 140655556867904 ag_logging.py:145] Entity <bound method Conv.call of <tensorflow.python.layers.convolutional.Conv2D object at 0x7fec77e188d0>> could not be transformed and will be executed as-is. Please report this to the AutgoGraph team. When filing the bug, set the verbosity to 10 (on Linux, `export AUTOGRAPH_VERBOSITY=10`) and attach the full output. Cause: converting <bound method Conv.call of <tensorflow.python.layers.convolutional.Conv2D object at 0x7fec77e188d0>>: AssertionError: Bad argument number for Name: 3, expecting 4
WARNING:tensorflow:Entity <bound method Conv.call of <tensorflow.python.layers.convolutional.Conv2D object at 0x7fec77ed23d0>> could not be transformed and will be executed as-is. Please report this to the AutgoGraph team. When filing the bug, set the verbosity to 10 (on Linux, `export AUTOGRAPH_VERBOSITY=10`) and attach the full output. Cause: converting <bound method Conv.call of <tensorflow.python.layers.convolutional.Conv2D object at 0x7fec77ed23d0>>: AssertionError: Bad argument number for Name: 3, expecting 4
W0114 14:23:06.317317 140655556867904 ag_logging.py:145] Entity <bound method Conv.call of <tensorflow.python.layers.convolutional.Conv2D object at 0x7fec77ed23d0>> could not be transformed and will be executed as-is. Please report this to the AutgoGraph team. When filing the bug, set the verbosity to 10 (on Linux, `export AUTOGRAPH_VERBOSITY=10`) and attach the full output. Cause: converting <bound method Conv.call of <tensorflow.python.layers.convolutional.Conv2D object at 0x7fec77ed23d0>>: AssertionError: Bad argument number for Name: 3, expecting 4
WARNING:tensorflow:Entity <bound method Pooling2D.call of <tensorflow.python.layers.pooling.MaxPooling2D object at 0x7fec77d8de90>> could not be transformed and will be executed as-is. Please report this to the AutgoGraph team. When filing the bug, set the verbosity to 10 (on Linux, `export AUTOGRAPH_VERBOSITY=10`) and attach the full output. Cause: converting <bound method Pooling2D.call of <tensorflow.python.layers.pooling.MaxPooling2D object at 0x7fec77d8de90>>: AssertionError: Bad argument number for Name: 3, expecting 4
W0114 14:23:06.380875 140655556867904 ag_logging.py:145] Entity <bound method Pooling2D.call of <tensorflow.python.layers.pooling.MaxPooling2D object at 0x7fec77d8de90>> could not be transformed and will be executed as-is. Please report this to the AutgoGraph team. When filing the bug, set the verbosity to 10 (on Linux, `export AUTOGRAPH_VERBOSITY=10`) and attach the full output. Cause: converting <bound method Pooling2D.call of <tensorflow.python.layers.pooling.MaxPooling2D object at 0x7fec77d8de90>>: AssertionError: Bad argument number for Name: 3, expecting 4
WARNING:tensorflow:Entity <bound method Conv.call of <tensorflow.python.layers.convolutional.Conv2D object at 0x7fec77e71990>> could not be transformed and will be executed as-is. Please report this to the AutgoGraph team. When filing the bug, set the verbosity to 10 (on Linux, `export AUTOGRAPH_VERBOSITY=10`) and attach the full output. Cause: converting <bound method Conv.call of <tensorflow.python.layers.convolutional.Conv2D object at 0x7fec77e71990>>: AssertionError: Bad argument number for Name: 3, expecting 4
W0114 14:23:06.485426 140655556867904 ag_logging.py:145] Entity <bound method Conv.call of <tensorflow.python.layers.convolutional.Conv2D object at 0x7fec77e71990>> could not be transformed and will be executed as-is. Please report this to the AutgoGraph team. When filing the bug, set the verbosity to 10 (on Linux, `export AUTOGRAPH_VERBOSITY=10`) and attach the full output. Cause: converting <bound method Conv.call of <tensorflow.python.layers.convolutional.Conv2D object at 0x7fec77e71990>>: AssertionError: Bad argument number for Name: 3, expecting 4
WARNING:tensorflow:Entity <bound method Conv.call of <tensorflow.python.layers.convolutional.Conv2D object at 0x7fec77d76d50>> could not be transformed and will be executed as-is. Please report this to the AutgoGraph team. When filing the bug, set the verbosity to 10 (on Linux, `export AUTOGRAPH_VERBOSITY=10`) and attach the full output. Cause: converting <bound method Conv.call of <tensorflow.python.layers.convolutional.Conv2D object at 0x7fec77d76d50>>: AssertionError: Bad argument number for Name: 3, expecting 4
W0114 14:23:06.590602 140655556867904 ag_logging.py:145] Entity <bound method Conv.call of <tensorflow.python.layers.convolutional.Conv2D object at 0x7fec77d76d50>> could not be transformed and will be executed as-is. Please report this to the AutgoGraph team. When filing the bug, set the verbosity to 10 (on Linux, `export AUTOGRAPH_VERBOSITY=10`) and attach the full output. Cause: converting <bound method Conv.call of <tensorflow.python.layers.convolutional.Conv2D object at 0x7fec77d76d50>>: AssertionError: Bad argument number for Name: 3, expecting 4
WARNING:tensorflow:Entity <bound method Conv.call of <tensorflow.python.layers.convolutional.Conv2D object at 0x7fec77e176d0>> could not be transformed and will be executed as-is. Please report this to the AutgoGraph team. When filing the bug, set the verbosity to 10 (on Linux, `export AUTOGRAPH_VERBOSITY=10`) and attach the full output. Cause: converting <bound method Conv.call of <tensorflow.python.layers.convolutional.Conv2D object at 0x7fec77e176d0>>: AssertionError: Bad argument number for Name: 3, expecting 4
W0114 14:23:06.695889 140655556867904 ag_logging.py:145] Entity <bound method Conv.call of <tensorflow.python.layers.convolutional.Conv2D object at 0x7fec77e176d0>> could not be transformed and will be executed as-is. Please report this to the AutgoGraph team. When filing the bug, set the verbosity to 10 (on Linux, `export AUTOGRAPH_VERBOSITY=10`) and attach the full output. Cause: converting <bound method Conv.call of <tensorflow.python.layers.convolutional.Conv2D object at 0x7fec77e176d0>>: AssertionError: Bad argument number for Name: 3, expecting 4
WARNING:tensorflow:Entity <bound method Pooling2D.call of <tensorflow.python.layers.pooling.MaxPooling2D object at 0x7fec77ec4b50>> could not be transformed and will be executed as-is. Please report this to the AutgoGraph team. When filing the bug, set the verbosity to 10 (on Linux, `export AUTOGRAPH_VERBOSITY=10`) and attach the full output. Cause: converting <bound method Pooling2D.call of <tensorflow.python.layers.pooling.MaxPooling2D object at 0x7fec77ec4b50>>: AssertionError: Bad argument number for Name: 3, expecting 4
W0114 14:23:06.759469 140655556867904 ag_logging.py:145] Entity <bound method Pooling2D.call of <tensorflow.python.layers.pooling.MaxPooling2D object at 0x7fec77ec4b50>> could not be transformed and will be executed as-is. Please report this to the AutgoGraph team. When filing the bug, set the verbosity to 10 (on Linux, `export AUTOGRAPH_VERBOSITY=10`) and attach the full output. Cause: converting <bound method Pooling2D.call of <tensorflow.python.layers.pooling.MaxPooling2D object at 0x7fec77ec4b50>>: AssertionError: Bad argument number for Name: 3, expecting 4
WARNING:tensorflow:Entity <bound method Conv.call of <tensorflow.python.layers.convolutional.Conv2D object at 0x7fec77e17350>> could not be transformed and will be executed as-is. Please report this to the AutgoGraph team. When filing the bug, set the verbosity to 10 (on Linux, `export AUTOGRAPH_VERBOSITY=10`) and attach the full output. Cause: converting <bound method Conv.call of <tensorflow.python.layers.convolutional.Conv2D object at 0x7fec77e17350>>: AssertionError: Bad argument number for Name: 3, expecting 4
W0114 14:23:06.865367 140655556867904 ag_logging.py:145] Entity <bound method Conv.call of <tensorflow.python.layers.convolutional.Conv2D object at 0x7fec77e17350>> could not be transformed and will be executed as-is. Please report this to the AutgoGraph team. When filing the bug, set the verbosity to 10 (on Linux, `export AUTOGRAPH_VERBOSITY=10`) and attach the full output. Cause: converting <bound method Conv.call of <tensorflow.python.layers.convolutional.Conv2D object at 0x7fec77e17350>>: AssertionError: Bad argument number for Name: 3, expecting 4
WARNING:tensorflow:Entity <bound method Dropout.call of <tensorflow.python.layers.core.Dropout object at 0x7fec77e196d0>> could not be transformed and will be executed as-is. Please report this to the AutgoGraph team. When filing the bug, set the verbosity to 10 (on Linux, `export AUTOGRAPH_VERBOSITY=10`) and attach the full output. Cause: converting <bound method Dropout.call of <tensorflow.python.layers.core.Dropout object at 0x7fec77e196d0>>: AssertionError: Bad argument number for Name: 3, expecting 4
W0114 14:23:06.886489 140655556867904 ag_logging.py:145] Entity <bound method Dropout.call of <tensorflow.python.layers.core.Dropout object at 0x7fec77e196d0>> could not be transformed and will be executed as-is. Please report this to the AutgoGraph team. When filing the bug, set the verbosity to 10 (on Linux, `export AUTOGRAPH_VERBOSITY=10`) and attach the full output. Cause: converting <bound method Dropout.call of <tensorflow.python.layers.core.Dropout object at 0x7fec77e196d0>>: AssertionError: Bad argument number for Name: 3, expecting 4
WARNING:tensorflow:Entity <bound method Conv.call of <tensorflow.python.layers.convolutional.Conv2D object at 0x7fec77e17350>> could not be transformed and will be executed as-is. Please report this to the AutgoGraph team. When filing the bug, set the verbosity to 10 (on Linux, `export AUTOGRAPH_VERBOSITY=10`) and attach the full output. Cause: converting <bound method Conv.call of <tensorflow.python.layers.convolutional.Conv2D object at 0x7fec77e17350>>: AssertionError: Bad argument number for Name: 3, expecting 4
W0114 14:23:07.007072 140655556867904 ag_logging.py:145] Entity <bound method Conv.call of <tensorflow.python.layers.convolutional.Conv2D object at 0x7fec77e17350>> could not be transformed and will be executed as-is. Please report this to the AutgoGraph team. When filing the bug, set the verbosity to 10 (on Linux, `export AUTOGRAPH_VERBOSITY=10`) and attach the full output. Cause: converting <bound method Conv.call of <tensorflow.python.layers.convolutional.Conv2D object at 0x7fec77e17350>>: AssertionError: Bad argument number for Name: 3, expecting 4
WARNING:tensorflow:Entity <bound method Dropout.call of <tensorflow.python.layers.core.Dropout object at 0x7fec77c06110>> could not be transformed and will be executed as-is. Please report this to the AutgoGraph team. When filing the bug, set the verbosity to 10 (on Linux, `export AUTOGRAPH_VERBOSITY=10`) and attach the full output. Cause: converting <bound method Dropout.call of <tensorflow.python.layers.core.Dropout object at 0x7fec77c06110>>: AssertionError: Bad argument number for Name: 3, expecting 4
W0114 14:23:07.028507 140655556867904 ag_logging.py:145] Entity <bound method Dropout.call of <tensorflow.python.layers.core.Dropout object at 0x7fec77c06110>> could not be transformed and will be executed as-is. Please report this to the AutgoGraph team. When filing the bug, set the verbosity to 10 (on Linux, `export AUTOGRAPH_VERBOSITY=10`) and attach the full output. Cause: converting <bound method Dropout.call of <tensorflow.python.layers.core.Dropout object at 0x7fec77c06110>>: AssertionError: Bad argument number for Name: 3, expecting 4
WARNING:tensorflow:Entity <bound method Conv.call of <tensorflow.python.layers.convolutional.Conv2D object at 0x7fec77c06110>> could not be transformed and will be executed as-is. Please report this to the AutgoGraph team. When filing the bug, set the verbosity to 10 (on Linux, `export AUTOGRAPH_VERBOSITY=10`) and attach the full output. Cause: converting <bound method Conv.call of <tensorflow.python.layers.convolutional.Conv2D object at 0x7fec77c06110>>: AssertionError: Bad argument number for Name: 3, expecting 4
W0114 14:23:07.148643 140655556867904 ag_logging.py:145] Entity <bound method Conv.call of <tensorflow.python.layers.convolutional.Conv2D object at 0x7fec77c06110>> could not be transformed and will be executed as-is. Please report this to the AutgoGraph team. When filing the bug, set the verbosity to 10 (on Linux, `export AUTOGRAPH_VERBOSITY=10`) and attach the full output. Cause: converting <bound method Conv.call of <tensorflow.python.layers.convolutional.Conv2D object at 0x7fec77c06110>>: AssertionError: Bad argument number for Name: 3, expecting 4
WARNING:tensorflow:From train_image_classifier_biasCNN_TEST.py:567: The name tf.losses.softmax_cross_entropy is deprecated. Please use tf.compat.v1.losses.softmax_cross_entropy instead.

W0114 14:23:07.152241 140655556867904 deprecation_wrapper.py:119] From train_image_classifier_biasCNN_TEST.py:567: The name tf.losses.softmax_cross_entropy is deprecated. Please use tf.compat.v1.losses.softmax_cross_entropy instead.

WARNING:tensorflow:From /home/AD/mmhender/anaconda3/lib/python3.7/site-packages/tensorflow/python/ops/losses/losses_impl.py:121: add_dispatch_support.<locals>.wrapper (from tensorflow.python.ops.array_ops) is deprecated and will be removed in a future version.
Instructions for updating:
Use tf.where in 2.0, which has the same broadcast rule as np.where
W0114 14:23:07.190411 140655556867904 deprecation.py:323] From /home/AD/mmhender/anaconda3/lib/python3.7/site-packages/tensorflow/python/ops/losses/losses_impl.py:121: add_dispatch_support.<locals>.wrapper (from tensorflow.python.ops.array_ops) is deprecated and will be removed in a future version.
Instructions for updating:
Use tf.where in 2.0, which has the same broadcast rule as np.where
WARNING:tensorflow:From train_image_classifier_biasCNN_TEST.py:588: The name tf.summary.image is deprecated. Please use tf.compat.v1.summary.image instead.

W0114 14:23:07.201532 140655556867904 deprecation_wrapper.py:119] From train_image_classifier_biasCNN_TEST.py:588: The name tf.summary.image is deprecated. Please use tf.compat.v1.summary.image instead.

WARNING:tensorflow:From train_image_classifier_biasCNN_TEST.py:589: The name tf.summary.histogram is deprecated. Please use tf.compat.v1.summary.histogram instead.

W0114 14:23:07.218957 140655556867904 deprecation_wrapper.py:119] From train_image_classifier_biasCNN_TEST.py:589: The name tf.summary.histogram is deprecated. Please use tf.compat.v1.summary.histogram instead.

WARNING:tensorflow:From train_image_classifier_biasCNN_TEST.py:590: The name tf.summary.scalar is deprecated. Please use tf.compat.v1.summary.scalar instead.

W0114 14:23:07.220426 140655556867904 deprecation_wrapper.py:119] From train_image_classifier_biasCNN_TEST.py:590: The name tf.summary.scalar is deprecated. Please use tf.compat.v1.summary.scalar instead.

WARNING:tensorflow:From train_image_classifier_biasCNN_TEST.py:301: The name tf.train.exponential_decay is deprecated. Please use tf.compat.v1.train.exponential_decay instead.

W0114 14:23:07.999545 140655556867904 deprecation_wrapper.py:119] From train_image_classifier_biasCNN_TEST.py:301: The name tf.train.exponential_decay is deprecated. Please use tf.compat.v1.train.exponential_decay instead.

WARNING:tensorflow:From train_image_classifier_biasCNN_TEST.py:362: The name tf.train.RMSPropOptimizer is deprecated. Please use tf.compat.v1.train.RMSPropOptimizer instead.

W0114 14:23:08.007546 140655556867904 deprecation_wrapper.py:119] From train_image_classifier_biasCNN_TEST.py:362: The name tf.train.RMSPropOptimizer is deprecated. Please use tf.compat.v1.train.RMSPropOptimizer instead.

WARNING:tensorflow:From /home/AD/mmhender/anaconda3/lib/python3.7/site-packages/tensorflow/python/training/rmsprop.py:119: calling Ones.__init__ (from tensorflow.python.ops.init_ops) with dtype is deprecated and will be removed in a future version.
Instructions for updating:
Call initializer instance with the dtype argument instead of passing it to the constructor
W0114 14:23:08.207257 140655556867904 deprecation.py:506] From /home/AD/mmhender/anaconda3/lib/python3.7/site-packages/tensorflow/python/training/rmsprop.py:119: calling Ones.__init__ (from tensorflow.python.ops.init_ops) with dtype is deprecated and will be removed in a future version.
Instructions for updating:
Call initializer instance with the dtype argument instead of passing it to the constructor
INFO:tensorflow:Scale of 0 disables regularizer.
I0114 14:23:08.645011 140655556867904 regularizers.py:98] Scale of 0 disables regularizer.
WARNING:tensorflow:Entity <bound method Conv.call of <tensorflow.python.layers.convolutional.Conv2D object at 0x7fec77382450>> could not be transformed and will be executed as-is. Please report this to the AutgoGraph team. When filing the bug, set the verbosity to 10 (on Linux, `export AUTOGRAPH_VERBOSITY=10`) and attach the full output. Cause: converting <bound method Conv.call of <tensorflow.python.layers.convolutional.Conv2D object at 0x7fec77382450>>: AssertionError: Bad argument number for Name: 3, expecting 4
W0114 14:23:08.766868 140655556867904 ag_logging.py:145] Entity <bound method Conv.call of <tensorflow.python.layers.convolutional.Conv2D object at 0x7fec77382450>> could not be transformed and will be executed as-is. Please report this to the AutgoGraph team. When filing the bug, set the verbosity to 10 (on Linux, `export AUTOGRAPH_VERBOSITY=10`) and attach the full output. Cause: converting <bound method Conv.call of <tensorflow.python.layers.convolutional.Conv2D object at 0x7fec77382450>>: AssertionError: Bad argument number for Name: 3, expecting 4
WARNING:tensorflow:Entity <bound method Conv.call of <tensorflow.python.layers.convolutional.Conv2D object at 0x7fec773828d0>> could not be transformed and will be executed as-is. Please report this to the AutgoGraph team. When filing the bug, set the verbosity to 10 (on Linux, `export AUTOGRAPH_VERBOSITY=10`) and attach the full output. Cause: converting <bound method Conv.call of <tensorflow.python.layers.convolutional.Conv2D object at 0x7fec773828d0>>: AssertionError: Bad argument number for Name: 3, expecting 4
W0114 14:23:08.879718 140655556867904 ag_logging.py:145] Entity <bound method Conv.call of <tensorflow.python.layers.convolutional.Conv2D object at 0x7fec773828d0>> could not be transformed and will be executed as-is. Please report this to the AutgoGraph team. When filing the bug, set the verbosity to 10 (on Linux, `export AUTOGRAPH_VERBOSITY=10`) and attach the full output. Cause: converting <bound method Conv.call of <tensorflow.python.layers.convolutional.Conv2D object at 0x7fec773828d0>>: AssertionError: Bad argument number for Name: 3, expecting 4
WARNING:tensorflow:Entity <bound method Pooling2D.call of <tensorflow.python.layers.pooling.MaxPooling2D object at 0x7fec77572390>> could not be transformed and will be executed as-is. Please report this to the AutgoGraph team. When filing the bug, set the verbosity to 10 (on Linux, `export AUTOGRAPH_VERBOSITY=10`) and attach the full output. Cause: converting <bound method Pooling2D.call of <tensorflow.python.layers.pooling.MaxPooling2D object at 0x7fec77572390>>: AssertionError: Bad argument number for Name: 3, expecting 4
W0114 14:23:08.958372 140655556867904 ag_logging.py:145] Entity <bound method Pooling2D.call of <tensorflow.python.layers.pooling.MaxPooling2D object at 0x7fec77572390>> could not be transformed and will be executed as-is. Please report this to the AutgoGraph team. When filing the bug, set the verbosity to 10 (on Linux, `export AUTOGRAPH_VERBOSITY=10`) and attach the full output. Cause: converting <bound method Pooling2D.call of <tensorflow.python.layers.pooling.MaxPooling2D object at 0x7fec77572390>>: AssertionError: Bad argument number for Name: 3, expecting 4
WARNING:tensorflow:Entity <bound method Conv.call of <tensorflow.python.layers.convolutional.Conv2D object at 0x7fec77382450>> could not be transformed and will be executed as-is. Please report this to the AutgoGraph team. When filing the bug, set the verbosity to 10 (on Linux, `export AUTOGRAPH_VERBOSITY=10`) and attach the full output. Cause: converting <bound method Conv.call of <tensorflow.python.layers.convolutional.Conv2D object at 0x7fec77382450>>: AssertionError: Bad argument number for Name: 3, expecting 4
W0114 14:23:09.068175 140655556867904 ag_logging.py:145] Entity <bound method Conv.call of <tensorflow.python.layers.convolutional.Conv2D object at 0x7fec77382450>> could not be transformed and will be executed as-is. Please report this to the AutgoGraph team. When filing the bug, set the verbosity to 10 (on Linux, `export AUTOGRAPH_VERBOSITY=10`) and attach the full output. Cause: converting <bound method Conv.call of <tensorflow.python.layers.convolutional.Conv2D object at 0x7fec77382450>>: AssertionError: Bad argument number for Name: 3, expecting 4
WARNING:tensorflow:Entity <bound method Conv.call of <tensorflow.python.layers.convolutional.Conv2D object at 0x7fec77382750>> could not be transformed and will be executed as-is. Please report this to the AutgoGraph team. When filing the bug, set the verbosity to 10 (on Linux, `export AUTOGRAPH_VERBOSITY=10`) and attach the full output. Cause: converting <bound method Conv.call of <tensorflow.python.layers.convolutional.Conv2D object at 0x7fec77382750>>: AssertionError: Bad argument number for Name: 3, expecting 4
W0114 14:23:09.179442 140655556867904 ag_logging.py:145] Entity <bound method Conv.call of <tensorflow.python.layers.convolutional.Conv2D object at 0x7fec77382750>> could not be transformed and will be executed as-is. Please report this to the AutgoGraph team. When filing the bug, set the verbosity to 10 (on Linux, `export AUTOGRAPH_VERBOSITY=10`) and attach the full output. Cause: converting <bound method Conv.call of <tensorflow.python.layers.convolutional.Conv2D object at 0x7fec77382750>>: AssertionError: Bad argument number for Name: 3, expecting 4
WARNING:tensorflow:Entity <bound method Pooling2D.call of <tensorflow.python.layers.pooling.MaxPooling2D object at 0x7fec77e0eb50>> could not be transformed and will be executed as-is. Please report this to the AutgoGraph team. When filing the bug, set the verbosity to 10 (on Linux, `export AUTOGRAPH_VERBOSITY=10`) and attach the full output. Cause: converting <bound method Pooling2D.call of <tensorflow.python.layers.pooling.MaxPooling2D object at 0x7fec77e0eb50>>: AssertionError: Bad argument number for Name: 3, expecting 4
W0114 14:23:09.258149 140655556867904 ag_logging.py:145] Entity <bound method Pooling2D.call of <tensorflow.python.layers.pooling.MaxPooling2D object at 0x7fec77e0eb50>> could not be transformed and will be executed as-is. Please report this to the AutgoGraph team. When filing the bug, set the verbosity to 10 (on Linux, `export AUTOGRAPH_VERBOSITY=10`) and attach the full output. Cause: converting <bound method Pooling2D.call of <tensorflow.python.layers.pooling.MaxPooling2D object at 0x7fec77e0eb50>>: AssertionError: Bad argument number for Name: 3, expecting 4
WARNING:tensorflow:Entity <bound method Conv.call of <tensorflow.python.layers.convolutional.Conv2D object at 0x7fec775722d0>> could not be transformed and will be executed as-is. Please report this to the AutgoGraph team. When filing the bug, set the verbosity to 10 (on Linux, `export AUTOGRAPH_VERBOSITY=10`) and attach the full output. Cause: converting <bound method Conv.call of <tensorflow.python.layers.convolutional.Conv2D object at 0x7fec775722d0>>: AssertionError: Bad argument number for Name: 3, expecting 4
W0114 14:23:09.367782 140655556867904 ag_logging.py:145] Entity <bound method Conv.call of <tensorflow.python.layers.convolutional.Conv2D object at 0x7fec775722d0>> could not be transformed and will be executed as-is. Please report this to the AutgoGraph team. When filing the bug, set the verbosity to 10 (on Linux, `export AUTOGRAPH_VERBOSITY=10`) and attach the full output. Cause: converting <bound method Conv.call of <tensorflow.python.layers.convolutional.Conv2D object at 0x7fec775722d0>>: AssertionError: Bad argument number for Name: 3, expecting 4
WARNING:tensorflow:Entity <bound method Conv.call of <tensorflow.python.layers.convolutional.Conv2D object at 0x7fec77e0ed50>> could not be transformed and will be executed as-is. Please report this to the AutgoGraph team. When filing the bug, set the verbosity to 10 (on Linux, `export AUTOGRAPH_VERBOSITY=10`) and attach the full output. Cause: converting <bound method Conv.call of <tensorflow.python.layers.convolutional.Conv2D object at 0x7fec77e0ed50>>: AssertionError: Bad argument number for Name: 3, expecting 4
W0114 14:23:09.479037 140655556867904 ag_logging.py:145] Entity <bound method Conv.call of <tensorflow.python.layers.convolutional.Conv2D object at 0x7fec77e0ed50>> could not be transformed and will be executed as-is. Please report this to the AutgoGraph team. When filing the bug, set the verbosity to 10 (on Linux, `export AUTOGRAPH_VERBOSITY=10`) and attach the full output. Cause: converting <bound method Conv.call of <tensorflow.python.layers.convolutional.Conv2D object at 0x7fec77e0ed50>>: AssertionError: Bad argument number for Name: 3, expecting 4
WARNING:tensorflow:Entity <bound method Conv.call of <tensorflow.python.layers.convolutional.Conv2D object at 0x7fec77e8ab90>> could not be transformed and will be executed as-is. Please report this to the AutgoGraph team. When filing the bug, set the verbosity to 10 (on Linux, `export AUTOGRAPH_VERBOSITY=10`) and attach the full output. Cause: converting <bound method Conv.call of <tensorflow.python.layers.convolutional.Conv2D object at 0x7fec77e8ab90>>: AssertionError: Bad argument number for Name: 3, expecting 4
W0114 14:23:09.596803 140655556867904 ag_logging.py:145] Entity <bound method Conv.call of <tensorflow.python.layers.convolutional.Conv2D object at 0x7fec77e8ab90>> could not be transformed and will be executed as-is. Please report this to the AutgoGraph team. When filing the bug, set the verbosity to 10 (on Linux, `export AUTOGRAPH_VERBOSITY=10`) and attach the full output. Cause: converting <bound method Conv.call of <tensorflow.python.layers.convolutional.Conv2D object at 0x7fec77e8ab90>>: AssertionError: Bad argument number for Name: 3, expecting 4
WARNING:tensorflow:Entity <bound method Pooling2D.call of <tensorflow.python.layers.pooling.MaxPooling2D object at 0x7fec77382650>> could not be transformed and will be executed as-is. Please report this to the AutgoGraph team. When filing the bug, set the verbosity to 10 (on Linux, `export AUTOGRAPH_VERBOSITY=10`) and attach the full output. Cause: converting <bound method Pooling2D.call of <tensorflow.python.layers.pooling.MaxPooling2D object at 0x7fec77382650>>: AssertionError: Bad argument number for Name: 3, expecting 4
W0114 14:23:09.687121 140655556867904 ag_logging.py:145] Entity <bound method Pooling2D.call of <tensorflow.python.layers.pooling.MaxPooling2D object at 0x7fec77382650>> could not be transformed and will be executed as-is. Please report this to the AutgoGraph team. When filing the bug, set the verbosity to 10 (on Linux, `export AUTOGRAPH_VERBOSITY=10`) and attach the full output. Cause: converting <bound method Pooling2D.call of <tensorflow.python.layers.pooling.MaxPooling2D object at 0x7fec77382650>>: AssertionError: Bad argument number for Name: 3, expecting 4
WARNING:tensorflow:Entity <bound method Conv.call of <tensorflow.python.layers.convolutional.Conv2D object at 0x7fec77572f90>> could not be transformed and will be executed as-is. Please report this to the AutgoGraph team. When filing the bug, set the verbosity to 10 (on Linux, `export AUTOGRAPH_VERBOSITY=10`) and attach the full output. Cause: converting <bound method Conv.call of <tensorflow.python.layers.convolutional.Conv2D object at 0x7fec77572f90>>: AssertionError: Bad argument number for Name: 3, expecting 4
W0114 14:23:09.776584 140655556867904 ag_logging.py:145] Entity <bound method Conv.call of <tensorflow.python.layers.convolutional.Conv2D object at 0x7fec77572f90>> could not be transformed and will be executed as-is. Please report this to the AutgoGraph team. When filing the bug, set the verbosity to 10 (on Linux, `export AUTOGRAPH_VERBOSITY=10`) and attach the full output. Cause: converting <bound method Conv.call of <tensorflow.python.layers.convolutional.Conv2D object at 0x7fec77572f90>>: AssertionError: Bad argument number for Name: 3, expecting 4
WARNING:tensorflow:Entity <bound method Conv.call of <tensorflow.python.layers.convolutional.Conv2D object at 0x7fec773ae2d0>> could not be transformed and will be executed as-is. Please report this to the AutgoGraph team. When filing the bug, set the verbosity to 10 (on Linux, `export AUTOGRAPH_VERBOSITY=10`) and attach the full output. Cause: converting <bound method Conv.call of <tensorflow.python.layers.convolutional.Conv2D object at 0x7fec773ae2d0>>: AssertionError: Bad argument number for Name: 3, expecting 4
W0114 14:23:09.866788 140655556867904 ag_logging.py:145] Entity <bound method Conv.call of <tensorflow.python.layers.convolutional.Conv2D object at 0x7fec773ae2d0>> could not be transformed and will be executed as-is. Please report this to the AutgoGraph team. When filing the bug, set the verbosity to 10 (on Linux, `export AUTOGRAPH_VERBOSITY=10`) and attach the full output. Cause: converting <bound method Conv.call of <tensorflow.python.layers.convolutional.Conv2D object at 0x7fec773ae2d0>>: AssertionError: Bad argument number for Name: 3, expecting 4
WARNING:tensorflow:Entity <bound method Conv.call of <tensorflow.python.layers.convolutional.Conv2D object at 0x7fec773ae5d0>> could not be transformed and will be executed as-is. Please report this to the AutgoGraph team. When filing the bug, set the verbosity to 10 (on Linux, `export AUTOGRAPH_VERBOSITY=10`) and attach the full output. Cause: converting <bound method Conv.call of <tensorflow.python.layers.convolutional.Conv2D object at 0x7fec773ae5d0>>: AssertionError: Bad argument number for Name: 3, expecting 4
W0114 14:23:09.957063 140655556867904 ag_logging.py:145] Entity <bound method Conv.call of <tensorflow.python.layers.convolutional.Conv2D object at 0x7fec773ae5d0>> could not be transformed and will be executed as-is. Please report this to the AutgoGraph team. When filing the bug, set the verbosity to 10 (on Linux, `export AUTOGRAPH_VERBOSITY=10`) and attach the full output. Cause: converting <bound method Conv.call of <tensorflow.python.layers.convolutional.Conv2D object at 0x7fec773ae5d0>>: AssertionError: Bad argument number for Name: 3, expecting 4
WARNING:tensorflow:Entity <bound method Pooling2D.call of <tensorflow.python.layers.pooling.MaxPooling2D object at 0x7fec77382390>> could not be transformed and will be executed as-is. Please report this to the AutgoGraph team. When filing the bug, set the verbosity to 10 (on Linux, `export AUTOGRAPH_VERBOSITY=10`) and attach the full output. Cause: converting <bound method Pooling2D.call of <tensorflow.python.layers.pooling.MaxPooling2D object at 0x7fec77382390>>: AssertionError: Bad argument number for Name: 3, expecting 4
W0114 14:23:10.020626 140655556867904 ag_logging.py:145] Entity <bound method Pooling2D.call of <tensorflow.python.layers.pooling.MaxPooling2D object at 0x7fec77382390>> could not be transformed and will be executed as-is. Please report this to the AutgoGraph team. When filing the bug, set the verbosity to 10 (on Linux, `export AUTOGRAPH_VERBOSITY=10`) and attach the full output. Cause: converting <bound method Pooling2D.call of <tensorflow.python.layers.pooling.MaxPooling2D object at 0x7fec77382390>>: AssertionError: Bad argument number for Name: 3, expecting 4
WARNING:tensorflow:Entity <bound method Conv.call of <tensorflow.python.layers.convolutional.Conv2D object at 0x7fec77346dd0>> could not be transformed and will be executed as-is. Please report this to the AutgoGraph team. When filing the bug, set the verbosity to 10 (on Linux, `export AUTOGRAPH_VERBOSITY=10`) and attach the full output. Cause: converting <bound method Conv.call of <tensorflow.python.layers.convolutional.Conv2D object at 0x7fec77346dd0>>: AssertionError: Bad argument number for Name: 3, expecting 4
W0114 14:23:10.109224 140655556867904 ag_logging.py:145] Entity <bound method Conv.call of <tensorflow.python.layers.convolutional.Conv2D object at 0x7fec77346dd0>> could not be transformed and will be executed as-is. Please report this to the AutgoGraph team. When filing the bug, set the verbosity to 10 (on Linux, `export AUTOGRAPH_VERBOSITY=10`) and attach the full output. Cause: converting <bound method Conv.call of <tensorflow.python.layers.convolutional.Conv2D object at 0x7fec77346dd0>>: AssertionError: Bad argument number for Name: 3, expecting 4
WARNING:tensorflow:Entity <bound method Conv.call of <tensorflow.python.layers.convolutional.Conv2D object at 0x7fec773aec90>> could not be transformed and will be executed as-is. Please report this to the AutgoGraph team. When filing the bug, set the verbosity to 10 (on Linux, `export AUTOGRAPH_VERBOSITY=10`) and attach the full output. Cause: converting <bound method Conv.call of <tensorflow.python.layers.convolutional.Conv2D object at 0x7fec773aec90>>: AssertionError: Bad argument number for Name: 3, expecting 4
W0114 14:23:10.199822 140655556867904 ag_logging.py:145] Entity <bound method Conv.call of <tensorflow.python.layers.convolutional.Conv2D object at 0x7fec773aec90>> could not be transformed and will be executed as-is. Please report this to the AutgoGraph team. When filing the bug, set the verbosity to 10 (on Linux, `export AUTOGRAPH_VERBOSITY=10`) and attach the full output. Cause: converting <bound method Conv.call of <tensorflow.python.layers.convolutional.Conv2D object at 0x7fec773aec90>>: AssertionError: Bad argument number for Name: 3, expecting 4
WARNING:tensorflow:Entity <bound method Conv.call of <tensorflow.python.layers.convolutional.Conv2D object at 0x7fec77e181d0>> could not be transformed and will be executed as-is. Please report this to the AutgoGraph team. When filing the bug, set the verbosity to 10 (on Linux, `export AUTOGRAPH_VERBOSITY=10`) and attach the full output. Cause: converting <bound method Conv.call of <tensorflow.python.layers.convolutional.Conv2D object at 0x7fec77e181d0>>: AssertionError: Bad argument number for Name: 3, expecting 4
W0114 14:23:10.290370 140655556867904 ag_logging.py:145] Entity <bound method Conv.call of <tensorflow.python.layers.convolutional.Conv2D object at 0x7fec77e181d0>> could not be transformed and will be executed as-is. Please report this to the AutgoGraph team. When filing the bug, set the verbosity to 10 (on Linux, `export AUTOGRAPH_VERBOSITY=10`) and attach the full output. Cause: converting <bound method Conv.call of <tensorflow.python.layers.convolutional.Conv2D object at 0x7fec77e181d0>>: AssertionError: Bad argument number for Name: 3, expecting 4
WARNING:tensorflow:Entity <bound method Pooling2D.call of <tensorflow.python.layers.pooling.MaxPooling2D object at 0x7fec77382450>> could not be transformed and will be executed as-is. Please report this to the AutgoGraph team. When filing the bug, set the verbosity to 10 (on Linux, `export AUTOGRAPH_VERBOSITY=10`) and attach the full output. Cause: converting <bound method Pooling2D.call of <tensorflow.python.layers.pooling.MaxPooling2D object at 0x7fec77382450>>: AssertionError: Bad argument number for Name: 3, expecting 4
W0114 14:23:10.353878 140655556867904 ag_logging.py:145] Entity <bound method Pooling2D.call of <tensorflow.python.layers.pooling.MaxPooling2D object at 0x7fec77382450>> could not be transformed and will be executed as-is. Please report this to the AutgoGraph team. When filing the bug, set the verbosity to 10 (on Linux, `export AUTOGRAPH_VERBOSITY=10`) and attach the full output. Cause: converting <bound method Pooling2D.call of <tensorflow.python.layers.pooling.MaxPooling2D object at 0x7fec77382450>>: AssertionError: Bad argument number for Name: 3, expecting 4
WARNING:tensorflow:Entity <bound method Conv.call of <tensorflow.python.layers.convolutional.Conv2D object at 0x7fec773ae2d0>> could not be transformed and will be executed as-is. Please report this to the AutgoGraph team. When filing the bug, set the verbosity to 10 (on Linux, `export AUTOGRAPH_VERBOSITY=10`) and attach the full output. Cause: converting <bound method Conv.call of <tensorflow.python.layers.convolutional.Conv2D object at 0x7fec773ae2d0>>: AssertionError: Bad argument number for Name: 3, expecting 4
W0114 14:23:10.442331 140655556867904 ag_logging.py:145] Entity <bound method Conv.call of <tensorflow.python.layers.convolutional.Conv2D object at 0x7fec773ae2d0>> could not be transformed and will be executed as-is. Please report this to the AutgoGraph team. When filing the bug, set the verbosity to 10 (on Linux, `export AUTOGRAPH_VERBOSITY=10`) and attach the full output. Cause: converting <bound method Conv.call of <tensorflow.python.layers.convolutional.Conv2D object at 0x7fec773ae2d0>>: AssertionError: Bad argument number for Name: 3, expecting 4
WARNING:tensorflow:Entity <bound method Dropout.call of <tensorflow.python.layers.core.Dropout object at 0x7fec773aed90>> could not be transformed and will be executed as-is. Please report this to the AutgoGraph team. When filing the bug, set the verbosity to 10 (on Linux, `export AUTOGRAPH_VERBOSITY=10`) and attach the full output. Cause: converting <bound method Dropout.call of <tensorflow.python.layers.core.Dropout object at 0x7fec773aed90>>: AssertionError: Bad argument number for Name: 3, expecting 4
W0114 14:23:10.463050 140655556867904 ag_logging.py:145] Entity <bound method Dropout.call of <tensorflow.python.layers.core.Dropout object at 0x7fec773aed90>> could not be transformed and will be executed as-is. Please report this to the AutgoGraph team. When filing the bug, set the verbosity to 10 (on Linux, `export AUTOGRAPH_VERBOSITY=10`) and attach the full output. Cause: converting <bound method Dropout.call of <tensorflow.python.layers.core.Dropout object at 0x7fec773aed90>>: AssertionError: Bad argument number for Name: 3, expecting 4
WARNING:tensorflow:Entity <bound method Conv.call of <tensorflow.python.layers.convolutional.Conv2D object at 0x7fec77e0e9d0>> could not be transformed and will be executed as-is. Please report this to the AutgoGraph team. When filing the bug, set the verbosity to 10 (on Linux, `export AUTOGRAPH_VERBOSITY=10`) and attach the full output. Cause: converting <bound method Conv.call of <tensorflow.python.layers.convolutional.Conv2D object at 0x7fec77e0e9d0>>: AssertionError: Bad argument number for Name: 3, expecting 4
W0114 14:23:10.551594 140655556867904 ag_logging.py:145] Entity <bound method Conv.call of <tensorflow.python.layers.convolutional.Conv2D object at 0x7fec77e0e9d0>> could not be transformed and will be executed as-is. Please report this to the AutgoGraph team. When filing the bug, set the verbosity to 10 (on Linux, `export AUTOGRAPH_VERBOSITY=10`) and attach the full output. Cause: converting <bound method Conv.call of <tensorflow.python.layers.convolutional.Conv2D object at 0x7fec77e0e9d0>>: AssertionError: Bad argument number for Name: 3, expecting 4
WARNING:tensorflow:Entity <bound method Dropout.call of <tensorflow.python.layers.core.Dropout object at 0x7fec77425a10>> could not be transformed and will be executed as-is. Please report this to the AutgoGraph team. When filing the bug, set the verbosity to 10 (on Linux, `export AUTOGRAPH_VERBOSITY=10`) and attach the full output. Cause: converting <bound method Dropout.call of <tensorflow.python.layers.core.Dropout object at 0x7fec77425a10>>: AssertionError: Bad argument number for Name: 3, expecting 4
W0114 14:23:10.572019 140655556867904 ag_logging.py:145] Entity <bound method Dropout.call of <tensorflow.python.layers.core.Dropout object at 0x7fec77425a10>> could not be transformed and will be executed as-is. Please report this to the AutgoGraph team. When filing the bug, set the verbosity to 10 (on Linux, `export AUTOGRAPH_VERBOSITY=10`) and attach the full output. Cause: converting <bound method Dropout.call of <tensorflow.python.layers.core.Dropout object at 0x7fec77425a10>>: AssertionError: Bad argument number for Name: 3, expecting 4
WARNING:tensorflow:Entity <bound method Conv.call of <tensorflow.python.layers.convolutional.Conv2D object at 0x7fec77e181d0>> could not be transformed and will be executed as-is. Please report this to the AutgoGraph team. When filing the bug, set the verbosity to 10 (on Linux, `export AUTOGRAPH_VERBOSITY=10`) and attach the full output. Cause: converting <bound method Conv.call of <tensorflow.python.layers.convolutional.Conv2D object at 0x7fec77e181d0>>: AssertionError: Bad argument number for Name: 3, expecting 4
W0114 14:23:10.660791 140655556867904 ag_logging.py:145] Entity <bound method Conv.call of <tensorflow.python.layers.convolutional.Conv2D object at 0x7fec77e181d0>> could not be transformed and will be executed as-is. Please report this to the AutgoGraph team. When filing the bug, set the verbosity to 10 (on Linux, `export AUTOGRAPH_VERBOSITY=10`) and attach the full output. Cause: converting <bound method Conv.call of <tensorflow.python.layers.convolutional.Conv2D object at 0x7fec77e181d0>>: AssertionError: Bad argument number for Name: 3, expecting 4
WARNING:tensorflow:From train_image_classifier_biasCNN_TEST.py:683: The name tf.metrics.accuracy is deprecated. Please use tf.compat.v1.metrics.accuracy instead.

W0114 14:23:10.714895 140655556867904 deprecation_wrapper.py:119] From train_image_classifier_biasCNN_TEST.py:683: The name tf.metrics.accuracy is deprecated. Please use tf.compat.v1.metrics.accuracy instead.

WARNING:tensorflow:From train_image_classifier_biasCNN_TEST.py:684: The name tf.metrics.recall_at_k is deprecated. Please use tf.compat.v1.metrics.recall_at_k instead.

W0114 14:23:10.732864 140655556867904 deprecation_wrapper.py:119] From train_image_classifier_biasCNN_TEST.py:684: The name tf.metrics.recall_at_k is deprecated. Please use tf.compat.v1.metrics.recall_at_k instead.

WARNING:tensorflow:From /home/AD/mmhender/anaconda3/lib/python3.7/site-packages/tensorflow/python/ops/metrics_impl.py:2640: div (from tensorflow.python.ops.math_ops) is deprecated and will be removed in a future version.
Instructions for updating:
Deprecated in favor of operator or tf.math.divide.
W0114 14:23:10.759251 140655556867904 deprecation.py:323] From /home/AD/mmhender/anaconda3/lib/python3.7/site-packages/tensorflow/python/ops/metrics_impl.py:2640: div (from tensorflow.python.ops.math_ops) is deprecated and will be removed in a future version.
Instructions for updating:
Deprecated in favor of operator or tf.math.divide.
WARNING:tensorflow:From /home/AD/mmhender/anaconda3/lib/python3.7/site-packages/tensorflow/python/util/tf_should_use.py:193: initialize_variables (from tensorflow.python.ops.variables) is deprecated and will be removed after 2017-03-02.
Instructions for updating:
Use `tf.variables_initializer` instead.
W0114 14:23:10.823269 140655556867904 deprecation.py:323] From /home/AD/mmhender/anaconda3/lib/python3.7/site-packages/tensorflow/python/util/tf_should_use.py:193: initialize_variables (from tensorflow.python.ops.variables) is deprecated and will be removed after 2017-03-02.
Instructions for updating:
Use `tf.variables_initializer` instead.
WARNING:tensorflow:From train_image_classifier_biasCNN_TEST.py:714: The name tf.summary.merge is deprecated. Please use tf.compat.v1.summary.merge instead.

W0114 14:23:10.824320 140655556867904 deprecation_wrapper.py:119] From train_image_classifier_biasCNN_TEST.py:714: The name tf.summary.merge is deprecated. Please use tf.compat.v1.summary.merge instead.

WARNING:tensorflow:From train_image_classifier_biasCNN_TEST.py:736: to_int64 (from tensorflow.python.ops.math_ops) is deprecated and will be removed in a future version.
Instructions for updating:
Use `tf.cast` instead.
W0114 14:23:10.913439 140655556867904 deprecation.py:323] From train_image_classifier_biasCNN_TEST.py:736: to_int64 (from tensorflow.python.ops.math_ops) is deprecated and will be removed in a future version.
Instructions for updating:
Use `tf.cast` instead.
WARNING:tensorflow:From /home/AD/mmhender/anaconda3/lib/python3.7/site-packages/tensorflow/contrib/slim/python/slim/learning.py:742: Supervisor.__init__ (from tensorflow.python.training.supervisor) is deprecated and will be removed in a future version.
Instructions for updating:
Please switch to tf.train.MonitoredTrainingSession
W0114 14:23:10.999264 140655556867904 deprecation.py:323] From /home/AD/mmhender/anaconda3/lib/python3.7/site-packages/tensorflow/contrib/slim/python/slim/learning.py:742: Supervisor.__init__ (from tensorflow.python.training.supervisor) is deprecated and will be removed in a future version.
Instructions for updating:
Please switch to tf.train.MonitoredTrainingSession
2020-01-14 14:23:11.198580: I tensorflow/stream_executor/platform/default/dso_loader.cc:42] Successfully opened dynamic library libcuda.so.1
2020-01-14 14:23:13.946699: I tensorflow/core/common_runtime/gpu/gpu_device.cc:1640] Found device 0 with properties: 
name: Tesla K40c major: 3 minor: 5 memoryClockRate(GHz): 0.745
pciBusID: 0000:03:00.0
2020-01-14 14:23:13.948623: I tensorflow/stream_executor/platform/default/dso_loader.cc:42] Successfully opened dynamic library libcudart.so.10.1
2020-01-14 14:23:13.952172: I tensorflow/stream_executor/platform/default/dso_loader.cc:42] Successfully opened dynamic library libcublas.so.10
2020-01-14 14:23:13.954780: I tensorflow/stream_executor/platform/default/dso_loader.cc:42] Successfully opened dynamic library libcufft.so.10
2020-01-14 14:23:13.955593: I tensorflow/stream_executor/platform/default/dso_loader.cc:42] Successfully opened dynamic library libcurand.so.10
2020-01-14 14:23:13.958501: I tensorflow/stream_executor/platform/default/dso_loader.cc:42] Successfully opened dynamic library libcusolver.so.10
2020-01-14 14:23:13.960655: I tensorflow/stream_executor/platform/default/dso_loader.cc:42] Successfully opened dynamic library libcusparse.so.10
2020-01-14 14:23:13.966488: I tensorflow/stream_executor/platform/default/dso_loader.cc:42] Successfully opened dynamic library libcudnn.so.7
2020-01-14 14:23:13.968531: I tensorflow/core/common_runtime/gpu/gpu_device.cc:1763] Adding visible gpu devices: 0
2020-01-14 14:23:13.969906: I tensorflow/core/platform/cpu_feature_guard.cc:142] Your CPU supports instructions that this TensorFlow binary was not compiled to use: SSE4.1 SSE4.2 AVX
2020-01-14 14:23:14.004225: I tensorflow/core/platform/profile_utils/cpu_utils.cc:94] CPU Frequency: 2100030000 Hz
2020-01-14 14:23:14.006639: I tensorflow/compiler/xla/service/service.cc:168] XLA service 0x55ab981994f0 executing computations on platform Host. Devices:
2020-01-14 14:23:14.006686: I tensorflow/compiler/xla/service/service.cc:175]   StreamExecutor device (0): <undefined>, <undefined>
2020-01-14 14:23:14.008176: I tensorflow/core/common_runtime/gpu/gpu_device.cc:1640] Found device 0 with properties: 
name: Tesla K40c major: 3 minor: 5 memoryClockRate(GHz): 0.745
pciBusID: 0000:03:00.0
2020-01-14 14:23:14.008268: I tensorflow/stream_executor/platform/default/dso_loader.cc:42] Successfully opened dynamic library libcudart.so.10.1
2020-01-14 14:23:14.008318: I tensorflow/stream_executor/platform/default/dso_loader.cc:42] Successfully opened dynamic library libcublas.so.10
2020-01-14 14:23:14.008365: I tensorflow/stream_executor/platform/default/dso_loader.cc:42] Successfully opened dynamic library libcufft.so.10
2020-01-14 14:23:14.008412: I tensorflow/stream_executor/platform/default/dso_loader.cc:42] Successfully opened dynamic library libcurand.so.10
2020-01-14 14:23:14.008459: I tensorflow/stream_executor/platform/default/dso_loader.cc:42] Successfully opened dynamic library libcusolver.so.10
2020-01-14 14:23:14.008506: I tensorflow/stream_executor/platform/default/dso_loader.cc:42] Successfully opened dynamic library libcusparse.so.10
2020-01-14 14:23:14.008554: I tensorflow/stream_executor/platform/default/dso_loader.cc:42] Successfully opened dynamic library libcudnn.so.7
2020-01-14 14:23:14.010842: I tensorflow/core/common_runtime/gpu/gpu_device.cc:1763] Adding visible gpu devices: 0
2020-01-14 14:23:14.010919: I tensorflow/stream_executor/platform/default/dso_loader.cc:42] Successfully opened dynamic library libcudart.so.10.1
2020-01-14 14:23:14.069978: I tensorflow/core/common_runtime/gpu/gpu_device.cc:1181] Device interconnect StreamExecutor with strength 1 edge matrix:
2020-01-14 14:23:14.070032: I tensorflow/core/common_runtime/gpu/gpu_device.cc:1187]      0 
2020-01-14 14:23:14.070047: I tensorflow/core/common_runtime/gpu/gpu_device.cc:1200] 0:   N 
2020-01-14 14:23:14.073209: I tensorflow/core/common_runtime/gpu/gpu_device.cc:1326] Created TensorFlow device (/job:localhost/replica:0/task:0/device:GPU:0 with 10798 MB memory) -> physical GPU (device: 0, name: Tesla K40c, pci bus id: 0000:03:00.0, compute capability: 3.5)
2020-01-14 14:23:14.077743: I tensorflow/compiler/xla/service/service.cc:168] XLA service 0x55ab9a2f0f00 executing computations on platform CUDA. Devices:
2020-01-14 14:23:14.077776: I tensorflow/compiler/xla/service/service.cc:175]   StreamExecutor device (0): Tesla K40c, Compute Capability 3.5
2020-01-14 14:23:18.307155: W tensorflow/compiler/jit/mark_for_compilation_pass.cc:1412] (One-time warning): Not using XLA:CPU for cluster because envvar TF_XLA_FLAGS=--tf_xla_cpu_global_jit was not set.  If you want XLA:CPU, either set that envvar, or use experimental_jit_scope to enable XLA:CPU.  To confirm that XLA is active, pass --vmodule=xla_compilation_cache=1 (as a proper command-line flag, not via TF_XLA_FLAGS) or set the envvar XLA_FLAGS=--xla_hlo_profile.
INFO:tensorflow:Running local_init_op.
I0114 14:23:20.774402 140655556867904 session_manager.py:500] Running local_init_op.
INFO:tensorflow:Done running local_init_op.
I0114 14:23:21.553675 140655556867904 session_manager.py:502] Done running local_init_op.
INFO:tensorflow:Starting Session.
I0114 14:23:22.973853 140655556867904 learning.py:754] Starting Session.
INFO:tensorflow:Saving checkpoint to path /cube/neurocube/local/serenceslab/maggie/biasCNN/logs/vgg16/ImageNet/scratch_vgg16_imagenet_rot_45/init1_testrestart/model.ckpt
I0114 14:23:23.007075 140646262228736 supervisor.py:1117] Saving checkpoint to path /cube/neurocube/local/serenceslab/maggie/biasCNN/logs/vgg16/ImageNet/scratch_vgg16_imagenet_rot_45/init1_testrestart/model.ckpt
INFO:tensorflow:Starting Queues.
I0114 14:23:23.017976 140655556867904 learning.py:768] Starting Queues.
INFO:tensorflow:global_step/sec: 0
I0114 14:23:24.377963 140646270621440 supervisor.py:1099] global_step/sec: 0
2020-01-14 14:23:25.787066: I tensorflow/stream_executor/platform/default/dso_loader.cc:42] Successfully opened dynamic library libcudnn.so.7
2020-01-14 14:23:28.402779: W tensorflow/core/common_runtime/bfc_allocator.cc:237] Allocator (GPU_0_bfc) ran out of memory trying to allocate 3.45GiB with freed_by_count=0. The caller indicates that this is not a failure, but may mean that there could be performance gains if more memory were available.
INFO:tensorflow:Recording summary at step 1.
I0114 14:23:41.226235 140646279014144 supervisor.py:1050] Recording summary at step 1.
INFO:tensorflow:global_step/sec: 0.155087
I0114 14:23:43.721855 140646270621440 supervisor.py:1099] global_step/sec: 0.155087
INFO:tensorflow:Recording summary at step 10.
I0114 14:23:50.946663 140646279014144 supervisor.py:1050] Recording summary at step 10.
INFO:tensorflow:global step 10: loss = 13.8322 (0.668 sec/step)
I0114 14:23:51.190187 140655556867904 learning.py:507] global step 10: loss = 13.8322 (0.668 sec/step)
INFO:tensorflow:EVALUATING MODEL AT STEP 10

I0114 14:23:51.193317 140655556867904 learning_biasCNN_TEST.py:48] EVALUATING MODEL AT STEP 10

INFO:tensorflow:global step 20: loss = 0.0502 (0.755 sec/step)
I0114 14:23:59.644819 140655556867904 learning.py:507] global step 20: loss = 0.0502 (0.755 sec/step)
INFO:tensorflow:EVALUATING MODEL AT STEP 20

I0114 14:23:59.647794 140655556867904 learning_biasCNN_TEST.py:48] EVALUATING MODEL AT STEP 20

INFO:tensorflow:global_step/sec: 1
I0114 14:24:03.722164 140646270621440 supervisor.py:1099] global_step/sec: 1
INFO:tensorflow:Recording summary at step 29.
I0114 14:24:09.369094 140646279014144 supervisor.py:1050] Recording summary at step 29.
INFO:tensorflow:global step 30: loss = 4.0528 (0.610 sec/step)
I0114 14:24:10.011361 140655556867904 learning.py:507] global step 30: loss = 4.0528 (0.610 sec/step)
INFO:tensorflow:EVALUATING MODEL AT STEP 30

I0114 14:24:10.013630 140655556867904 learning_biasCNN_TEST.py:48] EVALUATING MODEL AT STEP 30

INFO:tensorflow:global step 40: loss = 8.4869 (0.622 sec/step)
I0114 14:24:17.657224 140655556867904 learning.py:507] global step 40: loss = 8.4869 (0.622 sec/step)
INFO:tensorflow:EVALUATING MODEL AT STEP 40

I0114 14:24:17.660242 140655556867904 learning_biasCNN_TEST.py:48] EVALUATING MODEL AT STEP 40

INFO:tensorflow:global_step/sec: 1.15001
I0114 14:24:23.721694 140646270621440 supervisor.py:1099] global_step/sec: 1.15001
INFO:tensorflow:global step 50: loss = 12.9545 (0.714 sec/step)
I0114 14:24:27.892324 140655556867904 learning.py:507] global step 50: loss = 12.9545 (0.714 sec/step)
INFO:tensorflow:RESETTING STREAMING EVAL METRICS AT STEP 50

I0114 14:24:27.893956 140655556867904 learning_biasCNN_TEST.py:41] RESETTING STREAMING EVAL METRICS AT STEP 50

INFO:tensorflow:EVALUATING MODEL AT STEP 50

I0114 14:24:27.942534 140655556867904 learning_biasCNN_TEST.py:48] EVALUATING MODEL AT STEP 50

INFO:tensorflow:Recording summary at step 50.
I0114 14:24:29.404841 140646279014144 supervisor.py:1050] Recording summary at step 50.
INFO:tensorflow:global step 60: loss = 3.7144 (0.625 sec/step)
I0114 14:24:35.855858 140655556867904 learning.py:507] global step 60: loss = 3.7144 (0.625 sec/step)
INFO:tensorflow:EVALUATING MODEL AT STEP 60

I0114 14:24:35.859439 140655556867904 learning_biasCNN_TEST.py:48] EVALUATING MODEL AT STEP 60

INFO:tensorflow:global_step/sec: 1.15
I0114 14:24:43.721653 140646270621440 supervisor.py:1099] global_step/sec: 1.15
INFO:tensorflow:global step 70: loss = -0.2246 (3.221 sec/step)
I0114 14:24:47.734169 140655556867904 learning.py:507] global step 70: loss = -0.2246 (3.221 sec/step)
INFO:tensorflow:EVALUATING MODEL AT STEP 70

I0114 14:24:47.736207 140655556867904 learning_biasCNN_TEST.py:48] EVALUATING MODEL AT STEP 70

INFO:tensorflow:Recording summary at step 70.
I0114 14:24:49.197984 140646279014144 supervisor.py:1050] Recording summary at step 70.
INFO:tensorflow:global step 80: loss = -2.6541 (0.619 sec/step)
I0114 14:24:55.464992 140655556867904 learning.py:507] global step 80: loss = -2.6541 (0.619 sec/step)
INFO:tensorflow:EVALUATING MODEL AT STEP 80

I0114 14:24:55.468491 140655556867904 learning_biasCNN_TEST.py:48] EVALUATING MODEL AT STEP 80

INFO:tensorflow:global_step/sec: 1.05
I0114 14:25:03.721933 140646270621440 supervisor.py:1099] global_step/sec: 1.05
INFO:tensorflow:global step 90: loss = 1.9941 (2.028 sec/step)
I0114 14:25:05.416291 140655556867904 learning.py:507] global step 90: loss = 1.9941 (2.028 sec/step)
INFO:tensorflow:EVALUATING MODEL AT STEP 90

I0114 14:25:05.482455 140655556867904 learning_biasCNN_TEST.py:48] EVALUATING MODEL AT STEP 90

INFO:tensorflow:Recording summary at step 94.
I0114 14:25:09.150719 140646279014144 supervisor.py:1050] Recording summary at step 94.
INFO:tensorflow:global step 100: loss = 4.4791 (0.743 sec/step)
I0114 14:25:13.343955 140655556867904 learning.py:507] global step 100: loss = 4.4791 (0.743 sec/step)
INFO:tensorflow:RESETTING STREAMING EVAL METRICS AT STEP 100

I0114 14:25:13.346836 140655556867904 learning_biasCNN_TEST.py:41] RESETTING STREAMING EVAL METRICS AT STEP 100

INFO:tensorflow:EVALUATING MODEL AT STEP 100

I0114 14:25:13.348927 140655556867904 learning_biasCNN_TEST.py:48] EVALUATING MODEL AT STEP 100

INFO:tensorflow:global step 110: loss = 5.8946 (0.740 sec/step)
I0114 14:25:21.684144 140655556867904 learning.py:507] global step 110: loss = 5.8946 (0.740 sec/step)
INFO:tensorflow:EVALUATING MODEL AT STEP 110

I0114 14:25:21.686818 140655556867904 learning_biasCNN_TEST.py:48] EVALUATING MODEL AT STEP 110

INFO:tensorflow:global_step/sec: 1.05
I0114 14:25:23.721681 140646270621440 supervisor.py:1099] global_step/sec: 1.05
INFO:tensorflow:Recording summary at step 117.
I0114 14:25:29.268899 140646279014144 supervisor.py:1050] Recording summary at step 117.
INFO:tensorflow:global step 120: loss = -2.5255 (0.624 sec/step)
I0114 14:25:31.396704 140655556867904 learning.py:507] global step 120: loss = -2.5255 (0.624 sec/step)
INFO:tensorflow:EVALUATING MODEL AT STEP 120

I0114 14:25:31.399972 140655556867904 learning_biasCNN_TEST.py:48] EVALUATING MODEL AT STEP 120

INFO:tensorflow:global step 130: loss = 6.6066 (0.737 sec/step)
I0114 14:25:39.847890 140655556867904 learning.py:507] global step 130: loss = 6.6066 (0.737 sec/step)
INFO:tensorflow:EVALUATING MODEL AT STEP 130

I0114 14:25:39.851609 140655556867904 learning_biasCNN_TEST.py:48] EVALUATING MODEL AT STEP 130

INFO:tensorflow:global_step/sec: 1.1
I0114 14:25:43.721632 140646270621440 supervisor.py:1099] global_step/sec: 1.1
INFO:tensorflow:Recording summary at step 139.
I0114 14:25:49.331780 140646279014144 supervisor.py:1050] Recording summary at step 139.
INFO:tensorflow:global step 140: loss = -1.0204 (0.730 sec/step)
I0114 14:25:49.578800 140655556867904 learning.py:507] global step 140: loss = -1.0204 (0.730 sec/step)
INFO:tensorflow:EVALUATING MODEL AT STEP 140

I0114 14:25:49.581855 140655556867904 learning_biasCNN_TEST.py:48] EVALUATING MODEL AT STEP 140

INFO:tensorflow:global step 150: loss = 7.2311 (0.618 sec/step)
I0114 14:25:57.714837 140655556867904 learning.py:507] global step 150: loss = 7.2311 (0.618 sec/step)
INFO:tensorflow:RESETTING STREAMING EVAL METRICS AT STEP 150

I0114 14:25:57.717185 140655556867904 learning_biasCNN_TEST.py:41] RESETTING STREAMING EVAL METRICS AT STEP 150

INFO:tensorflow:EVALUATING MODEL AT STEP 150

I0114 14:25:57.719077 140655556867904 learning_biasCNN_TEST.py:48] EVALUATING MODEL AT STEP 150

INFO:tensorflow:global_step/sec: 1.19994
I0114 14:26:03.722703 140646270621440 supervisor.py:1099] global_step/sec: 1.19994
INFO:tensorflow:global step 160: loss = -8.1845 (0.608 sec/step)
I0114 14:26:07.268242 140655556867904 learning.py:507] global step 160: loss = -8.1845 (0.608 sec/step)
INFO:tensorflow:EVALUATING MODEL AT STEP 160

I0114 14:26:07.270375 140655556867904 learning_biasCNN_TEST.py:48] EVALUATING MODEL AT STEP 160

INFO:tensorflow:Recording summary at step 161.
I0114 14:26:09.343015 140646279014144 supervisor.py:1050] Recording summary at step 161.
INFO:tensorflow:global step 170: loss = 2.0161 (0.630 sec/step)
I0114 14:26:15.241036 140655556867904 learning.py:507] global step 170: loss = 2.0161 (0.630 sec/step)
INFO:tensorflow:EVALUATING MODEL AT STEP 170

I0114 14:26:15.244571 140655556867904 learning_biasCNN_TEST.py:48] EVALUATING MODEL AT STEP 170

INFO:tensorflow:global_step/sec: 1.10003
I0114 14:26:23.722405 140646270621440 supervisor.py:1099] global_step/sec: 1.10003
INFO:tensorflow:global step 180: loss = -1.9847 (2.072 sec/step)
I0114 14:26:25.484498 140655556867904 learning.py:507] global step 180: loss = -1.9847 (2.072 sec/step)
INFO:tensorflow:EVALUATING MODEL AT STEP 180

I0114 14:26:25.486526 140655556867904 learning_biasCNN_TEST.py:48] EVALUATING MODEL AT STEP 180

INFO:tensorflow:Recording summary at step 184.
I0114 14:26:29.203565 140646279014144 supervisor.py:1050] Recording summary at step 184.
INFO:tensorflow:global step 190: loss = 0.6779 (0.794 sec/step)
I0114 14:26:33.402118 140655556867904 learning.py:507] global step 190: loss = 0.6779 (0.794 sec/step)
INFO:tensorflow:EVALUATING MODEL AT STEP 190

I0114 14:26:33.404606 140655556867904 learning_biasCNN_TEST.py:48] EVALUATING MODEL AT STEP 190

INFO:tensorflow:global step 200: loss = 5.5630 (0.785 sec/step)
I0114 14:26:41.411698 140655556867904 learning.py:507] global step 200: loss = 5.5630 (0.785 sec/step)
INFO:tensorflow:RESETTING STREAMING EVAL METRICS AT STEP 200

I0114 14:26:41.414986 140655556867904 learning_biasCNN_TEST.py:41] RESETTING STREAMING EVAL METRICS AT STEP 200

INFO:tensorflow:EVALUATING MODEL AT STEP 200

I0114 14:26:41.417050 140655556867904 learning_biasCNN_TEST.py:48] EVALUATING MODEL AT STEP 200

INFO:tensorflow:Recording summary at step 207.
I0114 14:26:49.280778 140646279014144 supervisor.py:1050] Recording summary at step 207.
INFO:tensorflow:global step 210: loss = -3.9497 (0.647 sec/step)
I0114 14:26:51.047673 140655556867904 learning.py:507] global step 210: loss = -3.9497 (0.647 sec/step)
INFO:tensorflow:EVALUATING MODEL AT STEP 210

I0114 14:26:51.051223 140655556867904 learning_biasCNN_TEST.py:48] EVALUATING MODEL AT STEP 210

slurmstepd-ssrde-c-402: error: *** JOB 16054 ON ssrde-c-402 CANCELLED AT 2020-01-14T14:26:58 ***
